Workbook

Sheet Dashboard
A1: VERTRAGSEINGÄNGE (KW) | L1: CONVERSION RATE
B2: Verträge Gesamt | L2: Leads Gesamt | O2: Reife Conv. Rate
B3: =IF($E$4="Alle",COUNTA(Vertragseingänge!E4:E500),COUNTIFS(Vertragseingänge!$C$4:$C$500,$E$4*1,Vertragseingänge!$E$4:$E$500,"<>")) -> 180 | L3: =IF($E$4="Alle",SUM('Leads Rohdaten'!D4:D503),SUMIFS('Leads Rohdaten'!$D$4:$D$503,'Leads Rohdaten'!$A$4:$A$503,$E$4*1)) -> 1235 | O3: =IF($E$4="Alle",IF(SUMIFS('Leads Rohdaten'!$D$4:$D$503,'Leads Rohdaten'!$H$4:$H$503,"Reif")=0,"-",SUMIFS('Leads Rohdaten'!$E$4:$E$503,'Leads Rohdaten'!$H$4:$H$503,"Reif")/SUMIFS('Leads Rohdaten'!$D$4:$D$503,'Leads Rohdaten'!$H$4:$H$503,"Reif")),IF(SUMIFS('Leads Rohdaten'!$D$4:$D$503,'Leads Rohdaten'!$H$4:$H$503,"Reif",'Leads Rohdaten'!$A$4:$A$503,$E$4*1)=0,"-",SUMIFS('Leads Rohdaten'!$E$4:$E$503,'Leads Rohdaten'!$H$4:$H$503,"Reif",'Leads Rohdaten'!$A$4:$A$503,$E$4*1)/SUMIFS('Leads Rohdaten'!$D$4:$D$503,'Leads Rohdaten'!$H$4:$H$503,"Reif",'Leads Rohdaten'!$A$4:$A$503,$E$4*1))) -> 0.04180791
A4: Jahr-Filter: | E4: 2026 | G4: ← Jahr wählen (Alle / 2025 / 2026) | L4: =" Anzeige für: "&$E$4&" | Maturity: "&Steuerung!$C$27&" Tage" -> Anzeige für: 2026 | Maturity: 90 Tage
A5: KW | B5: Ges. | C5: =IF(Steuerung!B16="","",Steuerung!C16) -> Fatima | D5: =IF(Steuerung!B17="","",Steuerung!C17) -> Gabriella | E5: =IF(Steuerung!B18="","",Steuerung!C18) -> Gerd | F5: =IF(Steuerung!B19="","",Steuerung!C19) -> David | G5: =IF(Steuerung!B20="","",Steuerung!C20) -> Nicole | H5: =IF(Steuerung!B21="","",Steuerung!C21) -> Drilan | I5: =IF(Steuerung!B22="","",Steuerung!C22) -> Salvat. | J5: Sonst. | L5: REIFE CONVERSION RATE (Leads ≥ Maturity-Schwelle)
A6: KW 2 | B6: =IF($E$4="Alle",COUNTIFS(Vertragseingänge!$A$4:$A$500,A6),COUNTIFS(Vertragseingänge!$A$4:$A$500,A6,Vertragseingänge!$C$4:$C$500,$E$4*1)) -> 3 | C6: =IFERROR(IF(Steuerung!$B$16="","",IF($E$4="Alle",IF(COUNTIFS(Vertragseingänge!$A$4:$A$500,A6,Vertragseingänge!$E$4:$E$500,Steuerung!$B$16)=0,"",COUNTIFS(Vertragseingänge!$A$4:$A$500,A6,Vertragseingänge!$E$4:$E$500,Steuerung!$B$16)),IF(COUNTIFS(Vertragseingänge!$A$4:$A$500,A6,Vertragseingänge!$E$4:$E$500,Steuerung!$B$16,Vertragseingänge!$C$4:$C$500,$E$4*1)=0,"",COUNTIFS(Vertragseingänge!$A$4:$A$500,A6,Vertragseingänge!$E$4:$E$500,Steuerung!$B$16,Vertragseingänge!$C$4:$C$500,$E$4*1)))),"") -> 1 | D6: =IFERROR(IF(Steuerung!$B$17="","",IF($E$4="Alle",IF(COUNTIFS(Vertragseingänge!$A$4:$A$500,A6,Vertragseingänge!$E$4:$E$500,Steuerung!$B$17)=0,"",COUNTIFS(Vertragseingänge!$A$4:$A$500,A6,Vertragseingänge!$E$4:$E$500,Steuerung!$B$17)),IF(COUNTIFS(Vertragseingänge!$A$4:$A$500,A6,Vertragseingänge!$E$4:$E$500,Steuerung!$B$17,Vertragseingänge!$C$4:$C$500,$E$4*1)=0,"",COUNTIFS(Vertragseingänge!$A$4:$A$500,A6,Vertragseingänge!$E$4:$E$500,Steuerung!$B$17,Vertragseingänge!$C$4:$C$500,$E$4*1)))),"") | E6: =IFERROR(IF(Steuerung!$B$18="","",IF($E$4="Alle",IF(COUNTIFS(Vertragseingänge!$A$4:$A$500,A6,Vertragseingänge!$E$4:$E$500,Steuerung!$B$18)=0,"",COUNTIFS(Vertragseingänge!$A$4:$A$500,A6,Vertragseingänge!$E$4:$E$500,Steuerung!$B$18)),IF(COUNTIFS(Vertragseingänge!$A$4:$A$500,A6,Vertragseingänge!$E$4:$E$500,Steuerung!$B$18,Vertragseingänge!$C$4:$C$500,$E$4*1)=0,"",COUNTIFS(Vertragseingänge!$A$4:$A$500,A6,Vertragseingänge!$E$4:$E$500,Steuerung!$B$18,Vertragseingänge!$C$4:$C$500,$E$4*1)))),"") -> 2 | F6: =IFERROR(IF(Steuerung!$B$19="","",IF($E$4="Alle",IF(COUNTIFS(Vertragseingänge!$A$4:$A$500,A6,Vertragseingänge!$E$4:$E$500,Steuerung!$B$19)=0,"",COUNTIFS(Vertragseingänge!$A$4:$A$500,A6,Vertragseingänge!$E$4:$E$500,Steuerung!$B$19)),IF(COUNTIFS(Vertragseingänge!$A$4:$A$500,A6,Vertragseingänge!$E$4:$E$500,Steuerung!$B$19,Vertragseingänge!$C$4:$C$500,$E$4*1)=0,"",COUNTIFS(Vertragseingänge!$A$4:$A$500,A6,Vertragseingänge!$E$4:$E$500,Steuerung!$B$19,Vertragseingänge!$C$4:$C$500,$E$4*1)))),"") | G6: =IFERROR(IF(Steuerung!$B$20="","",IF($E$4="Alle",IF(COUNTIFS(Vertragseingänge!$A$4:$A$500,A6,Vertragseingänge!$E$4:$E$500,Steuerung!$B$20)=0,"",COUNTIFS(Vertragseingänge!$A$4:$A$500,A6,Vertragseingänge!$E$4:$E$500,Steuerung!$B$20)),IF(COUNTIFS(Vertragseingänge!$A$4:$A$500,A6,Vertragseingänge!$E$4:$E$500,Steuerung!$B$20,Vertragseingänge!$C$4:$C$500,$E$4*1)=0,"",COUNTIFS(Vertragseingänge!$A$4:$A$500,A6,Vertragseingänge!$E$4:$E$500,Steuerung!$B$20,Vertragseingänge!$C$4:$C$500,$E$4*1)))),"") | H6: =IFERROR(IF(Steuerung!$B$21="","",IF($E$4="Alle",IF(COUNTIFS(Vertragseingänge!$A$4:$A$500,A6,Vertragseingänge!$E$4:$E$500,Steuerung!$B$21)=0,"",COUNTIFS(Vertragseingänge!$A$4:$A$500,A6,Vertragseingänge!$E$4:$E$500,Steuerung!$B$21)),IF(COUNTIFS(Vertragseingänge!$A$4:$A$500,A6,Vertragseingänge!$E$4:$E$500,Steuerung!$B$21,Vertragseingänge!$C$4:$C$500,$E$4*1)=0,"",COUNTIFS(Vertragseingänge!$A$4:$A$500,A6,Vertragseingänge!$E$4:$E$500,Steuerung!$B$21,Vertragseingänge!$C$4:$C$500,$E$4*1)))),"") | I6: =IFERROR(IF(Steuerung!$B$22="","",IF($E$4="Alle",IF(COUNTIFS(Vertragseingänge!$A$4:$A$500,A6,Vertragseingänge!$E$4:$E$500,Steuerung!$B$22)=0,"",COUNTIFS(Vertragseingänge!$A$4:$A$500,A6,Vertragseingänge!$E$4:$E$500,Steuerung!$B$22)),IF(COUNTIFS(Vertragseingänge!$A$4:$A$500,A6,Vertragseingänge!$E$4:$E$500,Steuerung!$B$22,Vertragseingänge!$C$4:$C$500,$E$4*1)=0,"",COUNTIFS(Vertragseingänge!$A$4:$A$500,A6,Vertragseingänge!$E$4:$E$500,Steuerung!$B$22,Vertragseingänge!$C$4:$C$500,$E$4*1)))),"") | J6: =IFERROR(IF(B6-SUM(C6:I6)=0,"",B6-SUM(C6:I6)),"") | L6: Verkäufer | M6: Leads | N6: Vertr. | O6: Conv.%
A7: KW 3 | B7: =IF($E$4="Alle",COUNTIFS(Vertragseingänge!$A$4:$A$500,A7),COUNTIFS(Vertragseingänge!$A$4:$A$500,A7,Vertragseingänge!$C$4:$C$500,$E$4*1)) -> 1 | C7: =IFERROR(IF(Steuerung!$B$16="","",IF($E$4="Alle",IF(COUNTIFS(Vertragseingänge!$A$4:$A$500,A7,Vertragseingänge!$E$4:$E$500,Steuerung!$B$16)=0,"",COUNTIFS(Vertragseingänge!$A$4:$A$500,A7,Vertragseingänge!$E$4:$E$500,Steuerung!$B$16)),IF(COUNTIFS(Vertragseingänge!$A$4:$A$500,A7,Vertragseingänge!$E$4:$E$500,Steuerung!$B$16,Vertragseingänge!$C$4:$C$500,$E$4*1)=0,"",COUNTIFS(Vertragseingänge!$A$4:$A$500,A7,Vertragseingänge!$E$4:$E$500,Steuerung!$B$16,Vertragseingänge!$C$4:$C$500,$E$4*1)))),"") | D7: =IFERROR(IF(Steuerung!$B$17="","",IF($E$4="Alle",IF(COUNTIFS(Vertragseingänge!$A$4:$A$500,A7,Vertragseingänge!$E$4:$E$500,Steuerung!$B$17)=0,"",COUNTIFS(Vertragseingänge!$A$4:$A$500,A7,Vertragseingänge!$E$4:$E$500,Steuerung!$B$17)),IF(COUNTIFS(Vertragseingänge!$A$4:$A$500,A7,Vertragseingänge!$E$4:$E$500,Steuerung!$B$17,Vertragseingänge!$C$4:$C$500,$E$4*1)=0,"",COUNTIFS(Vertragseingänge!$A$4:$A$500,A7,Vertragseingänge!$E$4:$E$500,Steuerung!$B$17,Vertragseingänge!$C$4:$C$500,$E$4*1)))),"") -> 1 | E7: =IFERROR(IF(Steuerung!$B$18="","",IF($E$4="Alle",IF(COUNTIFS(Vertragseingänge!$A$4:$A$500,A7,Vertragseingänge!$E$4:$E$500,Steuerung!$B$18)=0,"",COUNTIFS(Vertragseingänge!$A$4:$A$500,A7,Vertragseingänge!$E$4:$E$500,Steuerung!$B$18)),IF(COUNTIFS(Vertragseingänge!$A$4:$A$500,A7,Vertragseingänge!$E$4:$E$500,Steuerung!$B$18,Vertragseingänge!$C$4:$C$500,$E$4*1)=0,"",COUNTIFS(Vertragseingänge!$A$4:$A$500,A7,Vertragseingänge!$E$4:$E$500,Steuerung!$B$18,Vertragseingänge!$C$4:$C$500,$E$4*1)))),"") | F7: =IFERROR(IF(Steuerung!$B$19="","",IF($E$4="Alle",IF(COUNTIFS(Vertragseingänge!$A$4:$A$500,A7,Vertragseingänge!$E$4:$E$500,Steuerung!$B$19)=0,"",COUNTIFS(Vertragseingänge!$A$4:$A$500,A7,Vertragseingänge!$E$4:$E$500,Steuerung!$B$19)),IF(COUNTIFS(Vertragseingänge!$A$4:$A$500,A7,Vertragseingänge!$E$4:$E$500,Steuerung!$B$19,Vertragseingänge!$C$4:$C$500,$E$4*1)=0,"",COUNTIFS(Vertragseingänge!$A$4:$A$500,A7,Vertragseingänge!$E$4:$E$500,Steuerung!$B$19,Vertragseingänge!$C$4:$C$500,$E$4*1)))),"") | G7: =IFERROR(IF(Steuerung!$B$20="","",IF($E$4="Alle",IF(COUNTIFS(Vertragseingänge!$A$4:$A$500,A7,Vertragseingänge!$E$4:$E$500,Steuerung!$B$20)=0,"",COUNTIFS(Vertragseingänge!$A$4:$A$500,A7,Vertragseingänge!$E$4:$E$500,Steuerung!$B$20)),IF(COUNTIFS(Vertragseingänge!$A$4:$A$500,A7,Vertragseingänge!$E$4:$E$500,Steuerung!$B$20,Vertragseingänge!$C$4:$C$500,$E$4*1)=0,"",COUNTIFS(Vertragseingänge!$A$4:$A$500,A7,Vertragseingänge!$E$4:$E$500,Steuerung!$B$20,Vertragseingänge!$C$4:$C$500,$E$4*1)))),"") | H7: =IFERROR(IF(Steuerung!$B$21="","",IF($E$4="Alle",IF(COUNTIFS(Vertragseingänge!$A$4:$A$500,A7,Vertragseingänge!$E$4:$E$500,Steuerung!$B$21)=0,"",COUNTIFS(Vertragseingänge!$A$4:$A$500,A7,Vertragseingänge!$E$4:$E$500,Steuerung!$B$21)),IF(COUNTIFS(Vertragseingänge!$A$4:$A$500,A7,Vertragseingänge!$E$4:$E$500,Steuerung!$B$21,Vertragseingänge!$C$4:$C$500,$E$4*1)=0,"",COUNTIFS(Vertragseingänge!$A$4:$A$500,A7,Vertragseingänge!$E$4:$E$500,Steuerung!$B$21,Vertragseingänge!$C$4:$C$500,$E$4*1)))),"") | I7: =IFERROR(IF(Steuerung!$B$22="","",IF($E$4="Alle",IF(COUNTIFS(Vertragseingänge!$A$4:$A$500,A7,Vertragseingänge!$E$4:$E$500,Steuerung!$B$22)=0,"",COUNTIFS(Vertragseingänge!$A$4:$A$500,A7,Vertragseingänge!$E$4:$E$500,Steuerung!$B$22)),IF(COUNTIFS(Vertragseingänge!$A$4:$A$500,A7,Vertragseingänge!$E$4:$E$500,Steuerung!$B$22,Vertragseingänge!$C$4:$C$500,$E$4*1)=0,"",COUNTIFS(Vertragseingänge!$A$4:$A$500,A7,Vertragseingänge!$E$4:$E$500,Steuerung!$B$22,Vertragseingänge!$C$4:$C$500,$E$4*1)))),"") | J7: =IFERROR(IF(B7-SUM(C7:I7)=0,"",B7-SUM(C7:I7)),"") | L7: =IF(Steuerung!B6="","",Steuerung!C6) -> Fatima | M7: =IF(Steuerung!$B$6="","",IF($E$4="Alle",SUMIFS('Leads Rohdaten'!$D$4:$D$503,'Leads Rohdaten'!$C$4:$C$503,Steuerung!$B$6,'Leads Rohdaten'!$H$4:$H$503,"Reif"),SUMIFS('Leads Rohdaten'!$D$4:$D$503,'Leads Rohdaten'!$C$4:$C$503,Steuerung!$B$6,'Leads Rohdaten'!$H$4:$H$503,"Reif",'Leads Rohdaten'!$A$4:$A$503,$E$4*1))) -> 210 | N7: =IF(Steuerung!$B$6="","",IF($E$4="Alle",SUMIFS('Leads Rohdaten'!$E$4:$E$503,'Leads Rohdaten'!$C$4:$C$503,Steuerung!$B$6,'Leads Rohdaten'!$H$4:$H$503,"Reif"),SUMIFS('Leads Rohdaten'!$E$4:$E$503,'Leads Rohdaten'!$C$4:$C$503,Steuerung!$B$6,'Leads Rohdaten'!$H$4:$H$503,"Reif",'Leads Rohdaten'!$A$4:$A$503,$E$4*1))) -> 21 | O7: =IF(OR(M7="",M7=0),"–",N7/M7) -> 0.1 | P7: =IF(OR(M7="",M7=0),"",IF(N7/MAX(M7,1)>=0.1,"✅",IF(N7/MAX(M7,1)>=0.03,"⚠","⛔"))) -> ✅
A8: KW 4 | B8: =IF($E$4="Alle",COUNTIFS(Vertragseingänge!$A$4:$A$500,A8),COUNTIFS(Vertragseingänge!$A$4:$A$500,A8,Vertragseingänge!$C$4:$C$500,$E$4*1)) -> 5 | C8: =IFERROR(IF(Steuerung!$B$16="","",IF($E$4="Alle",IF(COUNTIFS(Vertragseingänge!$A$4:$A$500,A8,Vertragseingänge!$E$4:$E$500,Steuerung!$B$16)=0,"",COUNTIFS(Vertragseingänge!$A$4:$A$500,A8,Vertragseingänge!$E$4:$E$500,Steuerung!$B$16)),IF(COUNTIFS(Vertragseingänge!$A$4:$A$500,A8,Vertragseingänge!$E$4:$E$500,Steuerung!$B$16,Vertragseingänge!$C$4:$C$500,$E$4*1)=0,"",COUNTIFS(Vertragseingänge!$A$4:$A$500,A8,Vertragseingänge!$E$4:$E$500,Steuerung!$B$16,Vertragseingänge!$C$4:$C$500,$E$4*1)))),"") -> 3 | D8: =IFERROR(IF(Steuerung!$B$17="","",IF($E$4="Alle",IF(COUNTIFS(Vertragseingänge!$A$4:$A$500,A8,Vertragseingänge!$E$4:$E$500,Steuerung!$B$17)=0,"",COUNTIFS(Vertragseingänge!$A$4:$A$500,A8,Vertragseingänge!$E$4:$E$500,Steuerung!$B$17)),IF(COUNTIFS(Vertragseingänge!$A$4:$A$500,A8,Vertragseingänge!$E$4:$E$500,Steuerung!$B$17,Vertragseingänge!$C$4:$C$500,$E$4*1)=0,"",COUNTIFS(Vertragseingänge!$A$4:$A$500,A8,Vertragseingänge!$E$4:$E$500,Steuerung!$B$17,Vertragseingänge!$C$4:$C$500,$E$4*1)))),"") -> 1 | E8: =IFERROR(IF(Steuerung!$B$18="","",IF($E$4="Alle",IF(COUNTIFS(Vertragseingänge!$A$4:$A$500,A8,Vertragseingänge!$E$4:$E$500,Steuerung!$B$18)=0,"",COUNTIFS(Vertragseingänge!$A$4:$A$500,A8,Vertragseingänge!$E$4:$E$500,Steuerung!$B$18)),IF(COUNTIFS(Vertragseingänge!$A$4:$A$500,A8,Vertragseingänge!$E$4:$E$500,Steuerung!$B$18,Vertragseingänge!$C$4:$C$500,$E$4*1)=0,"",COUNTIFS(Vertragseingänge!$A$4:$A$500,A8,Vertragseingänge!$E$4:$E$500,Steuerung!$B$18,Vertragseingänge!$C$4:$C$500,$E$4*1)))),"") | F8: =IFERROR(IF(Steuerung!$B$19="","",IF($E$4="Alle",IF(COUNTIFS(Vertragseingänge!$A$4:$A$500,A8,Vertragseingänge!$E$4:$E$500,Steuerung!$B$19)=0,"",COUNTIFS(Vertragseingänge!$A$4:$A$500,A8,Vertragseingänge!$E$4:$E$500,Steuerung!$B$19)),IF(COUNTIFS(Vertragseingänge!$A$4:$A$500,A8,Vertragseingänge!$E$4:$E$500,Steuerung!$B$19,Vertragseingänge!$C$4:$C$500,$E$4*1)=0,"",COUNTIFS(Vertragseingänge!$A$4:$A$500,A8,Vertragseingänge!$E$4:$E$500,Steuerung!$B$19,Vertragseingänge!$C$4:$C$500,$E$4*1)))),"") | G8: =IFERROR(IF(Steuerung!$B$20="","",IF($E$4="Alle",IF(COUNTIFS(Vertragseingänge!$A$4:$A$500,A8,Vertragseingänge!$E$4:$E$500,Steuerung!$B$20)=0,"",COUNTIFS(Vertragseingänge!$A$4:$A$500,A8,Vertragseingänge!$E$4:$E$500,Steuerung!$B$20)),IF(COUNTIFS(Vertragseingänge!$A$4:$A$500,A8,Vertragseingänge!$E$4:$E$500,Steuerung!$B$20,Vertragseingänge!$C$4:$C$500,$E$4*1)=0,"",COUNTIFS(Vertragseingänge!$A$4:$A$500,A8,Vertragseingänge!$E$4:$E$500,Steuerung!$B$20,Vertragseingänge!$C$4:$C$500,$E$4*1)))),"") | H8: =IFERROR(IF(Steuerung!$B$21="","",IF($E$4="Alle",IF(COUNTIFS(Vertragseingänge!$A$4:$A$500,A8,Vertragseingänge!$E$4:$E$500,Steuerung!$B$21)=0,"",COUNTIFS(Vertragseingänge!$A$4:$A$500,A8,Vertragseingänge!$E$4:$E$500,Steuerung!$B$21)),IF(COUNTIFS(Vertragseingänge!$A$4:$A$500,A8,Vertragseingänge!$E$4:$E$500,Steuerung!$B$21,Vertragseingänge!$C$4:$C$500,$E$4*1)=0,"",COUNTIFS(Vertragseingänge!$A$4:$A$500,A8,Vertragseingänge!$E$4:$E$500,Steuerung!$B$21,Vertragseingänge!$C$4:$C$500,$E$4*1)))),"") | I8: =IFERROR(IF(Steuerung!$B$22="","",IF($E$4="Alle",IF(COUNTIFS(Vertragseingänge!$A$4:$A$500,A8,Vertragseingänge!$E$4:$E$500,Steuerung!$B$22)=0,"",COUNTIFS(Vertragseingänge!$A$4:$A$500,A8,Vertragseingänge!$E$4:$E$500,Steuerung!$B$22)),IF(COUNTIFS(Vertragseingänge!$A$4:$A$500,A8,Vertragseingänge!$E$4:$E$500,Steuerung!$B$22,Vertragseingänge!$C$4:$C$500,$E$4*1)=0,"",COUNTIFS(Vertragseingänge!$A$4:$A$500,A8,Vertragseingänge!$E$4:$E$500,Steuerung!$B$22,Vertragseingänge!$C$4:$C$500,$E$4*1)))),"") | J8: =IFERROR(IF(B8-SUM(C8:I8)=0,"",B8-SUM(C8:I8)),"") -> 1 | L8: =IF(Steuerung!B7="","",Steuerung!C7) -> Gabriella | M8: =IF(Steuerung!$B$7="","",IF($E$4="Alle",SUMIFS('Leads Rohdaten'!$D$4:$D$503,'Leads Rohdaten'!$C$4:$C$503,Steuerung!$B$7,'Leads Rohdaten'!$H$4:$H$503,"Reif"),SUMIFS('Leads Rohdaten'!$D$4:$D$503,'Leads Rohdaten'!$C$4:$C$503,Steuerung!$B$7,'Leads Rohdaten'!$H$4:$H$503,"Reif",'Leads Rohdaten'!$A$4:$A$503,$E$4*1))) -> 90 | N8: =IF(Steuerung!$B$7="","",IF($E$4="Alle",SUMIFS('Leads Rohdaten'!$E$4:$E$503,'Leads Rohdaten'!$C$4:$C$503,Steuerung!$B$7,'Leads Rohdaten'!$H$4:$H$503,"Reif"),SUMIFS('Leads Rohdaten'!$E$4:$E$503,'Leads Rohdaten'!$C$4:$C$503,Steuerung!$B$7,'Leads Rohdaten'!$H$4:$H$503,"Reif",'Leads Rohdaten'!$A$4:$A$503,$E$4*1))) -> 5 | O8: =IF(OR(M8="",M8=0),"–",N8/M8) -> 0.055555556 | P8: =IF(OR(M8="",M8=0),"",IF(N8/MAX(M8,1)>=0.1,"✅",IF(N8/MAX(M8,1)>=0.03,"⚠","⛔"))) -> ⚠
A9: KW 5 | B9: =IF($E$4="Alle",COUNTIFS(Vertragseingänge!$A$4:$A$500,A9),COUNTIFS(Vertragseingänge!$A$4:$A$500,A9,Vertragseingänge!$C$4:$C$500,$E$4*1)) -> 10 | C9: =IFERROR(IF(Steuerung!$B$16="","",IF($E$4="Alle",IF(COUNTIFS(Vertragseingänge!$A$4:$A$500,A9,Vertragseingänge!$E$4:$E$500,Steuerung!$B$16)=0,"",COUNTIFS(Vertragseingänge!$A$4:$A$500,A9,Vertragseingänge!$E$4:$E$500,Steuerung!$B$16)),IF(COUNTIFS(Vertragseingänge!$A$4:$A$500,A9,Vertragseingänge!$E$4:$E$500,Steuerung!$B$16,Vertragseingänge!$C$4:$C$500,$E$4*1)=0,"",COUNTIFS(Vertragseingänge!$A$4:$A$500,A9,Vertragseingänge!$E$4:$E$500,Steuerung!$B$16,Vertragseingänge!$C$4:$C$500,$E$4*1)))),"") -> 3 | D9: =IFERROR(IF(Steuerung!$B$17="","",IF($E$4="Alle",IF(COUNTIFS(Vertragseingänge!$A$4:$A$500,A9,Vertragseingänge!$E$4:$E$500,Steuerung!$B$17)=0,"",COUNTIFS(Vertragseingänge!$A$4:$A$500,A9,Vertragseingänge!$E$4:$E$500,Steuerung!$B$17)),IF(COUNTIFS(Vertragseingänge!$A$4:$A$500,A9,Vertragseingänge!$E$4:$E$500,Steuerung!$B$17,Vertragseingänge!$C$4:$C$500,$E$4*1)=0,"",COUNTIFS(Vertragseingänge!$A$4:$A$500,A9,Vertragseingänge!$E$4:$E$500,Steuerung!$B$17,Vertragseingänge!$C$4:$C$500,$E$4*1)))),"") -> 1 | E9: =IFERROR(IF(Steuerung!$B$18="","",IF($E$4="Alle",IF(COUNTIFS(Vertragseingänge!$A$4:$A$500,A9,Vertragseingänge!$E$4:$E$500,Steuerung!$B$18)=0,"",COUNTIFS(Vertragseingänge!$A$4:$A$500,A9,Vertragseingänge!$E$4:$E$500,Steuerung!$B$18)),IF(COUNTIFS(Vertragseingänge!$A$4:$A$500,A9,Vertragseingänge!$E$4:$E$500,Steuerung!$B$18,Vertragseingänge!$C$4:$C$500,$E$4*1)=0,"",COUNTIFS(Vertragseingänge!$A$4:$A$500,A9,Vertragseingänge!$E$4:$E$500,Steuerung!$B$18,Vertragseingänge!$C$4:$C$500,$E$4*1)))),"") -> 2 | F9: =IFERROR(IF(Steuerung!$B$19="","",IF($E$4="Alle",IF(COUNTIFS(Vertragseingänge!$A$4:$A$500,A9,Vertragseingänge!$E$4:$E$500,Steuerung!$B$19)=0,"",COUNTIFS(Vertragseingänge!$A$4:$A$500,A9,Vertragseingänge!$E$4:$E$500,Steuerung!$B$19)),IF(COUNTIFS(Vertragseingänge!$A$4:$A$500,A9,Vertragseingänge!$E$4:$E$500,Steuerung!$B$19,Vertragseingänge!$C$4:$C$500,$E$4*1)=0,"",COUNTIFS(Vertragseingänge!$A$4:$A$500,A9,Vertragseingänge!$E$4:$E$500,Steuerung!$B$19,Vertragseingänge!$C$4:$C$500,$E$4*1)))),"") | G9: =IFERROR(IF(Steuerung!$B$20="","",IF($E$4="Alle",IF(COUNTIFS(Vertragseingänge!$A$4:$A$500,A9,Vertragseingänge!$E$4:$E$500,Steuerung!$B$20)=0,"",COUNTIFS(Vertragseingänge!$A$4:$A$500,A9,Vertragseingänge!$E$4:$E$500,Steuerung!$B$20)),IF(COUNTIFS(Vertragseingänge!$A$4:$A$500,A9,Vertragseingänge!$E$4:$E$500,Steuerung!$B$20,Vertragseingänge!$C$4:$C$500,$E$4*1)=0,"",COUNTIFS(Vertragseingänge!$A$4:$A$500,A9,Vertragseingänge!$E$4:$E$500,Steuerung!$B$20,Vertragseingänge!$C$4:$C$500,$E$4*1)))),"") | H9: =IFERROR(IF(Steuerung!$B$21="","",IF($E$4="Alle",IF(COUNTIFS(Vertragseingänge!$A$4:$A$500,A9,Vertragseingänge!$E$4:$E$500,Steuerung!$B$21)=0,"",COUNTIFS(Vertragseingänge!$A$4:$A$500,A9,Vertragseingänge!$E$4:$E$500,Steuerung!$B$21)),IF(COUNTIFS(Vertragseingänge!$A$4:$A$500,A9,Vertragseingänge!$E$4:$E$500,Steuerung!$B$21,Vertragseingänge!$C$4:$C$500,$E$4*1)=0,"",COUNTIFS(Vertragseingänge!$A$4:$A$500,A9,Vertragseingänge!$E$4:$E$500,Steuerung!$B$21,Vertragseingänge!$C$4:$C$500,$E$4*1)))),"") | I9: =IFERROR(IF(Steuerung!$B$22="","",IF($E$4="Alle",IF(COUNTIFS(Vertragseingänge!$A$4:$A$500,A9,Vertragseingänge!$E$4:$E$500,Steuerung!$B$22)=0,"",COUNTIFS(Vertragseingänge!$A$4:$A$500,A9,Vertragseingänge!$E$4:$E$500,Steuerung!$B$22)),IF(COUNTIFS(Vertragseingänge!$A$4:$A$500,A9,Vertragseingänge!$E$4:$E$500,Steuerung!$B$22,Vertragseingänge!$C$4:$C$500,$E$4*1)=0,"",COUNTIFS(Vertragseingänge!$A$4:$A$500,A9,Vertragseingänge!$E$4:$E$500,Steuerung!$B$22,Vertragseingänge!$C$4:$C$500,$E$4*1)))),"") | J9: =IFERROR(IF(B9-SUM(C9:I9)=0,"",B9-SUM(C9:I9)),"") -> 4 | L9: =IF(Steuerung!B8="","",Steuerung!C8) -> Gerd | M9: =IF(Steuerung!$B$8="","",IF($E$4="Alle",SUMIFS('Leads Rohdaten'!$D$4:$D$503,'Leads Rohdaten'!$C$4:$C$503,Steuerung!$B$8,'Leads Rohdaten'!$H$4:$H$503,"Reif"),SUMIFS('Leads Rohdaten'!$D$4:$D$503,'Leads Rohdaten'!$C$4:$C$503,Steuerung!$B$8,'Leads Rohdaten'!$H$4:$H$503,"Reif",'Leads Rohdaten'!$A$4:$A$503,$E$4*1))) -> 33 | N9: =IF(Steuerung!$B$8="","",IF($E$4="Alle",SUMIFS('Leads Rohdaten'!$E$4:$E$503,'Leads Rohdaten'!$C$4:$C$503,Steuerung!$B$8,'Leads Rohdaten'!$H$4:$H$503,"Reif"),SUMIFS('Leads Rohdaten'!$E$4:$E$503,'Leads Rohdaten'!$C$4:$C$503,Steuerung!$B$8,'Leads Rohdaten'!$H$4:$H$503,"Reif",'Leads Rohdaten'!$A$4:$A$503,$E$4*1))) -> 3 | O9: =IF(OR(M9="",M9=0),"–",N9/M9) -> 0.090909091 | P9: =IF(OR(M9="",M9=0),"",IF(N9/MAX(M9,1)>=0.1,"✅",IF(N9/MAX(M9,1)>=0.03,"⚠","⛔"))) -> ⚠
A10: KW 6 | B10: =IF($E$4="Alle",COUNTIFS(Vertragseingänge!$A$4:$A$500,A10),COUNTIFS(Vertragseingänge!$A$4:$A$500,A10,Vertragseingänge!$C$4:$C$500,$E$4*1)) -> 10 | C10: =IFERROR(IF(Steuerung!$B$16="","",IF($E$4="Alle",IF(COUNTIFS(Vertragseingänge!$A$4:$A$500,A10,Vertragseingänge!$E$4:$E$500,Steuerung!$B$16)=0,"",COUNTIFS(Vertragseingänge!$A$4:$A$500,A10,Vertragseingänge!$E$4:$E$500,Steuerung!$B$16)),IF(COUNTIFS(Vertragseingänge!$A$4:$A$500,A10,Vertragseingänge!$E$4:$E$500,Steuerung!$B$16,Vertragseingänge!$C$4:$C$500,$E$4*1)=0,"",COUNTIFS(Vertragseingänge!$A$4:$A$500,A10,Vertragseingänge!$E$4:$E$500,Steuerung!$B$16,Vertragseingänge!$C$4:$C$500,$E$4*1)))),"") -> 3 | D10: =IFERROR(IF(Steuerung!$B$17="","",IF($E$4="Alle",IF(COUNTIFS(Vertragseingänge!$A$4:$A$500,A10,Vertragseingänge!$E$4:$E$500,Steuerung!$B$17)=0,"",COUNTIFS(Vertragseingänge!$A$4:$A$500,A10,Vertragseingänge!$E$4:$E$500,Steuerung!$B$17)),IF(COUNTIFS(Vertragseingänge!$A$4:$A$500,A10,Vertragseingänge!$E$4:$E$500,Steuerung!$B$17,Vertragseingänge!$C$4:$C$500,$E$4*1)=0,"",COUNTIFS(Vertragseingänge!$A$4:$A$500,A10,Vertragseingänge!$E$4:$E$500,Steuerung!$B$17,Vertragseingänge!$C$4:$C$500,$E$4*1)))),"") -> 1 | E10: =IFERROR(IF(Steuerung!$B$18="","",IF($E$4="Alle",IF(COUNTIFS(Vertragseingänge!$A$4:$A$500,A10,Vertragseingänge!$E$4:$E$500,Steuerung!$B$18)=0,"",COUNTIFS(Vertragseingänge!$A$4:$A$500,A10,Vertragseingänge!$E$4:$E$500,Steuerung!$B$18)),IF(COUNTIFS(Vertragseingänge!$A$4:$A$500,A10,Vertragseingänge!$E$4:$E$500,Steuerung!$B$18,Vertragseingänge!$C$4:$C$500,$E$4*1)=0,"",COUNTIFS(Vertragseingänge!$A$4:$A$500,A10,Vertragseingänge!$E$4:$E$500,Steuerung!$B$18,Vertragseingänge!$C$4:$C$500,$E$4*1)))),"") -> 5 | F10: =IFERROR(IF(Steuerung!$B$19="","",IF($E$4="Alle",IF(COUNTIFS(Vertragseingänge!$A$4:$A$500,A10,Vertragseingänge!$E$4:$E$500,Steuerung!$B$19)=0,"",COUNTIFS(Vertragseingänge!$A$4:$A$500,A10,Vertragseingänge!$E$4:$E$500,Steuerung!$B$19)),IF(COUNTIFS(Vertragseingänge!$A$4:$A$500,A10,Vertragseingänge!$E$4:$E$500,Steuerung!$B$19,Vertragseingänge!$C$4:$C$500,$E$4*1)=0,"",COUNTIFS(Vertragseingänge!$A$4:$A$500,A10,Vertragseingänge!$E$4:$E$500,Steuerung!$B$19,Vertragseingänge!$C$4:$C$500,$E$4*1)))),"") | G10: =IFERROR(IF(Steuerung!$B$20="","",IF($E$4="Alle",IF(COUNTIFS(Vertragseingänge!$A$4:$A$500,A10,Vertragseingänge!$E$4:$E$500,Steuerung!$B$20)=0,"",COUNTIFS(Vertragseingänge!$A$4:$A$500,A10,Vertragseingänge!$E$4:$E$500,Steuerung!$B$20)),IF(COUNTIFS(Vertragseingänge!$A$4:$A$500,A10,Vertragseingänge!$E$4:$E$500,Steuerung!$B$20,Vertragseingänge!$C$4:$C$500,$E$4*1)=0,"",COUNTIFS(Vertragseingänge!$A$4:$A$500,A10,Vertragseingänge!$E$4:$E$500,Steuerung!$B$20,Vertragseingänge!$C$4:$C$500,$E$4*1)))),"") | H10: =IFERROR(IF(Steuerung!$B$21="","",IF($E$4="Alle",IF(COUNTIFS(Vertragseingänge!$A$4:$A$500,A10,Vertragseingänge!$E$4:$E$500,Steuerung!$B$21)=0,"",COUNTIFS(Vertragseingänge!$A$4:$A$500,A10,Vertragseingänge!$E$4:$E$500,Steuerung!$B$21)),IF(COUNTIFS(Vertragseingänge!$A$4:$A$500,A10,Vertragseingänge!$E$4:$E$500,Steuerung!$B$21,Vertragseingänge!$C$4:$C$500,$E$4*1)=0,"",COUNTIFS(Vertragseingänge!$A$4:$A$500,A10,Vertragseingänge!$E$4:$E$500,Steuerung!$B$21,Vertragseingänge!$C$4:$C$500,$E$4*1)))),"") | I10: =IFERROR(IF(Steuerung!$B$22="","",IF($E$4="Alle",IF(COUNTIFS(Vertragseingänge!$A$4:$A$500,A10,Vertragseingänge!$E$4:$E$500,Steuerung!$B$22)=0,"",COUNTIFS(Vertragseingänge!$A$4:$A$500,A10,Vertragseingänge!$E$4:$E$500,Steuerung!$B$22)),IF(COUNTIFS(Vertragseingänge!$A$4:$A$500,A10,Vertragseingänge!$E$4:$E$500,Steuerung!$B$22,Vertragseingänge!$C$4:$C$500,$E$4*1)=0,"",COUNTIFS(Vertragseingänge!$A$4:$A$500,A10,Vertragseingänge!$E$4:$E$500,Steuerung!$B$22,Vertragseingänge!$C$4:$C$500,$E$4*1)))),"") | J10: =IFERROR(IF(B10-SUM(C10:I10)=0,"",B10-SUM(C10:I10)),"") -> 1 | L10: =IF(Steuerung!B9="","",Steuerung!C9) -> David | M10: =IF(Steuerung!$B$9="","",IF($E$4="Alle",SUMIFS('Leads Rohdaten'!$D$4:$D$503,'Leads Rohdaten'!$C$4:$C$503,Steuerung!$B$9,'Leads Rohdaten'!$H$4:$H$503,"Reif"),SUMIFS('Leads Rohdaten'!$D$4:$D$503,'Leads Rohdaten'!$C$4:$C$503,Steuerung!$B$9,'Leads Rohdaten'!$H$4:$H$503,"Reif",'Leads Rohdaten'!$A$4:$A$503,$E$4*1))) -> 0 | N10: =IF(Steuerung!$B$9="","",IF($E$4="Alle",SUMIFS('Leads Rohdaten'!$E$4:$E$503,'Leads Rohdaten'!$C$4:$C$503,Steuerung!$B$9,'Leads Rohdaten'!$H$4:$H$503,"Reif"),SUMIFS('Leads Rohdaten'!$E$4:$E$503,'Leads Rohdaten'!$C$4:$C$503,Steuerung!$B$9,'Leads Rohdaten'!$H$4:$H$503,"Reif",'Leads Rohdaten'!$A$4:$A$503,$E$4*1))) -> 0 | O10: =IF(OR(M10="",M10=0),"–",N10/M10) -> – | P10: =IF(OR(M10="",M10=0),"",IF(N10/MAX(M10,1)>=0.1,"✅",IF(N10/MAX(M10,1)>=0.03,"⚠","⛔")))
A11: KW 7 | B11: =IF($E$4="Alle",COUNTIFS(Vertragseingänge!$A$4:$A$500,A11),COUNTIFS(Vertragseingänge!$A$4:$A$500,A11,Vertragseingänge!$C$4:$C$500,$E$4*1)) -> 10 | C11: =IFERROR(IF(Steuerung!$B$16="","",IF($E$4="Alle",IF(COUNTIFS(Vertragseingänge!$A$4:$A$500,A11,Vertragseingänge!$E$4:$E$500,Steuerung!$B$16)=0,"",COUNTIFS(Vertragseingänge!$A$4:$A$500,A11,Vertragseingänge!$E$4:$E$500,Steuerung!$B$16)),IF(COUNTIFS(Vertragseingänge!$A$4:$A$500,A11,Vertragseingänge!$E$4:$E$500,Steuerung!$B$16,Vertragseingänge!$C$4:$C$500,$E$4*1)=0,"",COUNTIFS(Vertragseingänge!$A$4:$A$500,A11,Vertragseingänge!$E$4:$E$500,Steuerung!$B$16,Vertragseingänge!$C$4:$C$500,$E$4*1)))),"") -> 8 | D11: =IFERROR(IF(Steuerung!$B$17="","",IF($E$4="Alle",IF(COUNTIFS(Vertragseingänge!$A$4:$A$500,A11,Vertragseingänge!$E$4:$E$500,Steuerung!$B$17)=0,"",COUNTIFS(Vertragseingänge!$A$4:$A$500,A11,Vertragseingänge!$E$4:$E$500,Steuerung!$B$17)),IF(COUNTIFS(Vertragseingänge!$A$4:$A$500,A11,Vertragseingänge!$E$4:$E$500,Steuerung!$B$17,Vertragseingänge!$C$4:$C$500,$E$4*1)=0,"",COUNTIFS(Vertragseingänge!$A$4:$A$500,A11,Vertragseingänge!$E$4:$E$500,Steuerung!$B$17,Vertragseingänge!$C$4:$C$500,$E$4*1)))),"") | E11: =IFERROR(IF(Steuerung!$B$18="","",IF($E$4="Alle",IF(COUNTIFS(Vertragseingänge!$A$4:$A$500,A11,Vertragseingänge!$E$4:$E$500,Steuerung!$B$18)=0,"",COUNTIFS(Vertragseingänge!$A$4:$A$500,A11,Vertragseingänge!$E$4:$E$500,Steuerung!$B$18)),IF(COUNTIFS(Vertragseingänge!$A$4:$A$500,A11,Vertragseingänge!$E$4:$E$500,Steuerung!$B$18,Vertragseingänge!$C$4:$C$500,$E$4*1)=0,"",COUNTIFS(Vertragseingänge!$A$4:$A$500,A11,Vertragseingänge!$E$4:$E$500,Steuerung!$B$18,Vertragseingänge!$C$4:$C$500,$E$4*1)))),"") | F11: =IFERROR(IF(Steuerung!$B$19="","",IF($E$4="Alle",IF(COUNTIFS(Vertragseingänge!$A$4:$A$500,A11,Vertragseingänge!$E$4:$E$500,Steuerung!$B$19)=0,"",COUNTIFS(Vertragseingänge!$A$4:$A$500,A11,Vertragseingänge!$E$4:$E$500,Steuerung!$B$19)),IF(COUNTIFS(Vertragseingänge!$A$4:$A$500,A11,Vertragseingänge!$E$4:$E$500,Steuerung!$B$19,Vertragseingänge!$C$4:$C$500,$E$4*1)=0,"",COUNTIFS(Vertragseingänge!$A$4:$A$500,A11,Vertragseingänge!$E$4:$E$500,Steuerung!$B$19,Vertragseingänge!$C$4:$C$500,$E$4*1)))),"") | G11: =IFERROR(IF(Steuerung!$B$20="","",IF($E$4="Alle",IF(COUNTIFS(Vertragseingänge!$A$4:$A$500,A11,Vertragseingänge!$E$4:$E$500,Steuerung!$B$20)=0,"",COUNTIFS(Vertragseingänge!$A$4:$A$500,A11,Vertragseingänge!$E$4:$E$500,Steuerung!$B$20)),IF(COUNTIFS(Vertragseingänge!$A$4:$A$500,A11,Vertragseingänge!$E$4:$E$500,Steuerung!$B$20,Vertragseingänge!$C$4:$C$500,$E$4*1)=0,"",COUNTIFS(Vertragseingänge!$A$4:$A$500,A11,Vertragseingänge!$E$4:$E$500,Steuerung!$B$20,Vertragseingänge!$C$4:$C$500,$E$4*1)))),"") -> 1 | H11: =IFERROR(IF(Steuerung!$B$21="","",IF($E$4="Alle",IF(COUNTIFS(Vertragseingänge!$A$4:$A$500,A11,Vertragseingänge!$E$4:$E$500,Steuerung!$B$21)=0,"",COUNTIFS(Vertragseingänge!$A$4:$A$500,A11,Vertragseingänge!$E$4:$E$500,Steuerung!$B$21)),IF(COUNTIFS(Vertragseingänge!$A$4:$A$500,A11,Vertragseingänge!$E$4:$E$500,Steuerung!$B$21,Vertragseingänge!$C$4:$C$500,$E$4*1)=0,"",COUNTIFS(Vertragseingänge!$A$4:$A$500,A11,Vertragseingänge!$E$4:$E$500,Steuerung!$B$21,Vertragseingänge!$C$4:$C$500,$E$4*1)))),"") | I11: =IFERROR(IF(Steuerung!$B$22="","",IF($E$4="Alle",IF(COUNTIFS(Vertragseingänge!$A$4:$A$500,A11,Vertragseingänge!$E$4:$E$500,Steuerung!$B$22)=0,"",COUNTIFS(Vertragseingänge!$A$4:$A$500,A11,Vertragseingänge!$E$4:$E$500,Steuerung!$B$22)),IF(COUNTIFS(Vertragseingänge!$A$4:$A$500,A11,Vertragseingänge!$E$4:$E$500,Steuerung!$B$22,Vertragseingänge!$C$4:$C$500,$E$4*1)=0,"",COUNTIFS(Vertragseingänge!$A$4:$A$500,A11,Vertragseingänge!$E$4:$E$500,Steuerung!$B$22,Vertragseingänge!$C$4:$C$500,$E$4*1)))),"") | J11: =IFERROR(IF(B11-SUM(C11:I11)=0,"",B11-SUM(C11:I11)),"") -> 1 | L11: =IF(Steuerung!B10="","",Steuerung!C10) | M11: =IF(Steuerung!$B$10="","",IF($E$4="Alle",SUMIFS('Leads Rohdaten'!$D$4:$D$503,'Leads Rohdaten'!$C$4:$C$503,Steuerung!$B$10,'Leads Rohdaten'!$H$4:$H$503,"Reif"),SUMIFS('Leads Rohdaten'!$D$4:$D$503,'Leads Rohdaten'!$C$4:$C$503,Steuerung!$B$10,'Leads Rohdaten'!$H$4:$H$503,"Reif",'Leads Rohdaten'!$A$4:$A$503,$E$4*1))) | N11: =IF(Steuerung!$B$10="","",IF($E$4="Alle",SUMIFS('Leads Rohdaten'!$E$4:$E$503,'Leads Rohdaten'!$C$4:$C$503,Steuerung!$B$10,'Leads Rohdaten'!$H$4:$H$503,"Reif"),SUMIFS('Leads Rohdaten'!$E$4:$E$503,'Leads Rohdaten'!$C$4:$C$503,Steuerung!$B$10,'Leads Rohdaten'!$H$4:$H$503,"Reif",'Leads Rohdaten'!$A$4:$A$503,$E$4*1))) | O11: =IF(OR(M11="",M11=0),"–",N11/M11) -> – | P11: =IF(OR(M11="",M11=0),"",IF(N11/MAX(M11,1)>=0.1,"✅",IF(N11/MAX(M11,1)>=0.03,"⚠","⛔")))
A12: KW 8 | B12: =IF($E$4="Alle",COUNTIFS(Vertragseingänge!$A$4:$A$500,A12),COUNTIFS(Vertragseingänge!$A$4:$A$500,A12,Vertragseingänge!$C$4:$C$500,$E$4*1)) -> 6 | C12: =IFERROR(IF(Steuerung!$B$16="","",IF($E$4="Alle",IF(COUNTIFS(Vertragseingänge!$A$4:$A$500,A12,Vertragseingänge!$E$4:$E$500,Steuerung!$B$16)=0,"",COUNTIFS(Vertragseingänge!$A$4:$A$500,A12,Vertragseingänge!$E$4:$E$500,Steuerung!$B$16)),IF(COUNTIFS(Vertragseingänge!$A$4:$A$500,A12,Vertragseingänge!$E$4:$E$500,Steuerung!$B$16,Vertragseingänge!$C$4:$C$500,$E$4*1)=0,"",COUNTIFS(Vertragseingänge!$A$4:$A$500,A12,Vertragseingänge!$E$4:$E$500,Steuerung!$B$16,Vertragseingänge!$C$4:$C$500,$E$4*1)))),"") -> 1 | D12: =IFERROR(IF(Steuerung!$B$17="","",IF($E$4="Alle",IF(COUNTIFS(Vertragseingänge!$A$4:$A$500,A12,Vertragseingänge!$E$4:$E$500,Steuerung!$B$17)=0,"",COUNTIFS(Vertragseingänge!$A$4:$A$500,A12,Vertragseingänge!$E$4:$E$500,Steuerung!$B$17)),IF(COUNTIFS(Vertragseingänge!$A$4:$A$500,A12,Vertragseingänge!$E$4:$E$500,Steuerung!$B$17,Vertragseingänge!$C$4:$C$500,$E$4*1)=0,"",COUNTIFS(Vertragseingänge!$A$4:$A$500,A12,Vertragseingänge!$E$4:$E$500,Steuerung!$B$17,Vertragseingänge!$C$4:$C$500,$E$4*1)))),"") -> 2 | E12: =IFERROR(IF(Steuerung!$B$18="","",IF($E$4="Alle",IF(COUNTIFS(Vertragseingänge!$A$4:$A$500,A12,Vertragseingänge!$E$4:$E$500,Steuerung!$B$18)=0,"",COUNTIFS(Vertragseingänge!$A$4:$A$500,A12,Vertragseingänge!$E$4:$E$500,Steuerung!$B$18)),IF(COUNTIFS(Vertragseingänge!$A$4:$A$500,A12,Vertragseingänge!$E$4:$E$500,Steuerung!$B$18,Vertragseingänge!$C$4:$C$500,$E$4*1)=0,"",COUNTIFS(Vertragseingänge!$A$4:$A$500,A12,Vertragseingänge!$E$4:$E$500,Steuerung!$B$18,Vertragseingänge!$C$4:$C$500,$E$4*1)))),"") -> 2 | F12: =IFERROR(IF(Steuerung!$B$19="","",IF($E$4="Alle",IF(COUNTIFS(Vertragseingänge!$A$4:$A$500,A12,Vertragseingänge!$E$4:$E$500,Steuerung!$B$19)=0,"",COUNTIFS(Vertragseingänge!$A$4:$A$500,A12,Vertragseingänge!$E$4:$E$500,Steuerung!$B$19)),IF(COUNTIFS(Vertragseingänge!$A$4:$A$500,A12,Vertragseingänge!$E$4:$E$500,Steuerung!$B$19,Vertragseingänge!$C$4:$C$500,$E$4*1)=0,"",COUNTIFS(Vertragseingänge!$A$4:$A$500,A12,Vertragseingänge!$E$4:$E$500,Steuerung!$B$19,Vertragseingänge!$C$4:$C$500,$E$4*1)))),"") | G12: =IFERROR(IF(Steuerung!$B$20="","",IF($E$4="Alle",IF(COUNTIFS(Vertragseingänge!$A$4:$A$500,A12,Vertragseingänge!$E$4:$E$500,Steuerung!$B$20)=0,"",COUNTIFS(Vertragseingänge!$A$4:$A$500,A12,Vertragseingänge!$E$4:$E$500,Steuerung!$B$20)),IF(COUNTIFS(Vertragseingänge!$A$4:$A$500,A12,Vertragseingänge!$E$4:$E$500,Steuerung!$B$20,Vertragseingänge!$C$4:$C$500,$E$4*1)=0,"",COUNTIFS(Vertragseingänge!$A$4:$A$500,A12,Vertragseingänge!$E$4:$E$500,Steuerung!$B$20,Vertragseingänge!$C$4:$C$500,$E$4*1)))),"") | H12: =IFERROR(IF(Steuerung!$B$21="","",IF($E$4="Alle",IF(COUNTIFS(Vertragseingänge!$A$4:$A$500,A12,Vertragseingänge!$E$4:$E$500,Steuerung!$B$21)=0,"",COUNTIFS(Vertragseingänge!$A$4:$A$500,A12,Vertragseingänge!$E$4:$E$500,Steuerung!$B$21)),IF(COUNTIFS(Vertragseingänge!$A$4:$A$500,A12,Vertragseingänge!$E$4:$E$500,Steuerung!$B$21,Vertragseingänge!$C$4:$C$500,$E$4*1)=0,"",COUNTIFS(Vertragseingänge!$A$4:$A$500,A12,Vertragseingänge!$E$4:$E$500,Steuerung!$B$21,Vertragseingänge!$C$4:$C$500,$E$4*1)))),"") | I12: =IFERROR(IF(Steuerung!$B$22="","",IF($E$4="Alle",IF(COUNTIFS(Vertragseingänge!$A$4:$A$500,A12,Vertragseingänge!$E$4:$E$500,Steuerung!$B$22)=0,"",COUNTIFS(Vertragseingänge!$A$4:$A$500,A12,Vertragseingänge!$E$4:$E$500,Steuerung!$B$22)),IF(COUNTIFS(Vertragseingänge!$A$4:$A$500,A12,Vertragseingänge!$E$4:$E$500,Steuerung!$B$22,Vertragseingänge!$C$4:$C$500,$E$4*1)=0,"",COUNTIFS(Vertragseingänge!$A$4:$A$500,A12,Vertragseingänge!$E$4:$E$500,Steuerung!$B$22,Vertragseingänge!$C$4:$C$500,$E$4*1)))),"") | J12: =IFERROR(IF(B12-SUM(C12:I12)=0,"",B12-SUM(C12:I12)),"") -> 1 | L12: =IF(Steuerung!B11="","",Steuerung!C11) | M12: =IF(Steuerung!$B$11="","",IF($E$4="Alle",SUMIFS('Leads Rohdaten'!$D$4:$D$503,'Leads Rohdaten'!$C$4:$C$503,Steuerung!$B$11,'Leads Rohdaten'!$H$4:$H$503,"Reif"),SUMIFS('Leads Rohdaten'!$D$4:$D$503,'Leads Rohdaten'!$C$4:$C$503,Steuerung!$B$11,'Leads Rohdaten'!$H$4:$H$503,"Reif",'Leads Rohdaten'!$A$4:$A$503,$E$4*1))) | N12: =IF(Steuerung!$B$11="","",IF($E$4="Alle",SUMIFS('Leads Rohdaten'!$E$4:$E$503,'Leads Rohdaten'!$C$4:$C$503,Steuerung!$B$11,'Leads Rohdaten'!$H$4:$H$503,"Reif"),SUMIFS('Leads Rohdaten'!$E$4:$E$503,'Leads Rohdaten'!$C$4:$C$503,Steuerung!$B$11,'Leads Rohdaten'!$H$4:$H$503,"Reif",'Leads Rohdaten'!$A$4:$A$503,$E$4*1))) | O12: =IF(OR(M12="",M12=0),"–",N12/M12) -> – | P12: =IF(OR(M12="",M12=0),"",IF(N12/MAX(M12,1)>=0.1,"✅",IF(N12/MAX(M12,1)>=0.03,"⚠","⛔")))
A13: KW 9 | B13: =IF($E$4="Alle",COUNTIFS(Vertragseingänge!$A$4:$A$500,A13),COUNTIFS(Vertragseingänge!$A$4:$A$500,A13,Vertragseingänge!$C$4:$C$500,$E$4*1)) -> 4 | C13: =IFERROR(IF(Steuerung!$B$16="","",IF($E$4="Alle",IF(COUNTIFS(Vertragseingänge!$A$4:$A$500,A13,Vertragseingänge!$E$4:$E$500,Steuerung!$B$16)=0,"",COUNTIFS(Vertragseingänge!$A$4:$A$500,A13,Vertragseingänge!$E$4:$E$500,Steuerung!$B$16)),IF(COUNTIFS(Vertragseingänge!$A$4:$A$500,A13,Vertragseingänge!$E$4:$E$500,Steuerung!$B$16,Vertragseingänge!$C$4:$C$500,$E$4*1)=0,"",COUNTIFS(Vertragseingänge!$A$4:$A$500,A13,Vertragseingänge!$E$4:$E$500,Steuerung!$B$16,Vertragseingänge!$C$4:$C$500,$E$4*1)))),"") -> 1 | D13: =IFERROR(IF(Steuerung!$B$17="","",IF($E$4="Alle",IF(COUNTIFS(Vertragseingänge!$A$4:$A$500,A13,Vertragseingänge!$E$4:$E$500,Steuerung!$B$17)=0,"",COUNTIFS(Vertragseingänge!$A$4:$A$500,A13,Vertragseingänge!$E$4:$E$500,Steuerung!$B$17)),IF(COUNTIFS(Vertragseingänge!$A$4:$A$500,A13,Vertragseingänge!$E$4:$E$500,Steuerung!$B$17,Vertragseingänge!$C$4:$C$500,$E$4*1)=0,"",COUNTIFS(Vertragseingänge!$A$4:$A$500,A13,Vertragseingänge!$E$4:$E$500,Steuerung!$B$17,Vertragseingänge!$C$4:$C$500,$E$4*1)))),"") | E13: =IFERROR(IF(Steuerung!$B$18="","",IF($E$4="Alle",IF(COUNTIFS(Vertragseingänge!$A$4:$A$500,A13,Vertragseingänge!$E$4:$E$500,Steuerung!$B$18)=0,"",COUNTIFS(Vertragseingänge!$A$4:$A$500,A13,Vertragseingänge!$E$4:$E$500,Steuerung!$B$18)),IF(COUNTIFS(Vertragseingänge!$A$4:$A$500,A13,Vertragseingänge!$E$4:$E$500,Steuerung!$B$18,Vertragseingänge!$C$4:$C$500,$E$4*1)=0,"",COUNTIFS(Vertragseingänge!$A$4:$A$500,A13,Vertragseingänge!$E$4:$E$500,Steuerung!$B$18,Vertragseingänge!$C$4:$C$500,$E$4*1)))),"") | F13: =IFERROR(IF(Steuerung!$B$19="","",IF($E$4="Alle",IF(COUNTIFS(Vertragseingänge!$A$4:$A$500,A13,Vertragseingänge!$E$4:$E$500,Steuerung!$B$19)=0,"",COUNTIFS(Vertragseingänge!$A$4:$A$500,A13,Vertragseingänge!$E$4:$E$500,Steuerung!$B$19)),IF(COUNTIFS(Vertragseingänge!$A$4:$A$500,A13,Vertragseingänge!$E$4:$E$500,Steuerung!$B$19,Vertragseingänge!$C$4:$C$500,$E$4*1)=0,"",COUNTIFS(Vertragseingänge!$A$4:$A$500,A13,Vertragseingänge!$E$4:$E$500,Steuerung!$B$19,Vertragseingänge!$C$4:$C$500,$E$4*1)))),"") | G13: =IFERROR(IF(Steuerung!$B$20="","",IF($E$4="Alle",IF(COUNTIFS(Vertragseingänge!$A$4:$A$500,A13,Vertragseingänge!$E$4:$E$500,Steuerung!$B$20)=0,"",COUNTIFS(Vertragseingänge!$A$4:$A$500,A13,Vertragseingänge!$E$4:$E$500,Steuerung!$B$20)),IF(COUNTIFS(Vertragseingänge!$A$4:$A$500,A13,Vertragseingänge!$E$4:$E$500,Steuerung!$B$20,Vertragseingänge!$C$4:$C$500,$E$4*1)=0,"",COUNTIFS(Vertragseingänge!$A$4:$A$500,A13,Vertragseingänge!$E$4:$E$500,Steuerung!$B$20,Vertragseingänge!$C$4:$C$500,$E$4*1)))),"") -> 1 | H13: =IFERROR(IF(Steuerung!$B$21="","",IF($E$4="Alle",IF(COUNTIFS(Vertragseingänge!$A$4:$A$500,A13,Vertragseingänge!$E$4:$E$500,Steuerung!$B$21)=0,"",COUNTIFS(Vertragseingänge!$A$4:$A$500,A13,Vertragseingänge!$E$4:$E$500,Steuerung!$B$21)),IF(COUNTIFS(Vertragseingänge!$A$4:$A$500,A13,Vertragseingänge!$E$4:$E$500,Steuerung!$B$21,Vertragseingänge!$C$4:$C$500,$E$4*1)=0,"",COUNTIFS(Vertragseingänge!$A$4:$A$500,A13,Vertragseingänge!$E$4:$E$500,Steuerung!$B$21,Vertragseingänge!$C$4:$C$500,$E$4*1)))),"") -> 1 | I13: =IFERROR(IF(Steuerung!$B$22="","",IF($E$4="Alle",IF(COUNTIFS(Vertragseingänge!$A$4:$A$500,A13,Vertragseingänge!$E$4:$E$500,Steuerung!$B$22)=0,"",COUNTIFS(Vertragseingänge!$A$4:$A$500,A13,Vertragseingänge!$E$4:$E$500,Steuerung!$B$22)),IF(COUNTIFS(Vertragseingänge!$A$4:$A$500,A13,Vertragseingänge!$E$4:$E$500,Steuerung!$B$22,Vertragseingänge!$C$4:$C$500,$E$4*1)=0,"",COUNTIFS(Vertragseingänge!$A$4:$A$500,A13,Vertragseingänge!$E$4:$E$500,Steuerung!$B$22,Vertragseingänge!$C$4:$C$500,$E$4*1)))),"") | J13: =IFERROR(IF(B13-SUM(C13:I13)=0,"",B13-SUM(C13:I13)),"") -> 1 | L13: GESAMT | M13: =SUM(M7:M12) -> 333 | N13: =SUM(N7:N12) -> 29 | O13: =IF(M13=0,"-",N13/M13) -> 0.087087087
A14: KW 10 | B14: =IF($E$4="Alle",COUNTIFS(Vertragseingänge!$A$4:$A$500,A14),COUNTIFS(Vertragseingänge!$A$4:$A$500,A14,Vertragseingänge!$C$4:$C$500,$E$4*1)) -> 8 | C14: =IFERROR(IF(Steuerung!$B$16="","",IF($E$4="Alle",IF(COUNTIFS(Vertragseingänge!$A$4:$A$500,A14,Vertragseingänge!$E$4:$E$500,Steuerung!$B$16)=0,"",COUNTIFS(Vertragseingänge!$A$4:$A$500,A14,Vertragseingänge!$E$4:$E$500,Steuerung!$B$16)),IF(COUNTIFS(Vertragseingänge!$A$4:$A$500,A14,Vertragseingänge!$E$4:$E$500,Steuerung!$B$16,Vertragseingänge!$C$4:$C$500,$E$4*1)=0,"",COUNTIFS(Vertragseingänge!$A$4:$A$500,A14,Vertragseingänge!$E$4:$E$500,Steuerung!$B$16,Vertragseingänge!$C$4:$C$500,$E$4*1)))),"") -> 2 | D14: =IFERROR(IF(Steuerung!$B$17="","",IF($E$4="Alle",IF(COUNTIFS(Vertragseingänge!$A$4:$A$500,A14,Vertragseingänge!$E$4:$E$500,Steuerung!$B$17)=0,"",COUNTIFS(Vertragseingänge!$A$4:$A$500,A14,Vertragseingänge!$E$4:$E$500,Steuerung!$B$17)),IF(COUNTIFS(Vertragseingänge!$A$4:$A$500,A14,Vertragseingänge!$E$4:$E$500,Steuerung!$B$17,Vertragseingänge!$C$4:$C$500,$E$4*1)=0,"",COUNTIFS(Vertragseingänge!$A$4:$A$500,A14,Vertragseingänge!$E$4:$E$500,Steuerung!$B$17,Vertragseingänge!$C$4:$C$500,$E$4*1)))),"") -> 1 | E14: =IFERROR(IF(Steuerung!$B$18="","",IF($E$4="Alle",IF(COUNTIFS(Vertragseingänge!$A$4:$A$500,A14,Vertragseingänge!$E$4:$E$500,Steuerung!$B$18)=0,"",COUNTIFS(Vertragseingänge!$A$4:$A$500,A14,Vertragseingänge!$E$4:$E$500,Steuerung!$B$18)),IF(COUNTIFS(Vertragseingänge!$A$4:$A$500,A14,Vertragseingänge!$E$4:$E$500,Steuerung!$B$18,Vertragseingänge!$C$4:$C$500,$E$4*1)=0,"",COUNTIFS(Vertragseingänge!$A$4:$A$500,A14,Vertragseingänge!$E$4:$E$500,Steuerung!$B$18,Vertragseingänge!$C$4:$C$500,$E$4*1)))),"") -> 2 | F14: =IFERROR(IF(Steuerung!$B$19="","",IF($E$4="Alle",IF(COUNTIFS(Vertragseingänge!$A$4:$A$500,A14,Vertragseingänge!$E$4:$E$500,Steuerung!$B$19)=0,"",COUNTIFS(Vertragseingänge!$A$4:$A$500,A14,Vertragseingänge!$E$4:$E$500,Steuerung!$B$19)),IF(COUNTIFS(Vertragseingänge!$A$4:$A$500,A14,Vertragseingänge!$E$4:$E$500,Steuerung!$B$19,Vertragseingänge!$C$4:$C$500,$E$4*1)=0,"",COUNTIFS(Vertragseingänge!$A$4:$A$500,A14,Vertragseingänge!$E$4:$E$500,Steuerung!$B$19,Vertragseingänge!$C$4:$C$500,$E$4*1)))),"") | G14: =IFERROR(IF(Steuerung!$B$20="","",IF($E$4="Alle",IF(COUNTIFS(Vertragseingänge!$A$4:$A$500,A14,Vertragseingänge!$E$4:$E$500,Steuerung!$B$20)=0,"",COUNTIFS(Vertragseingänge!$A$4:$A$500,A14,Vertragseingänge!$E$4:$E$500,Steuerung!$B$20)),IF(COUNTIFS(Vertragseingänge!$A$4:$A$500,A14,Vertragseingänge!$E$4:$E$500,Steuerung!$B$20,Vertragseingänge!$C$4:$C$500,$E$4*1)=0,"",COUNTIFS(Vertragseingänge!$A$4:$A$500,A14,Vertragseingänge!$E$4:$E$500,Steuerung!$B$20,Vertragseingänge!$C$4:$C$500,$E$4*1)))),"") | H14: =IFERROR(IF(Steuerung!$B$21="","",IF($E$4="Alle",IF(COUNTIFS(Vertragseingänge!$A$4:$A$500,A14,Vertragseingänge!$E$4:$E$500,Steuerung!$B$21)=0,"",COUNTIFS(Vertragseingänge!$A$4:$A$500,A14,Vertragseingänge!$E$4:$E$500,Steuerung!$B$21)),IF(COUNTIFS(Vertragseingänge!$A$4:$A$500,A14,Vertragseingänge!$E$4:$E$500,Steuerung!$B$21,Vertragseingänge!$C$4:$C$500,$E$4*1)=0,"",COUNTIFS(Vertragseingänge!$A$4:$A$500,A14,Vertragseingänge!$E$4:$E$500,Steuerung!$B$21,Vertragseingänge!$C$4:$C$500,$E$4*1)))),"") | I14: =IFERROR(IF(Steuerung!$B$22="","",IF($E$4="Alle",IF(COUNTIFS(Vertragseingänge!$A$4:$A$500,A14,Vertragseingänge!$E$4:$E$500,Steuerung!$B$22)=0,"",COUNTIFS(Vertragseingänge!$A$4:$A$500,A14,Vertragseingänge!$E$4:$E$500,Steuerung!$B$22)),IF(COUNTIFS(Vertragseingänge!$A$4:$A$500,A14,Vertragseingänge!$E$4:$E$500,Steuerung!$B$22,Vertragseingänge!$C$4:$C$500,$E$4*1)=0,"",COUNTIFS(Vertragseingänge!$A$4:$A$500,A14,Vertragseingänge!$E$4:$E$500,Steuerung!$B$22,Vertragseingänge!$C$4:$C$500,$E$4*1)))),"") -> 1 | J14: =IFERROR(IF(B14-SUM(C14:I14)=0,"",B14-SUM(C14:I14)),"") -> 2
A15: KW 11 | B15: =IF($E$4="Alle",COUNTIFS(Vertragseingänge!$A$4:$A$500,A15),COUNTIFS(Vertragseingänge!$A$4:$A$500,A15,Vertragseingänge!$C$4:$C$500,$E$4*1)) -> 8 | C15: =IFERROR(IF(Steuerung!$B$16="","",IF($E$4="Alle",IF(COUNTIFS(Vertragseingänge!$A$4:$A$500,A15,Vertragseingänge!$E$4:$E$500,Steuerung!$B$16)=0,"",COUNTIFS(Vertragseingänge!$A$4:$A$500,A15,Vertragseingänge!$E$4:$E$500,Steuerung!$B$16)),IF(COUNTIFS(Vertragseingänge!$A$4:$A$500,A15,Vertragseingänge!$E$4:$E$500,Steuerung!$B$16,Vertragseingänge!$C$4:$C$500,$E$4*1)=0,"",COUNTIFS(Vertragseingänge!$A$4:$A$500,A15,Vertragseingänge!$E$4:$E$500,Steuerung!$B$16,Vertragseingänge!$C$4:$C$500,$E$4*1)))),"") -> 3 | D15: =IFERROR(IF(Steuerung!$B$17="","",IF($E$4="Alle",IF(COUNTIFS(Vertragseingänge!$A$4:$A$500,A15,Vertragseingänge!$E$4:$E$500,Steuerung!$B$17)=0,"",COUNTIFS(Vertragseingänge!$A$4:$A$500,A15,Vertragseingänge!$E$4:$E$500,Steuerung!$B$17)),IF(COUNTIFS(Vertragseingänge!$A$4:$A$500,A15,Vertragseingänge!$E$4:$E$500,Steuerung!$B$17,Vertragseingänge!$C$4:$C$500,$E$4*1)=0,"",COUNTIFS(Vertragseingänge!$A$4:$A$500,A15,Vertragseingänge!$E$4:$E$500,Steuerung!$B$17,Vertragseingänge!$C$4:$C$500,$E$4*1)))),"") -> 5 | E15: =IFERROR(IF(Steuerung!$B$18="","",IF($E$4="Alle",IF(COUNTIFS(Vertragseingänge!$A$4:$A$500,A15,Vertragseingänge!$E$4:$E$500,Steuerung!$B$18)=0,"",COUNTIFS(Vertragseingänge!$A$4:$A$500,A15,Vertragseingänge!$E$4:$E$500,Steuerung!$B$18)),IF(COUNTIFS(Vertragseingänge!$A$4:$A$500,A15,Vertragseingänge!$E$4:$E$500,Steuerung!$B$18,Vertragseingänge!$C$4:$C$500,$E$4*1)=0,"",COUNTIFS(Vertragseingänge!$A$4:$A$500,A15,Vertragseingänge!$E$4:$E$500,Steuerung!$B$18,Vertragseingänge!$C$4:$C$500,$E$4*1)))),"") | F15: =IFERROR(IF(Steuerung!$B$19="","",IF($E$4="Alle",IF(COUNTIFS(Vertragseingänge!$A$4:$A$500,A15,Vertragseingänge!$E$4:$E$500,Steuerung!$B$19)=0,"",COUNTIFS(Vertragseingänge!$A$4:$A$500,A15,Vertragseingänge!$E$4:$E$500,Steuerung!$B$19)),IF(COUNTIFS(Vertragseingänge!$A$4:$A$500,A15,Vertragseingänge!$E$4:$E$500,Steuerung!$B$19,Vertragseingänge!$C$4:$C$500,$E$4*1)=0,"",COUNTIFS(Vertragseingänge!$A$4:$A$500,A15,Vertragseingänge!$E$4:$E$500,Steuerung!$B$19,Vertragseingänge!$C$4:$C$500,$E$4*1)))),"") | G15: =IFERROR(IF(Steuerung!$B$20="","",IF($E$4="Alle",IF(COUNTIFS(Vertragseingänge!$A$4:$A$500,A15,Vertragseingänge!$E$4:$E$500,Steuerung!$B$20)=0,"",COUNTIFS(Vertragseingänge!$A$4:$A$500,A15,Vertragseingänge!$E$4:$E$500,Steuerung!$B$20)),IF(COUNTIFS(Vertragseingänge!$A$4:$A$500,A15,Vertragseingänge!$E$4:$E$500,Steuerung!$B$20,Vertragseingänge!$C$4:$C$500,$E$4*1)=0,"",COUNTIFS(Vertragseingänge!$A$4:$A$500,A15,Vertragseingänge!$E$4:$E$500,Steuerung!$B$20,Vertragseingänge!$C$4:$C$500,$E$4*1)))),"") | H15: =IFERROR(IF(Steuerung!$B$21="","",IF($E$4="Alle",IF(COUNTIFS(Vertragseingänge!$A$4:$A$500,A15,Vertragseingänge!$E$4:$E$500,Steuerung!$B$21)=0,"",COUNTIFS(Vertragseingänge!$A$4:$A$500,A15,Vertragseingänge!$E$4:$E$500,Steuerung!$B$21)),IF(COUNTIFS(Vertragseingänge!$A$4:$A$500,A15,Vertragseingänge!$E$4:$E$500,Steuerung!$B$21,Vertragseingänge!$C$4:$C$500,$E$4*1)=0,"",COUNTIFS(Vertragseingänge!$A$4:$A$500,A15,Vertragseingänge!$E$4:$E$500,Steuerung!$B$21,Vertragseingänge!$C$4:$C$500,$E$4*1)))),"") | I15: =IFERROR(IF(Steuerung!$B$22="","",IF($E$4="Alle",IF(COUNTIFS(Vertragseingänge!$A$4:$A$500,A15,Vertragseingänge!$E$4:$E$500,Steuerung!$B$22)=0,"",COUNTIFS(Vertragseingänge!$A$4:$A$500,A15,Vertragseingänge!$E$4:$E$500,Steuerung!$B$22)),IF(COUNTIFS(Vertragseingänge!$A$4:$A$500,A15,Vertragseingänge!$E$4:$E$500,Steuerung!$B$22,Vertragseingänge!$C$4:$C$500,$E$4*1)=0,"",COUNTIFS(Vertragseingänge!$A$4:$A$500,A15,Vertragseingänge!$E$4:$E$500,Steuerung!$B$22,Vertragseingänge!$C$4:$C$500,$E$4*1)))),"") | J15: =IFERROR(IF(B15-SUM(C15:I15)=0,"",B15-SUM(C15:I15)),"") | L15: FRISCHE LEADS (< Maturity – noch in Reifephase)
A16: KW 12 | B16: =IF($E$4="Alle",COUNTIFS(Vertragseingänge!$A$4:$A$500,A16),COUNTIFS(Vertragseingänge!$A$4:$A$500,A16,Vertragseingänge!$C$4:$C$500,$E$4*1)) -> 7 | C16: =IFERROR(IF(Steuerung!$B$16="","",IF($E$4="Alle",IF(COUNTIFS(Vertragseingänge!$A$4:$A$500,A16,Vertragseingänge!$E$4:$E$500,Steuerung!$B$16)=0,"",COUNTIFS(Vertragseingänge!$A$4:$A$500,A16,Vertragseingänge!$E$4:$E$500,Steuerung!$B$16)),IF(COUNTIFS(Vertragseingänge!$A$4:$A$500,A16,Vertragseingänge!$E$4:$E$500,Steuerung!$B$16,Vertragseingänge!$C$4:$C$500,$E$4*1)=0,"",COUNTIFS(Vertragseingänge!$A$4:$A$500,A16,Vertragseingänge!$E$4:$E$500,Steuerung!$B$16,Vertragseingänge!$C$4:$C$500,$E$4*1)))),"") -> 3 | D16: =IFERROR(IF(Steuerung!$B$17="","",IF($E$4="Alle",IF(COUNTIFS(Vertragseingänge!$A$4:$A$500,A16,Vertragseingänge!$E$4:$E$500,Steuerung!$B$17)=0,"",COUNTIFS(Vertragseingänge!$A$4:$A$500,A16,Vertragseingänge!$E$4:$E$500,Steuerung!$B$17)),IF(COUNTIFS(Vertragseingänge!$A$4:$A$500,A16,Vertragseingänge!$E$4:$E$500,Steuerung!$B$17,Vertragseingänge!$C$4:$C$500,$E$4*1)=0,"",COUNTIFS(Vertragseingänge!$A$4:$A$500,A16,Vertragseingänge!$E$4:$E$500,Steuerung!$B$17,Vertragseingänge!$C$4:$C$500,$E$4*1)))),"") -> 2 | E16: =IFERROR(IF(Steuerung!$B$18="","",IF($E$4="Alle",IF(COUNTIFS(Vertragseingänge!$A$4:$A$500,A16,Vertragseingänge!$E$4:$E$500,Steuerung!$B$18)=0,"",COUNTIFS(Vertragseingänge!$A$4:$A$500,A16,Vertragseingänge!$E$4:$E$500,Steuerung!$B$18)),IF(COUNTIFS(Vertragseingänge!$A$4:$A$500,A16,Vertragseingänge!$E$4:$E$500,Steuerung!$B$18,Vertragseingänge!$C$4:$C$500,$E$4*1)=0,"",COUNTIFS(Vertragseingänge!$A$4:$A$500,A16,Vertragseingänge!$E$4:$E$500,Steuerung!$B$18,Vertragseingänge!$C$4:$C$500,$E$4*1)))),"") -> 1 | F16: =IFERROR(IF(Steuerung!$B$19="","",IF($E$4="Alle",IF(COUNTIFS(Vertragseingänge!$A$4:$A$500,A16,Vertragseingänge!$E$4:$E$500,Steuerung!$B$19)=0,"",COUNTIFS(Vertragseingänge!$A$4:$A$500,A16,Vertragseingänge!$E$4:$E$500,Steuerung!$B$19)),IF(COUNTIFS(Vertragseingänge!$A$4:$A$500,A16,Vertragseingänge!$E$4:$E$500,Steuerung!$B$19,Vertragseingänge!$C$4:$C$500,$E$4*1)=0,"",COUNTIFS(Vertragseingänge!$A$4:$A$500,A16,Vertragseingänge!$E$4:$E$500,Steuerung!$B$19,Vertragseingänge!$C$4:$C$500,$E$4*1)))),"") | G16: =IFERROR(IF(Steuerung!$B$20="","",IF($E$4="Alle",IF(COUNTIFS(Vertragseingänge!$A$4:$A$500,A16,Vertragseingänge!$E$4:$E$500,Steuerung!$B$20)=0,"",COUNTIFS(Vertragseingänge!$A$4:$A$500,A16,Vertragseingänge!$E$4:$E$500,Steuerung!$B$20)),IF(COUNTIFS(Vertragseingänge!$A$4:$A$500,A16,Vertragseingänge!$E$4:$E$500,Steuerung!$B$20,Vertragseingänge!$C$4:$C$500,$E$4*1)=0,"",COUNTIFS(Vertragseingänge!$A$4:$A$500,A16,Vertragseingänge!$E$4:$E$500,Steuerung!$B$20,Vertragseingänge!$C$4:$C$500,$E$4*1)))),"") | H16: =IFERROR(IF(Steuerung!$B$21="","",IF($E$4="Alle",IF(COUNTIFS(Vertragseingänge!$A$4:$A$500,A16,Vertragseingänge!$E$4:$E$500,Steuerung!$B$21)=0,"",COUNTIFS(Vertragseingänge!$A$4:$A$500,A16,Vertragseingänge!$E$4:$E$500,Steuerung!$B$21)),IF(COUNTIFS(Vertragseingänge!$A$4:$A$500,A16,Vertragseingänge!$E$4:$E$500,Steuerung!$B$21,Vertragseingänge!$C$4:$C$500,$E$4*1)=0,"",COUNTIFS(Vertragseingänge!$A$4:$A$500,A16,Vertragseingänge!$E$4:$E$500,Steuerung!$B$21,Vertragseingänge!$C$4:$C$500,$E$4*1)))),"") -> 1 | I16: =IFERROR(IF(Steuerung!$B$22="","",IF($E$4="Alle",IF(COUNTIFS(Vertragseingänge!$A$4:$A$500,A16,Vertragseingänge!$E$4:$E$500,Steuerung!$B$22)=0,"",COUNTIFS(Vertragseingänge!$A$4:$A$500,A16,Vertragseingänge!$E$4:$E$500,Steuerung!$B$22)),IF(COUNTIFS(Vertragseingänge!$A$4:$A$500,A16,Vertragseingänge!$E$4:$E$500,Steuerung!$B$22,Vertragseingänge!$C$4:$C$500,$E$4*1)=0,"",COUNTIFS(Vertragseingänge!$A$4:$A$500,A16,Vertragseingänge!$E$4:$E$500,Steuerung!$B$22,Vertragseingänge!$C$4:$C$500,$E$4*1)))),"") | J16: =IFERROR(IF(B16-SUM(C16:I16)=0,"",B16-SUM(C16:I16)),"") | L16: Verkäufer | M16: Leads | N16: Vertr. | O16: (reift)
A17: KW 13 | B17: =IF($E$4="Alle",COUNTIFS(Vertragseingänge!$A$4:$A$500,A17),COUNTIFS(Vertragseingänge!$A$4:$A$500,A17,Vertragseingänge!$C$4:$C$500,$E$4*1)) -> 2 | C17: =IFERROR(IF(Steuerung!$B$16="","",IF($E$4="Alle",IF(COUNTIFS(Vertragseingänge!$A$4:$A$500,A17,Vertragseingänge!$E$4:$E$500,Steuerung!$B$16)=0,"",COUNTIFS(Vertragseingänge!$A$4:$A$500,A17,Vertragseingänge!$E$4:$E$500,Steuerung!$B$16)),IF(COUNTIFS(Vertragseingänge!$A$4:$A$500,A17,Vertragseingänge!$E$4:$E$500,Steuerung!$B$16,Vertragseingänge!$C$4:$C$500,$E$4*1)=0,"",COUNTIFS(Vertragseingänge!$A$4:$A$500,A17,Vertragseingänge!$E$4:$E$500,Steuerung!$B$16,Vertragseingänge!$C$4:$C$500,$E$4*1)))),"") -> 2 | D17: =IFERROR(IF(Steuerung!$B$17="","",IF($E$4="Alle",IF(COUNTIFS(Vertragseingänge!$A$4:$A$500,A17,Vertragseingänge!$E$4:$E$500,Steuerung!$B$17)=0,"",COUNTIFS(Vertragseingänge!$A$4:$A$500,A17,Vertragseingänge!$E$4:$E$500,Steuerung!$B$17)),IF(COUNTIFS(Vertragseingänge!$A$4:$A$500,A17,Vertragseingänge!$E$4:$E$500,Steuerung!$B$17,Vertragseingänge!$C$4:$C$500,$E$4*1)=0,"",COUNTIFS(Vertragseingänge!$A$4:$A$500,A17,Vertragseingänge!$E$4:$E$500,Steuerung!$B$17,Vertragseingänge!$C$4:$C$500,$E$4*1)))),"") | E17: =IFERROR(IF(Steuerung!$B$18="","",IF($E$4="Alle",IF(COUNTIFS(Vertragseingänge!$A$4:$A$500,A17,Vertragseingänge!$E$4:$E$500,Steuerung!$B$18)=0,"",COUNTIFS(Vertragseingänge!$A$4:$A$500,A17,Vertragseingänge!$E$4:$E$500,Steuerung!$B$18)),IF(COUNTIFS(Vertragseingänge!$A$4:$A$500,A17,Vertragseingänge!$E$4:$E$500,Steuerung!$B$18,Vertragseingänge!$C$4:$C$500,$E$4*1)=0,"",COUNTIFS(Vertragseingänge!$A$4:$A$500,A17,Vertragseingänge!$E$4:$E$500,Steuerung!$B$18,Vertragseingänge!$C$4:$C$500,$E$4*1)))),"") | F17: =IFERROR(IF(Steuerung!$B$19="","",IF($E$4="Alle",IF(COUNTIFS(Vertragseingänge!$A$4:$A$500,A17,Vertragseingänge!$E$4:$E$500,Steuerung!$B$19)=0,"",COUNTIFS(Vertragseingänge!$A$4:$A$500,A17,Vertragseingänge!$E$4:$E$500,Steuerung!$B$19)),IF(COUNTIFS(Vertragseingänge!$A$4:$A$500,A17,Vertragseingänge!$E$4:$E$500,Steuerung!$B$19,Vertragseingänge!$C$4:$C$500,$E$4*1)=0,"",COUNTIFS(Vertragseingänge!$A$4:$A$500,A17,Vertragseingänge!$E$4:$E$500,Steuerung!$B$19,Vertragseingänge!$C$4:$C$500,$E$4*1)))),"") | G17: =IFERROR(IF(Steuerung!$B$20="","",IF($E$4="Alle",IF(COUNTIFS(Vertragseingänge!$A$4:$A$500,A17,Vertragseingänge!$E$4:$E$500,Steuerung!$B$20)=0,"",COUNTIFS(Vertragseingänge!$A$4:$A$500,A17,Vertragseingänge!$E$4:$E$500,Steuerung!$B$20)),IF(COUNTIFS(Vertragseingänge!$A$4:$A$500,A17,Vertragseingänge!$E$4:$E$500,Steuerung!$B$20,Vertragseingänge!$C$4:$C$500,$E$4*1)=0,"",COUNTIFS(Vertragseingänge!$A$4:$A$500,A17,Vertragseingänge!$E$4:$E$500,Steuerung!$B$20,Vertragseingänge!$C$4:$C$500,$E$4*1)))),"") | H17: =IFERROR(IF(Steuerung!$B$21="","",IF($E$4="Alle",IF(COUNTIFS(Vertragseingänge!$A$4:$A$500,A17,Vertragseingänge!$E$4:$E$500,Steuerung!$B$21)=0,"",COUNTIFS(Vertragseingänge!$A$4:$A$500,A17,Vertragseingänge!$E$4:$E$500,Steuerung!$B$21)),IF(COUNTIFS(Vertragseingänge!$A$4:$A$500,A17,Vertragseingänge!$E$4:$E$500,Steuerung!$B$21,Vertragseingänge!$C$4:$C$500,$E$4*1)=0,"",COUNTIFS(Vertragseingänge!$A$4:$A$500,A17,Vertragseingänge!$E$4:$E$500,Steuerung!$B$21,Vertragseingänge!$C$4:$C$500,$E$4*1)))),"") | I17: =IFERROR(IF(Steuerung!$B$22="","",IF($E$4="Alle",IF(COUNTIFS(Vertragseingänge!$A$4:$A$500,A17,Vertragseingänge!$E$4:$E$500,Steuerung!$B$22)=0,"",COUNTIFS(Vertragseingänge!$A$4:$A$500,A17,Vertragseingänge!$E$4:$E$500,Steuerung!$B$22)),IF(COUNTIFS(Vertragseingänge!$A$4:$A$500,A17,Vertragseingänge!$E$4:$E$500,Steuerung!$B$22,Vertragseingänge!$C$4:$C$500,$E$4*1)=0,"",COUNTIFS(Vertragseingänge!$A$4:$A$500,A17,Vertragseingänge!$E$4:$E$500,Steuerung!$B$22,Vertragseingänge!$C$4:$C$500,$E$4*1)))),"") | J17: =IFERROR(IF(B17-SUM(C17:I17)=0,"",B17-SUM(C17:I17)),"") | L17: =IF(Steuerung!B6="","",Steuerung!C6) -> Fatima | M17: =IF(Steuerung!$B$6="","",IF($E$4="Alle",SUMIFS('Leads Rohdaten'!$D$4:$D$503,'Leads Rohdaten'!$C$4:$C$503,Steuerung!$B$6,'Leads Rohdaten'!$H$4:$H$503,"Frisch"),SUMIFS('Leads Rohdaten'!$D$4:$D$503,'Leads Rohdaten'!$C$4:$C$503,Steuerung!$B$6,'Leads Rohdaten'!$H$4:$H$503,"Frisch",'Leads Rohdaten'!$A$4:$A$503,$E$4*1))) -> 178 | N17: =IF(Steuerung!$B$6="","",IF($E$4="Alle",SUMIFS('Leads Rohdaten'!$E$4:$E$503,'Leads Rohdaten'!$C$4:$C$503,Steuerung!$B$6,'Leads Rohdaten'!$H$4:$H$503,"Frisch"),SUMIFS('Leads Rohdaten'!$E$4:$E$503,'Leads Rohdaten'!$C$4:$C$503,Steuerung!$B$6,'Leads Rohdaten'!$H$4:$H$503,"Frisch",'Leads Rohdaten'!$A$4:$A$503,$E$4*1))) -> 28 | O17: =IF(Steuerung!$B$6="","","⏳ läuft") -> ⏳ läuft
A18: KW 14 | B18: =IF($E$4="Alle",COUNTIFS(Vertragseingänge!$A$4:$A$500,A18),COUNTIFS(Vertragseingänge!$A$4:$A$500,A18,Vertragseingänge!$C$4:$C$500,$E$4*1)) -> 0 | C18: =IFERROR(IF(Steuerung!$B$16="","",IF($E$4="Alle",IF(COUNTIFS(Vertragseingänge!$A$4:$A$500,A18,Vertragseingänge!$E$4:$E$500,Steuerung!$B$16)=0,"",COUNTIFS(Vertragseingänge!$A$4:$A$500,A18,Vertragseingänge!$E$4:$E$500,Steuerung!$B$16)),IF(COUNTIFS(Vertragseingänge!$A$4:$A$500,A18,Vertragseingänge!$E$4:$E$500,Steuerung!$B$16,Vertragseingänge!$C$4:$C$500,$E$4*1)=0,"",COUNTIFS(Vertragseingänge!$A$4:$A$500,A18,Vertragseingänge!$E$4:$E$500,Steuerung!$B$16,Vertragseingänge!$C$4:$C$500,$E$4*1)))),"") | D18: =IFERROR(IF(Steuerung!$B$17="","",IF($E$4="Alle",IF(COUNTIFS(Vertragseingänge!$A$4:$A$500,A18,Vertragseingänge!$E$4:$E$500,Steuerung!$B$17)=0,"",COUNTIFS(Vertragseingänge!$A$4:$A$500,A18,Vertragseingänge!$E$4:$E$500,Steuerung!$B$17)),IF(COUNTIFS(Vertragseingänge!$A$4:$A$500,A18,Vertragseingänge!$E$4:$E$500,Steuerung!$B$17,Vertragseingänge!$C$4:$C$500,$E$4*1)=0,"",COUNTIFS(Vertragseingänge!$A$4:$A$500,A18,Vertragseingänge!$E$4:$E$500,Steuerung!$B$17,Vertragseingänge!$C$4:$C$500,$E$4*1)))),"") | E18: =IFERROR(IF(Steuerung!$B$18="","",IF($E$4="Alle",IF(COUNTIFS(Vertragseingänge!$A$4:$A$500,A18,Vertragseingänge!$E$4:$E$500,Steuerung!$B$18)=0,"",COUNTIFS(Vertragseingänge!$A$4:$A$500,A18,Vertragseingänge!$E$4:$E$500,Steuerung!$B$18)),IF(COUNTIFS(Vertragseingänge!$A$4:$A$500,A18,Vertragseingänge!$E$4:$E$500,Steuerung!$B$18,Vertragseingänge!$C$4:$C$500,$E$4*1)=0,"",COUNTIFS(Vertragseingänge!$A$4:$A$500,A18,Vertragseingänge!$E$4:$E$500,Steuerung!$B$18,Vertragseingänge!$C$4:$C$500,$E$4*1)))),"") | F18: =IFERROR(IF(Steuerung!$B$19="","",IF($E$4="Alle",IF(COUNTIFS(Vertragseingänge!$A$4:$A$500,A18,Vertragseingänge!$E$4:$E$500,Steuerung!$B$19)=0,"",COUNTIFS(Vertragseingänge!$A$4:$A$500,A18,Vertragseingänge!$E$4:$E$500,Steuerung!$B$19)),IF(COUNTIFS(Vertragseingänge!$A$4:$A$500,A18,Vertragseingänge!$E$4:$E$500,Steuerung!$B$19,Vertragseingänge!$C$4:$C$500,$E$4*1)=0,"",COUNTIFS(Vertragseingänge!$A$4:$A$500,A18,Vertragseingänge!$E$4:$E$500,Steuerung!$B$19,Vertragseingänge!$C$4:$C$500,$E$4*1)))),"") | G18: =IFERROR(IF(Steuerung!$B$20="","",IF($E$4="Alle",IF(COUNTIFS(Vertragseingänge!$A$4:$A$500,A18,Vertragseingänge!$E$4:$E$500,Steuerung!$B$20)=0,"",COUNTIFS(Vertragseingänge!$A$4:$A$500,A18,Vertragseingänge!$E$4:$E$500,Steuerung!$B$20)),IF(COUNTIFS(Vertragseingänge!$A$4:$A$500,A18,Vertragseingänge!$E$4:$E$500,Steuerung!$B$20,Vertragseingänge!$C$4:$C$500,$E$4*1)=0,"",COUNTIFS(Vertragseingänge!$A$4:$A$500,A18,Vertragseingänge!$E$4:$E$500,Steuerung!$B$20,Vertragseingänge!$C$4:$C$500,$E$4*1)))),"") | H18: =IFERROR(IF(Steuerung!$B$21="","",IF($E$4="Alle",IF(COUNTIFS(Vertragseingänge!$A$4:$A$500,A18,Vertragseingänge!$E$4:$E$500,Steuerung!$B$21)=0,"",COUNTIFS(Vertragseingänge!$A$4:$A$500,A18,Vertragseingänge!$E$4:$E$500,Steuerung!$B$21)),IF(COUNTIFS(Vertragseingänge!$A$4:$A$500,A18,Vertragseingänge!$E$4:$E$500,Steuerung!$B$21,Vertragseingänge!$C$4:$C$500,$E$4*1)=0,"",COUNTIFS(Vertragseingänge!$A$4:$A$500,A18,Vertragseingänge!$E$4:$E$500,Steuerung!$B$21,Vertragseingänge!$C$4:$C$500,$E$4*1)))),"") | I18: =IFERROR(IF(Steuerung!$B$22="","",IF($E$4="Alle",IF(COUNTIFS(Vertragseingänge!$A$4:$A$500,A18,Vertragseingänge!$E$4:$E$500,Steuerung!$B$22)=0,"",COUNTIFS(Vertragseingänge!$A$4:$A$500,A18,Vertragseingänge!$E$4:$E$500,Steuerung!$B$22)),IF(COUNTIFS(Vertragseingänge!$A$4:$A$500,A18,Vertragseingänge!$E$4:$E$500,Steuerung!$B$22,Vertragseingänge!$C$4:$C$500,$E$4*1)=0,"",COUNTIFS(Vertragseingänge!$A$4:$A$500,A18,Vertragseingänge!$E$4:$E$500,Steuerung!$B$22,Vertragseingänge!$C$4:$C$500,$E$4*1)))),"") | J18: =IFERROR(IF(B18-SUM(C18:I18)=0,"",B18-SUM(C18:I18)),"") | L18: =IF(Steuerung!B7="","",Steuerung!C7) -> Gabriella | M18: =IF(Steuerung!$B$7="","",IF($E$4="Alle",SUMIFS('Leads Rohdaten'!$D$4:$D$503,'Leads Rohdaten'!$C$4:$C$503,Steuerung!$B$7,'Leads Rohdaten'!$H$4:$H$503,"Frisch"),SUMIFS('Leads Rohdaten'!$D$4:$D$503,'Leads Rohdaten'!$C$4:$C$503,Steuerung!$B$7,'Leads Rohdaten'!$H$4:$H$503,"Frisch",'Leads Rohdaten'!$A$4:$A$503,$E$4*1))) -> 30 | N18: =IF(Steuerung!$B$7="","",IF($E$4="Alle",SUMIFS('Leads Rohdaten'!$E$4:$E$503,'Leads Rohdaten'!$C$4:$C$503,Steuerung!$B$7,'Leads Rohdaten'!$H$4:$H$503,"Frisch"),SUMIFS('Leads Rohdaten'!$E$4:$E$503,'Leads Rohdaten'!$C$4:$C$503,Steuerung!$B$7,'Leads Rohdaten'!$H$4:$H$503,"Frisch",'Leads Rohdaten'!$A$4:$A$503,$E$4*1))) -> 3 | O18: =IF(Steuerung!$B$7="","","⏳ läuft") -> ⏳ läuft
