Workbook

Sheet Dashboard
B2: Google-Bewertungen / Referenzen pro Auslieferung
B4: Jahr: | C4: 2026
B6: Auslieferungen | C6: Google-Bew. | D6: Referenzen | E6: Ø Sterne | F6: Google-Quote | G6: Referenz-Quote
B7: =IF($C$4="Alle",COUNTA(Rohdaten!B:B)-1,COUNTIF(Rohdaten!J:J,$C$4)) -> 78 | C7: =IF($C$4="Alle",COUNTIF(Rohdaten!F:F,"Ja"),COUNTIFS(Rohdaten!F:F,"Ja",Rohdaten!J:J,$C$4)) -> 43 | D7: =IF($C$4="Alle",COUNTIF(Rohdaten!H:H,"Ja"),COUNTIFS(Rohdaten!H:H,"Ja",Rohdaten!J:J,$C$4)) -> 67 | E7: =IF(C7=0,"-",IF($C$4="Alle",AVERAGEIF(Rohdaten!F:F,"Ja",Rohdaten!G:G),AVERAGEIFS(Rohdaten!G:G,Rohdaten!F:F,"Ja",Rohdaten!J:J,$C$4))) -> 4.9767442 | F7: =IF(B7=0,"-",C7/B7) -> 0.55128205 | G7: =IF(B7=0,"-",D7/B7) -> 0.85897436
B8: Projekte | C8: erhalten | D8: erhalten | E8: Sterne | F8: in % | G8: in %
B10: Zielerreichung
B11: KPI | C11: Ist-Wert | D11: Ziel Q2/2026 | E11: Ziel Q4/2026 | F11: Status
B12: Google-Quote | C12: =F7 -> 0.55128205 | D12: 85 % | E12: 95 % | F12: =IF(F7>=0.85,"🟢 Ziel erreicht",IF(F7>=0.7,"🟡 Auf Kurs","🔴 Handlungsbedarf")) -> 🔴 Handlungsbedarf
B13: Referenz-Quote | C13: =G7 -> 0.85897436 | D13: 65 % | E13: 85 % | F13: =IF(G7>=0.65,"🟢 Ziel erreicht",IF(G7>=0.45,"🟡 Auf Kurs","🔴 Handlungsbedarf")) -> 🟢 Ziel erreicht
B14: Ø Sterne | C14: =E7 -> 4.9767442 | D14: 4,5 | E14: 4,7 | F14: =IF(E7>=4.5,"🟢 Ziel erreicht",IF(E7>=4,"🟡 Auf Kurs","🔴 Handlungsbedarf")) -> 🟢 Ziel erreicht
B16: Auswertung nach Institutionstyp
B17: Institutionstyp | C17: Anzahl | D17: Google | E17: G-Quote | F17: Referenz | G17: R-Quote
B18: Feuerwehr (FFW) | C18: =IF($C$4="Alle",COUNTIF(Rohdaten!E:E,B18),COUNTIFS(Rohdaten!E:E,B18,Rohdaten!J:J,$C$4)) -> 20 | D18: =IF($C$4="Alle",COUNTIFS(Rohdaten!E:E,B18,Rohdaten!F:F,"Ja"),COUNTIFS(Rohdaten!E:E,B18,Rohdaten!F:F,"Ja",Rohdaten!J:J,$C$4)) -> 10 | E18: =IF(C18=0,"-",D18/C18) -> 0.5 | F18: =IF($C$4="Alle",COUNTIFS(Rohdaten!E:E,B18,Rohdaten!H:H,"Ja"),COUNTIFS(Rohdaten!E:E,B18,Rohdaten!H:H,"Ja",Rohdaten!J:J,$C$4)) -> 18 | G18: =IF(C18=0,"-",F18/C18) -> 0.9
B19: Sportverein | C19: =IF($C$4="Alle",COUNTIF(Rohdaten!E:E,B19),COUNTIFS(Rohdaten!E:E,B19,Rohdaten!J:J,$C$4)) -> 20 | D19: =IF($C$4="Alle",COUNTIFS(Rohdaten!E:E,B19,Rohdaten!F:F,"Ja"),COUNTIFS(Rohdaten!E:E,B19,Rohdaten!F:F,"Ja",Rohdaten!J:J,$C$4)) -> 6 | E19: =IF(C19=0,"-",D19/C19) -> 0.3 | F19: =IF($C$4="Alle",COUNTIFS(Rohdaten!E:E,B19,Rohdaten!H:H,"Ja"),COUNTIFS(Rohdaten!E:E,B19,Rohdaten!H:H,"Ja",Rohdaten!J:J,$C$4)) -> 13 | G19: =IF(C19=0,"-",F19/C19) -> 0.65
B20: Kulturverein / Theater | C20: =IF($C$4="Alle",COUNTIF(Rohdaten!E:E,B20),COUNTIFS(Rohdaten!E:E,B20,Rohdaten!J:J,$C$4)) -> 13 | D20: =IF($C$4="Alle",COUNTIFS(Rohdaten!E:E,B20,Rohdaten!F:F,"Ja"),COUNTIFS(Rohdaten!E:E,B20,Rohdaten!F:F,"Ja",Rohdaten!J:J,$C$4)) -> 8 | E20: =IF(C20=0,"-",D20/C20) -> 0.61538462 | F20: =IF($C$4="Alle",COUNTIFS(Rohdaten!E:E,B20,Rohdaten!H:H,"Ja"),COUNTIFS(Rohdaten!E:E,B20,Rohdaten!H:H,"Ja",Rohdaten!J:J,$C$4)) -> 12 | G20: =IF(C20=0,"-",F20/C20) -> 0.92307692
B21: Musikverein | C21: =IF($C$4="Alle",COUNTIF(Rohdaten!E:E,B21),COUNTIFS(Rohdaten!E:E,B21,Rohdaten!J:J,$C$4)) -> 3 | D21: =IF($C$4="Alle",COUNTIFS(Rohdaten!E:E,B21,Rohdaten!F:F,"Ja"),COUNTIFS(Rohdaten!E:E,B21,Rohdaten!F:F,"Ja",Rohdaten!J:J,$C$4)) -> 3 | E21: =IF(C21=0,"-",D21/C21) -> 1 | F21: =IF($C$4="Alle",COUNTIFS(Rohdaten!E:E,B21,Rohdaten!H:H,"Ja"),COUNTIFS(Rohdaten!E:E,B21,Rohdaten!H:H,"Ja",Rohdaten!J:J,$C$4)) -> 3 | G21: =IF(C21=0,"-",F21/C21) -> 1
B22: Soziale Einrichtung | C22: =IF($C$4="Alle",COUNTIF(Rohdaten!E:E,B22),COUNTIFS(Rohdaten!E:E,B22,Rohdaten!J:J,$C$4)) -> 8 | D22: =IF($C$4="Alle",COUNTIFS(Rohdaten!E:E,B22,Rohdaten!F:F,"Ja"),COUNTIFS(Rohdaten!E:E,B22,Rohdaten!F:F,"Ja",Rohdaten!J:J,$C$4)) -> 5 | E22: =IF(C22=0,"-",D22/C22) -> 0.625 | F22: =IF($C$4="Alle",COUNTIFS(Rohdaten!E:E,B22,Rohdaten!H:H,"Ja"),COUNTIFS(Rohdaten!E:E,B22,Rohdaten!H:H,"Ja",Rohdaten!J:J,$C$4)) -> 7 | G22: =IF(C22=0,"-",F22/C22) -> 0.875
B23: THW / Hilfsorganisation | C23: =IF($C$4="Alle",COUNTIF(Rohdaten!E:E,B23),COUNTIFS(Rohdaten!E:E,B23,Rohdaten!J:J,$C$4)) -> 4 | D23: =IF($C$4="Alle",COUNTIFS(Rohdaten!E:E,B23,Rohdaten!F:F,"Ja"),COUNTIFS(Rohdaten!E:E,B23,Rohdaten!F:F,"Ja",Rohdaten!J:J,$C$4)) -> 4 | E23: =IF(C23=0,"-",D23/C23) -> 1 | F23: =IF($C$4="Alle",COUNTIFS(Rohdaten!E:E,B23,Rohdaten!H:H,"Ja"),COUNTIFS(Rohdaten!E:E,B23,Rohdaten!H:H,"Ja",Rohdaten!J:J,$C$4)) -> 4 | G23: =IF(C23=0,"-",F23/C23) -> 1
B24: Gemeinde / Kommune | C24: =IF($C$4="Alle",COUNTIF(Rohdaten!E:E,B24),COUNTIFS(Rohdaten!E:E,B24,Rohdaten!J:J,$C$4)) -> 1 | D24: =IF($C$4="Alle",COUNTIFS(Rohdaten!E:E,B24,Rohdaten!F:F,"Ja"),COUNTIFS(Rohdaten!E:E,B24,Rohdaten!F:F,"Ja",Rohdaten!J:J,$C$4)) -> 0 | E24: =IF(C24=0,"-",D24/C24) -> 0 | F24: =IF($C$4="Alle",COUNTIFS(Rohdaten!E:E,B24,Rohdaten!H:H,"Ja"),COUNTIFS(Rohdaten!E:E,B24,Rohdaten!H:H,"Ja",Rohdaten!J:J,$C$4)) -> 1 | G24: =IF(C24=0,"-",F24/C24) -> 1
B25: Schule / Kita | C25: =IF($C$4="Alle",COUNTIF(Rohdaten!E:E,B25),COUNTIFS(Rohdaten!E:E,B25,Rohdaten!J:J,$C$4)) -> 3 | D25: =IF($C$4="Alle",COUNTIFS(Rohdaten!E:E,B25,Rohdaten!F:F,"Ja"),COUNTIFS(Rohdaten!E:E,B25,Rohdaten!F:F,"Ja",Rohdaten!J:J,$C$4)) -> 3 | E25: =IF(C25=0,"-",D25/C25) -> 1 | F25: =IF($C$4="Alle",COUNTIFS(Rohdaten!E:E,B25,Rohdaten!H:H,"Ja"),COUNTIFS(Rohdaten!E:E,B25,Rohdaten!H:H,"Ja",Rohdaten!J:J,$C$4)) -> 3 | G25: =IF(C25=0,"-",F25/C25) -> 1
B26: Sonstige | C26: =IF($C$4="Alle",COUNTIF(Rohdaten!E:E,B26),COUNTIFS(Rohdaten!E:E,B26,Rohdaten!J:J,$C$4)) -> 6 | D26: =IF($C$4="Alle",COUNTIFS(Rohdaten!E:E,B26,Rohdaten!F:F,"Ja"),COUNTIFS(Rohdaten!E:E,B26,Rohdaten!F:F,"Ja",Rohdaten!J:J,$C$4)) -> 4 | E26: =IF(C26=0,"-",D26/C26) -> 0.66666667 | F26: =IF($C$4="Alle",COUNTIFS(Rohdaten!E:E,B26,Rohdaten!H:H,"Ja"),COUNTIFS(Rohdaten!E:E,B26,Rohdaten!H:H,"Ja",Rohdaten!J:J,$C$4)) -> 6 | G26: =IF(C26=0,"-",F26/C26) -> 1
B28: Monatlicher Trend
B29: Monat | C29: Auslieferungen | D29: Google | E29: G-Quote | F29: Referenz | G29: R-Quote
B30: Januar | C30: =IF($C$4="Alle",COUNTIFS(Rohdaten!K:K,1,Rohdaten!B:B,"<>"),COUNTIFS(Rohdaten!K:K,1,Rohdaten!J:J,$C$4,Rohdaten!B:B,"<>")) -> 3 | D30: =IF($C$4="Alle",COUNTIFS(Rohdaten!K:K,1,Rohdaten!F:F,"Ja",Rohdaten!B:B,"<>"),COUNTIFS(Rohdaten!K:K,1,Rohdaten!F:F,"Ja",Rohdaten!J:J,$C$4,Rohdaten!B:B,"<>")) -> 1 | E30: =IF(C30=0,"-",D30/C30) -> 0.33333333 | F30: =IF($C$4="Alle",COUNTIFS(Rohdaten!K:K,1,Rohdaten!H:H,"Ja",Rohdaten!B:B,"<>"),COUNTIFS(Rohdaten!K:K,1,Rohdaten!H:H,"Ja",Rohdaten!J:J,$C$4,Rohdaten!B:B,"<>")) -> 1 | G30: =IF(C30=0,"-",F30/C30) -> 0.33333333
B31: Februar | C31: =IF($C$4="Alle",COUNTIFS(Rohdaten!K:K,2,Rohdaten!B:B,"<>"),COUNTIFS(Rohdaten!K:K,2,Rohdaten!J:J,$C$4,Rohdaten!B:B,"<>")) -> 14 | D31: =IF($C$4="Alle",COUNTIFS(Rohdaten!K:K,2,Rohdaten!F:F,"Ja",Rohdaten!B:B,"<>"),COUNTIFS(Rohdaten!K:K,2,Rohdaten!F:F,"Ja",Rohdaten!J:J,$C$4,Rohdaten!B:B,"<>")) -> 11 | E31: =IF(C31=0,"-",D31/C31) -> 0.78571429 | F31: =IF($C$4="Alle",COUNTIFS(Rohdaten!K:K,2,Rohdaten!H:H,"Ja",Rohdaten!B:B,"<>"),COUNTIFS(Rohdaten!K:K,2,Rohdaten!H:H,"Ja",Rohdaten!J:J,$C$4,Rohdaten!B:B,"<>")) -> 13 | G31: =IF(C31=0,"-",F31/C31) -> 0.92857143
B32: März | C32: =IF($C$4="Alle",COUNTIFS(Rohdaten!K:K,3,Rohdaten!B:B,"<>"),COUNTIFS(Rohdaten!K:K,3,Rohdaten!J:J,$C$4,Rohdaten!B:B,"<>")) -> 21 | D32: =IF($C$4="Alle",COUNTIFS(Rohdaten!K:K,3,Rohdaten!F:F,"Ja",Rohdaten!B:B,"<>"),COUNTIFS(Rohdaten!K:K,3,Rohdaten!F:F,"Ja",Rohdaten!J:J,$C$4,Rohdaten!B:B,"<>")) -> 15 | E32: =IF(C32=0,"-",D32/C32) -> 0.71428571 | F32: =IF($C$4="Alle",COUNTIFS(Rohdaten!K:K,3,Rohdaten!H:H,"Ja",Rohdaten!B:B,"<>"),COUNTIFS(Rohdaten!K:K,3,Rohdaten!H:H,"Ja",Rohdaten!J:J,$C$4,Rohdaten!B:B,"<>")) -> 17 | G32: =IF(C32=0,"-",F32/C32) -> 0.80952381
B33: April | C33: =IF($C$4="Alle",COUNTIFS(Rohdaten!K:K,4,Rohdaten!B:B,"<>"),COUNTIFS(Rohdaten!K:K,4,Rohdaten!J:J,$C$4,Rohdaten!B:B,"<>")) -> 17 | D33: =IF($C$4="Alle",COUNTIFS(Rohdaten!K:K,4,Rohdaten!F:F,"Ja",Rohdaten!B:B,"<>"),COUNTIFS(Rohdaten!K:K,4,Rohdaten!F:F,"Ja",Rohdaten!J:J,$C$4,Rohdaten!B:B,"<>")) -> 8 | E33: =IF(C33=0,"-",D33/C33) -> 0.47058824 | F33: =IF($C$4="Alle",COUNTIFS(Rohdaten!K:K,4,Rohdaten!H:H,"Ja",Rohdaten!B:B,"<>"),COUNTIFS(Rohdaten!K:K,4,Rohdaten!H:H,"Ja",Rohdaten!J:J,$C$4,Rohdaten!B:B,"<>")) -> 16 | G33: =IF(C33=0,"-",F33/C33) -> 0.94117647
B34: Mai | C34: =IF($C$4="Alle",COUNTIFS(Rohdaten!K:K,5,Rohdaten!B:B,"<>"),COUNTIFS(Rohdaten!K:K,5,Rohdaten!J:J,$C$4,Rohdaten!B:B,"<>")) -> 7 | D34: =IF($C$4="Alle",COUNTIFS(Rohdaten!K:K,5,Rohdaten!F:F,"Ja",Rohdaten!B:B,"<>"),COUNTIFS(Rohdaten!K:K,5,Rohdaten!F:F,"Ja",Rohdaten!J:J,$C$4,Rohdaten!B:B,"<>")) -> 3 | E34: =IF(C34=0,"-",D34/C34) -> 0.42857143 | F34: =IF($C$4="Alle",COUNTIFS(Rohdaten!K:K,5,Rohdaten!H:H,"Ja",Rohdaten!B:B,"<>"),COUNTIFS(Rohdaten!K:K,5,Rohdaten!H:H,"Ja",Rohdaten!J:J,$C$4,Rohdaten!B:B,"<>")) -> 7 | G34: =IF(C34=0,"-",F34/C34) -> 1
B35: Juni | C35: =IF($C$4="Alle",COUNTIFS(Rohdaten!K:K,6,Rohdaten!B:B,"<>"),COUNTIFS(Rohdaten!K:K,6,Rohdaten!J:J,$C$4,Rohdaten!B:B,"<>")) -> 13 | D35: =IF($C$4="Alle",COUNTIFS(Rohdaten!K:K,6,Rohdaten!F:F,"Ja",Rohdaten!B:B,"<>"),COUNTIFS(Rohdaten!K:K,6,Rohdaten!F:F,"Ja",Rohdaten!J:J,$C$4,Rohdaten!B:B,"<>")) -> 4 | E35: =IF(C35=0,"-",D35/C35) -> 0.30769231 | F35: =IF($C$4="Alle",COUNTIFS(Rohdaten!K:K,6,Rohdaten!H:H,"Ja",Rohdaten!B:B,"<>"),COUNTIFS(Rohdaten!K:K,6,Rohdaten!H:H,"Ja",Rohdaten!J:J,$C$4,Rohdaten!B:B,"<>")) -> 11 | G35: =IF(C35=0,"-",F35/C35) -> 0.84615385
B36: Juli | C36: =IF($C$4="Alle",COUNTIFS(Rohdaten!K:K,7,Rohdaten!B:B,"<>"),COUNTIFS(Rohdaten!K:K,7,Rohdaten!J:J,$C$4,Rohdaten!B:B,"<>")) -> 3 | D36: =IF($C$4="Alle",COUNTIFS(Rohdaten!K:K,7,Rohdaten!F:F,"Ja",Rohdaten!B:B,"<>"),COUNTIFS(Rohdaten!K:K,7,Rohdaten!F:F,"Ja",Rohdaten!J:J,$C$4,Rohdaten!B:B,"<>")) -> 1 | E36: =IF(C36=0,"-",D36/C36) -> 0.33333333 | F36: =IF($C$4="Alle",COUNTIFS(Rohdaten!K:K,7,Rohdaten!H:H,"Ja",Rohdaten!B:B,"<>"),COUNTIFS(Rohdaten!K:K,7,Rohdaten!H:H,"Ja",Rohdaten!J:J,$C$4,Rohdaten!B:B,"<>")) -> 2 | G36: =IF(C36=0,"-",F36/C36) -> 0.66666667
B37: August | C37: =IF($C$4="Alle",COUNTIFS(Rohdaten!K:K,8,Rohdaten!B:B,"<>"),COUNTIFS(Rohdaten!K:K,8,Rohdaten!J:J,$C$4,Rohdaten!B:B,"<>")) -> 0 | D37: =IF($C$4="Alle",COUNTIFS(Rohdaten!K:K,8,Rohdaten!F:F,"Ja",Rohdaten!B:B,"<>"),COUNTIFS(Rohdaten!K:K,8,Rohdaten!F:F,"Ja",Rohdaten!J:J,$C$4,Rohdaten!B:B,"<>")) -> 0 | E37: =IF(C37=0,"-",D37/C37) -> - | F37: =IF($C$4="Alle",COUNTIFS(Rohdaten!K:K,8,Rohdaten!H:H,"Ja",Rohdaten!B:B,"<>"),COUNTIFS(Rohdaten!K:K,8,Rohdaten!H:H,"Ja",Rohdaten!J:J,$C$4,Rohdaten!B:B,"<>")) -> 0 | G37: =IF(C37=0,"-",F37/C37) -> -
B38: September | C38: =IF($C$4="Alle",COUNTIFS(Rohdaten!K:K,9,Rohdaten!B:B,"<>"),COUNTIFS(Rohdaten!K:K,9,Rohdaten!J:J,$C$4,Rohdaten!B:B,"<>")) -> 0 | D38: =IF($C$4="Alle",COUNTIFS(Rohdaten!K:K,9,Rohdaten!F:F,"Ja",Rohdaten!B:B,"<>"),COUNTIFS(Rohdaten!K:K,9,Rohdaten!F:F,"Ja",Rohdaten!J:J,$C$4,Rohdaten!B:B,"<>")) -> 0 | E38: =IF(C38=0,"-",D38/C38) -> - | F38: =IF($C$4="Alle",COUNTIFS(Rohdaten!K:K,9,Rohdaten!H:H,"Ja",Rohdaten!B:B,"<>"),COUNTIFS(Rohdaten!K:K,9,Rohdaten!H:H,"Ja",Rohdaten!J:J,$C$4,Rohdaten!B:B,"<>")) -> 0 | G38: =IF(C38=0,"-",F38/C38) -> -
B39: Oktober | C39: =IF($C$4="Alle",COUNTIFS(Rohdaten!K:K,10,Rohdaten!B:B,"<>"),COUNTIFS(Rohdaten!K:K,10,Rohdaten!J:J,$C$4,Rohdaten!B:B,"<>")) -> 0 | D39: =IF($C$4="Alle",COUNTIFS(Rohdaten!K:K,10,Rohdaten!F:F,"Ja",Rohdaten!B:B,"<>"),COUNTIFS(Rohdaten!K:K,10,Rohdaten!F:F,"Ja",Rohdaten!J:J,$C$4,Rohdaten!B:B,"<>")) -> 0 | E39: =IF(C39=0,"-",D39/C39) -> - | F39: =IF($C$4="Alle",COUNTIFS(Rohdaten!K:K,10,Rohdaten!H:H,"Ja",Rohdaten!B:B,"<>"),COUNTIFS(Rohdaten!K:K,10,Rohdaten!H:H,"Ja",Rohdaten!J:J,$C$4,Rohdaten!B:B,"<>")) -> 0 | G39: =IF(C39=0,"-",F39/C39) -> -
B40: November | C40: =IF($C$4="Alle",COUNTIFS(Rohdaten!K:K,11,Rohdaten!B:B,"<>"),COUNTIFS(Rohdaten!K:K,11,Rohdaten!J:J,$C$4,Rohdaten!B:B,"<>")) -> 0 | D40: =IF($C$4="Alle",COUNTIFS(Rohdaten!K:K,11,Rohdaten!F:F,"Ja",Rohdaten!B:B,"<>"),COUNTIFS(Rohdaten!K:K,11,Rohdaten!F:F,"Ja",Rohdaten!J:J,$C$4,Rohdaten!B:B,"<>")) -> 0 | E40: =IF(C40=0,"-",D40/C40) -> - | F40: =IF($C$4="Alle",COUNTIFS(Rohdaten!K:K,11,Rohdaten!H:H,"Ja",Rohdaten!B:B,"<>"),COUNTIFS(Rohdaten!K:K,11,Rohdaten!H:H,"Ja",Rohdaten!J:J,$C$4,Rohdaten!B:B,"<>")) -> 0 | G40: =IF(C40=0,"-",F40/C40) -> -
B41: Dezember | C41: =IF($C$4="Alle",COUNTIFS(Rohdaten!K:K,12,Rohdaten!B:B,"<>"),COUNTIFS(Rohdaten!K:K,12,Rohdaten!J:J,$C$4,Rohdaten!B:B,"<>")) -> 0 | D41: =IF($C$4="Alle",COUNTIFS(Rohdaten!K:K,12,Rohdaten!F:F,"Ja",Rohdaten!B:B,"<>"),COUNTIFS(Rohdaten!K:K,12,Rohdaten!F:F,"Ja",Rohdaten!J:J,$C$4,Rohdaten!B:B,"<>")) -> 0 | E41: =IF(C41=0,"-",D41/C41) -> - | F41: =IF($C$4="Alle",COUNTIFS(Rohdaten!K:K,12,Rohdaten!H:H,"Ja",Rohdaten!B:B,"<>"),COUNTIFS(Rohdaten!K:K,12,Rohdaten!H:H,"Ja",Rohdaten!J:J,$C$4,Rohdaten!B:B,"<>")) -> 0 | G41: =IF(C41=0,"-",F41/C41) -> -

Sheet Rohdaten
A1: ROHDATEN – Eingabe (jede Zeile = eine Auslieferung)
A2: Pflichtfelder gelb markiert. Dropdowns hinterlegt. Alle Auswertungen basieren auf diesen Rohdaten.
A3: Nr. | B3: Auslieferungsdatum | C3: Projektnummer | D3: Vereinsname / Institution | E3: Institutionstyp | F3: Google-Bewertung erhalten? | G3: Sternebewertung (1–5) | H3: Referenz erhalten? | I3: Anmerkungen | J3: Jahr | K3: Monat-Nr.
A4: 1 | B4: 45888 | C4: 2402052518 | D4: Freiwillige Feuerwehr Markt Oberschwarzach | E4: Feuerwehr (FFW) | F4: ja | G4: 5 | H4: Nein | I4: Bewertung ang. Am 25.02. | J4: =IFERROR(IF(B4="","",IF(ISNUMBER(B4),TEXT(YEAR(B4),"0"),"")),"") -> 2025 | K4: =IFERROR(IF(B4="","",IF(ISNUMBER(B4),MONTH(B4),"")),"") -> 8
A5: 2 | B5: 45932 | C5: 2408052695 | D5: Feuerwehrverein Oßweil e.V. | E5: Feuerwehr (FFW) | F5: ja | G5: 5 | H5: Ja | I5: Bernd Rosenkranz | J5: =IFERROR(IF(B5="","",IF(ISNUMBER(B5),TEXT(YEAR(B5),"0"),"")),"") -> 2025 | K5: =IFERROR(IF(B5="","",IF(ISNUMBER(B5),MONTH(B5),"")),"") -> 10
A6: 3 | B6: 45945 | C6: 2402052503 | D6: Freiwillige Feuerwehr Schneeberg | E6: Feuerwehr (FFW) | F6: Ja | G6: 5 | H6: ja | I6: Bewertung erst Feb. 2026 | J6: =IFERROR(IF(B6="","",IF(ISNUMBER(B6),TEXT(YEAR(B6),"0"),"")),"") -> 2025 | K6: =IFERROR(IF(B6="","",IF(ISNUMBER(B6),MONTH(B6),"")),"") -> 10
A7: 4 | B7: 45976 | C7: 2412052785 | D7: FFW Breitengüßbach e.V. | E7: Feuerwehr (FFW) | F7: Ja | G7: 5 | H7: Ja | I7: Bewertung erst Feb. 2026 | J7: =IFERROR(IF(B7="","",IF(ISNUMBER(B7),TEXT(YEAR(B7),"0"),"")),"") -> 2025 | K7: =IFERROR(IF(B7="","",IF(ISNUMBER(B7),MONTH(B7),"")),"") -> 11
A8: 5 | B8: 45976 | C8: 2505052917 | D8: FFW Windsbach 1868 e.V. | E8: Feuerwehr (FFW) | F8: Ja | G8: 5 | H8: Nein | I8: Bewertung erst Feb. 2026 | J8: =IFERROR(IF(B8="","",IF(ISNUMBER(B8),TEXT(YEAR(B8),"0"),"")),"") -> 2025 | K8: =IFERROR(IF(B8="","",IF(ISNUMBER(B8),MONTH(B8),"")),"") -> 11
A9: 6 | B9: 45985 | C9: 2503052864 | D9: FFW Engelsbrand | E9: Feuerwehr (FFW) | F9: ja | G9: 5 | H9: ja | I9: Fabian Kurz | J9: =IFERROR(IF(B9="","",IF(ISNUMBER(B9),TEXT(YEAR(B9),"0"),"")),"") -> 2025 | K9: =IFERROR(IF(B9="","",IF(ISNUMBER(B9),MONTH(B9),"")),"") -> 11
A10: 7 | B10: 45986 | C10: 2403052574 | D10: Spielvereinigung Kleinkötz e.V. | E10: Sportverein | F10: Ja | G10: 5 | H10: Ja | I10: Herr Kraus | J10: =IFERROR(IF(B10="","",IF(ISNUMBER(B10),TEXT(YEAR(B10),"0"),"")),"") -> 2025 | K10: =IFERROR(IF(B10="","",IF(ISNUMBER(B10),MONTH(B10),"")),"") -> 11
A11: 8 | B11: 46006 | C11: 2501052806 | D11: Freiwillige Feuerwehr Bruck | E11: Feuerwehr (FFW) | F11: Ja | G11: 5 | H11: Nein | I11: Bewertung erst Feb. 2026 | J11: =IFERROR(IF(B11="","",IF(ISNUMBER(B11),TEXT(YEAR(B11),"0"),"")),"") -> 2025 | K11: =IFERROR(IF(B11="","",IF(ISNUMBER(B11),MONTH(B11),"")),"") -> 12
A12: 9 | B12: 46006 | C12: 2403052558 | D12: Freiwillige Feuerwehr Bruckberg | E12: Feuerwehr (FFW) | F12: Ja | G12: 4 | H12: Nein | I12: Referenz ausstehend | J12: =IFERROR(IF(B12="","",IF(ISNUMBER(B12),TEXT(YEAR(B12),"0"),"")),"") -> 2025 | K12: =IFERROR(IF(B12="","",IF(ISNUMBER(B12),MONTH(B12),"")),"") -> 12
A13: 10 | B13: 46009 | C13: 2306052317 | D13: DRK KV Freudenstadt e.V. | E13: Soziale Einrichtung | F13: ja | G13: 5 | H13: ja | J13: =IFERROR(IF(B13="","",IF(ISNUMBER(B13),TEXT(YEAR(B13),"0"),"")),"") -> 2025 | K13: =IFERROR(IF(B13="","",IF(ISNUMBER(B13),MONTH(B13),"")),"") -> 12
A14: 11 | B14: 46027 | C14: 2309052389 | D14: SSV Vogelstang, Mannheim | E14: Sportverein | F14: Nein | G14: 5 | H14: Nein | J14: =IFERROR(IF(B14="","",IF(ISNUMBER(B14),TEXT(YEAR(B14),"0"),"")),"") -> 2026 | K14: =IFERROR(IF(B14="","",IF(ISNUMBER(B14),MONTH(B14),"")),"") -> 1
A15: 12 | B15: 46027 | C15: 2402052510 | D15: Akademie für Darstellende Kunst - Ulm | E15: Kulturverein / Theater | F15: Ja | G15: 5 | H15: Ja | I15: erhalten | J15: =IFERROR(IF(B15="","",IF(ISNUMBER(B15),TEXT(YEAR(B15),"0"),"")),"") -> 2026 | K15: =IFERROR(IF(B15="","",IF(ISNUMBER(B15),MONTH(B15),"")),"") -> 1
A16: 13 | B16: 46036 | C16: 2411052747 | D16: Sportverein Jagstzell e.V. | E16: Sportverein | F16: Nein | G16: 5 | H16: Nein | I16: Bewertung erst Feb. 2026 | J16: =IFERROR(IF(B16="","",IF(ISNUMBER(B16),TEXT(YEAR(B16),"0"),"")),"") -> 2026 | K16: =IFERROR(IF(B16="","",IF(ISNUMBER(B16),MONTH(B16),"")),"") -> 1 | L16: Google Bewertung angefordert
A17: 14 | B17: 46056 | C17: 2407052681 | D17: Musikverein Bad Cannstatt e.V., Stuttgart | E17: Musikverein | F17: Ja | G17: 5 | H17: Ja | I17: Bewertung erst Feb. 2026 | J17: =IFERROR(IF(B17="","",IF(ISNUMBER(B17),TEXT(YEAR(B17),"0"),"")),"") -> 2026 | K17: =IFERROR(IF(B17="","",IF(ISNUMBER(B17),MONTH(B17),"")),"") -> 2
A18: 15 | B18: 46058 | C18: 2311052463 | D18: Theater im Palais, Erfurt | E18: Kulturverein / Theater | F18: Ja | G18: 5 | H18: Ja | J18: =IFERROR(IF(B18="","",IF(ISNUMBER(B18),TEXT(YEAR(B18),"0"),"")),"") -> 2026 | K18: =IFERROR(IF(B18="","",IF(ISNUMBER(B18),MONTH(B18),"")),"") -> 2
A19: 16 | B19: 46064 | C19: 2502052826 | D19: THW Helfervereinigung Lüneburg e.V. | E19: THW / Hilfsorganisation | F19: Ja | G19: 5 | H19: Ja | I19: 2 x 5 Sterne | J19: =IFERROR(IF(B19="","",IF(ISNUMBER(B19),TEXT(YEAR(B19),"0"),"")),"") -> 2026 | K19: =IFERROR(IF(B19="","",IF(ISNUMBER(B19),MONTH(B19),"")),"") -> 2
A20: 17 | B20: 46065 | C20: 2503052854 | D20: Stadtkapelle/Spielmannszug Pfaffenhofen | E20: Musikverein | F20: Ja | G20: 5 | H20: Ja | I20: erhalten | J20: =IFERROR(IF(B20="","",IF(ISNUMBER(B20),TEXT(YEAR(B20),"0"),"")),"") -> 2026 | K20: =IFERROR(IF(B20="","",IF(ISNUMBER(B20),MONTH(B20),"")),"") -> 2
A21: 18 | B21: 46065 | C21: 2405052628 | D21: SSV Neumünster | E21: Sportverein | F21: Ja | G21: 5 | H21: Nein | I21: Referenz ausstehend | J21: =IFERROR(IF(B21="","",IF(ISNUMBER(B21),TEXT(YEAR(B21),"0"),"")),"") -> 2026 | K21: =IFERROR(IF(B21="","",IF(ISNUMBER(B21),MONTH(B21),"")),"") -> 2
A22: 19 | B22: 46066 | C22: 2402052527 | D22: Haus Aichele, Beuren | E22: Sonstige | F22: Ja | G22: 5 | H22: Ja | J22: =IFERROR(IF(B22="","",IF(ISNUMBER(B22),TEXT(YEAR(B22),"0"),"")),"") -> 2026 | K22: =IFERROR(IF(B22="","",IF(ISNUMBER(B22),MONTH(B22),"")),"") -> 2
A23: 20 | B23: 46066 | C23: 2409052706 | D23: Florianskameradschaft Sauggart e.V. | E23: Sportverein | H23: ja | I23: Aus Auslieferungsliste 2026 ergänzt | J23: =IFERROR(IF(B23="","",IF(ISNUMBER(B23),TEXT(YEAR(B23),"0"),"")),"") -> 2026 | K23: =IFERROR(IF(B23="","",IF(ISNUMBER(B23),MONTH(B23),"")),"") -> 2 | L23: Erinnerung Google Bewertung 23.06.
A24: 21 | B24: 46071 | C24: 2503052855 | D24: Kleines Theater Bad Godesberg e.V. | E24: Kulturverein / Theater | F24: Ja | G24: 5 | H24: Ja | I24: Google Bewertung angef | J24: =IFERROR(IF(B24="","",IF(ISNUMBER(B24),TEXT(YEAR(B24),"0"),"")),"") -> 2026 | K24: =IFERROR(IF(B24="","",IF(ISNUMBER(B24),MONTH(B24),"")),"") -> 2
A25: 22 | B25: 46072 | C25: 2504052898 | D25: Familienzentrum minimaxi e.V. | E25: Soziale Einrichtung | F25: Ja | G25: 5 | H25: Ja | I25: Bewertung ang. Am 25.02. | J25: =IFERROR(IF(B25="","",IF(ISNUMBER(B25),TEXT(YEAR(B25),"0"),"")),"") -> 2026 | K25: =IFERROR(IF(B25="","",IF(ISNUMBER(B25),MONTH(B25),"")),"") -> 2
A26: 23 | B26: 46074 | C26: 2507052962 | D26: VFL Rheingold 1912 Köln-Poll e.V. | E26: Sportverein | F26: Ja | G26: 5 | H26: ja | I26: Kommt KW 9 | J26: =IFERROR(IF(B26="","",IF(ISNUMBER(B26),TEXT(YEAR(B26),"0"),"")),"") -> 2026 | K26: =IFERROR(IF(B26="","",IF(ISNUMBER(B26),MONTH(B26),"")),"") -> 2
A27: 24 | B27: 46076 | C27: 2505052910 | D27: Tinko Kindertheater Gießen e. V. | E27: Kulturverein / Theater | F27: ja | G27: 5 | H27: ja | I27: erhalten | J27: =IFERROR(IF(B27="","",IF(ISNUMBER(B27),TEXT(YEAR(B27),"0"),"")),"") -> 2026 | K27: =IFERROR(IF(B27="","",IF(ISNUMBER(B27),MONTH(B27),"")),"") -> 2
A28: 25 | B28: 46078 | C28: 2411052774 | D28: Turn- und Sportverein Schwangau e.V. | E28: Sportverein | H28: ja | I28: Google Bewertung kommt am 27.03 | J28: =IFERROR(IF(B28="","",IF(ISNUMBER(B28),TEXT(YEAR(B28),"0"),"")),"") -> 2026 | K28: =IFERROR(IF(B28="","",IF(ISNUMBER(B28),MONTH(B28),"")),"") -> 2 | L28: Erinnerung Google Bewertung 30.06.
A29: 26 | B29: 46078 | C29: 2409052712 | D29: Sportverein Eberhardzell 1922 e.V. | E29: Sportverein | F29: ja | G29: 5 | H29: ja | I29: Google Bewertung angef | J29: =IFERROR(IF(B29="","",IF(ISNUMBER(B29),TEXT(YEAR(B29),"0"),"")),"") -> 2026 | K29: =IFERROR(IF(B29="","",IF(ISNUMBER(B29),MONTH(B29),"")),"") -> 2 | L29: nochmal Google Bewertung gesendet 12.06.
A30: 27 | B30: 46080 | C30: 2502052829 | D30: FV Tiefenbronn 1920 e.V. | E30: Sportverein | H30: ja | I30: Google Bewertung angef | J30: =IFERROR(IF(B30="","",IF(ISNUMBER(B30),TEXT(YEAR(B30),"0"),"")),"") -> 2026 | K30: =IFERROR(IF(B30="","",IF(ISNUMBER(B30),MONTH(B30),"")),"") -> 2
A31: 28 | B31: 46085 | C31: 2402052504 | D31: Graf von Galen Schule - Heidelberg | E31: Schule / Kita | F31: ja | G31: 5 | H31: Ja | I31: Google Bewertung angef | J31: =IFERROR(IF(B31="","",IF(ISNUMBER(B31),TEXT(YEAR(B31),"0"),"")),"") -> 2026 | K31: =IFERROR(IF(B31="","",IF(ISNUMBER(B31),MONTH(B31),"")),"") -> 3
A32: 29 | B32: 46085 | C32: 2411052775 | D32: TSV Pflaumheim 1913 e.V. | E32: Sportverein | I32: Google Bewertung angef | J32: =IFERROR(IF(B32="","",IF(ISNUMBER(B32),TEXT(YEAR(B32),"0"),"")),"") -> 2026 | K32: =IFERROR(IF(B32="","",IF(ISNUMBER(B32),MONTH(B32),"")),"") -> 3 | L32: Erinnerung Google Bewertung 30.06.
A33: 30 | B33: 46086 | C33: 2407052686 | D33: Theater Gruene Sosse | E33: Kulturverein / Theater | F33: ja | G33: 5 | H33: Ja | I33: Google Bewertung angef | J33: =IFERROR(IF(B33="","",IF(ISNUMBER(B33),TEXT(YEAR(B33),"0"),"")),"") -> 2026 | K33: =IFERROR(IF(B33="","",IF(ISNUMBER(B33),MONTH(B33),"")),"") -> 3
A34: 31 | B34: 46087 | C34: 2202051897 | D34: Freie Waldorfschule Vordertaunus | E34: Schule / Kita | F34: ja | G34: 5 | H34: ja | I34: Google Bewertung kommt am 27.03 | J34: =IFERROR(IF(B34="","",IF(ISNUMBER(B34),TEXT(YEAR(B34),"0"),"")),"") -> 2026 | K34: =IFERROR(IF(B34="","",IF(ISNUMBER(B34),MONTH(B34),"")),"") -> 3
A35: 32 | B35: 46091 | C35: 2502052818 | D35: Schützenverein Owingen 1921 e.V. | E35: Kulturverein / Theater | F35: ja | G35: 5 | H35: ja | I35: Google Bewertung angef | J35: =IFERROR(IF(B35="","",IF(ISNUMBER(B35),TEXT(YEAR(B35),"0"),"")),"") -> 2026 | K35: =IFERROR(IF(B35="","",IF(ISNUMBER(B35),MONTH(B35),"")),"") -> 3
A36: 33 | B36: 46092 | C36: 2502052815 | D36: Anderssein e.V. | E36: Soziale Einrichtung | F36: ja | G36: 5 | H36: ja | I36: Google Bewertung angef | J36: =IFERROR(IF(B36="","",IF(ISNUMBER(B36),TEXT(YEAR(B36),"0"),"")),"") -> 2026 | K36: =IFERROR(IF(B36="","",IF(ISNUMBER(B36),MONTH(B36),"")),"") -> 3
A37: 34 | B37: 46092 | C37: 2407052675 | D37: Oppumer Verein für notleidende Pferde | E37: Sonstige | F37: ja | G37: 5 | H37: ja | I37: versuchen die Google Bewertung zu machen | J37: =IFERROR(IF(B37="","",IF(ISNUMBER(B37),TEXT(YEAR(B37),"0"),"")),"") -> 2026 | K37: =IFERROR(IF(B37="","",IF(ISNUMBER(B37),MONTH(B37),"")),"") -> 3
A38: 35 | B38: 46092 | C38: 2404052592 | D38: SV Hörmannsdorf e.V. | E38: Sportverein | F38: ja | G38: 5 | I38: Daniel Thomas | J38: =IFERROR(IF(B38="","",IF(ISNUMBER(B38),TEXT(YEAR(B38),"0"),"")),"") -> 2026 | K38: =IFERROR(IF(B38="","",IF(ISNUMBER(B38),MONTH(B38),"")),"") -> 3
A39: 36 | B39: 46100 | C39: 2507052954 | D39: AWO Betreuungsverein Altenkirchen e.V. | E39: Soziale Einrichtung | F39: ja | G39: 5 | H39: ja | I39: Google Bewertung angef. | J39: =IFERROR(IF(B39="","",IF(ISNUMBER(B39),TEXT(YEAR(B39),"0"),"")),"") -> 2026 | K39: =IFERROR(IF(B39="","",IF(ISNUMBER(B39),MONTH(B39),"")),"") -> 3
A40: 37 | B40: 46100 | C40: 2504052871 | D40: Freiwillige Feuerwehr Waldorfhäslach | E40: Feuerwehr (FFW) | I40: kommmt Bewertung - Tankgutschein | J40: =IFERROR(IF(B40="","",IF(ISNUMBER(B40),TEXT(YEAR(B40),"0"),"")),"") -> 2026 | K40: =IFERROR(IF(B40="","",IF(ISNUMBER(B40),MONTH(B40),"")),"") -> 3 | L40: Google Bewertung angefordert 30.06.
...

Sheet Monatsauswertung
A1: MONATSAUSWERTUNG – automatisch berechnet (basiert auf Rohdaten)
A2: Alle Werte werden per Formel aus dem Rohdaten-Sheet berechnet. Keine manuelle Eingabe nötig.
A3: Monat (MM/JJJJ) | B3: Anzahl Auslieferungen | C3: Anzahl Google-Bew. | D3: Google-Bew. Quote | E3: Anzahl Referenzen | F3: Referenz- Quote | G3: Ø Sterne- bewertung | H3: Anzahl 5-Sterne | I3: Anzahl 4-Sterne | J3: Anzahl 3-Sterne | K3: Anzahl ≤2-Sterne | L3: Antwort- Quote
A4: 10/2025 | B4: =COUNTIFS(Rohdaten!J:J,"2025",Rohdaten!K:K,10) -> 2 | C4: =COUNTIFS(Rohdaten!J:J,"2025",Rohdaten!K:K,10,Rohdaten!F:F,"Ja") -> 2 | D4: =IF(B4=0,"-",C4/B4) -> 1 | E4: =COUNTIFS(Rohdaten!J:J,"2025",Rohdaten!K:K,10,Rohdaten!H:H,"Ja") -> 2 | F4: =IF(B4=0,"-",E4/B4) -> 1 | G4: =IFERROR(AVERAGEIFS(Rohdaten!G:G,Rohdaten!J:J,"2025",Rohdaten!K:K,10,Rohdaten!F:F,"Ja"),"-") -> 5 | H4: =COUNTIFS(Rohdaten!J:J,"2025",Rohdaten!K:K,10,Rohdaten!G:G,5) -> 2 | I4: =COUNTIFS(Rohdaten!J:J,"2025",Rohdaten!K:K,10,Rohdaten!G:G,4) -> 0 | J4: =COUNTIFS(Rohdaten!J:J,"2025",Rohdaten!K:K,10,Rohdaten!G:G,3) -> 0 | K4: =COUNTIFS(Rohdaten!J:J,"2025",Rohdaten!K:K,10,Rohdaten!G:G,"<3") -> 0 | L4: =IF(C4=0,"-",COUNTIFS(Rohdaten!J:J,"2025",Rohdaten!K:K,10,Rohdaten!#REF!,"Ja")/C4) -> #REF!
A5: 11/2025 | B5: =COUNTIFS(Rohdaten!J:J,"2025",Rohdaten!K:K,11) -> 4 | C5: =COUNTIFS(Rohdaten!J:J,"2025",Rohdaten!K:K,11,Rohdaten!F:F,"Ja") -> 4 | D5: =IF(B5=0,"-",C5/B5) -> 1 | E5: =COUNTIFS(Rohdaten!J:J,"2025",Rohdaten!K:K,11,Rohdaten!H:H,"Ja") -> 3 | F5: =IF(B5=0,"-",E5/B5) -> 0.75 | G5: =IFERROR(AVERAGEIFS(Rohdaten!G:G,Rohdaten!J:J,"2025",Rohdaten!K:K,11,Rohdaten!F:F,"Ja"),"-") -> 5 | H5: =COUNTIFS(Rohdaten!J:J,"2025",Rohdaten!K:K,11,Rohdaten!G:G,5) -> 4 | I5: =COUNTIFS(Rohdaten!J:J,"2025",Rohdaten!K:K,11,Rohdaten!G:G,4) -> 0 | J5: =COUNTIFS(Rohdaten!J:J,"2025",Rohdaten!K:K,11,Rohdaten!G:G,3) -> 0 | K5: =COUNTIFS(Rohdaten!J:J,"2025",Rohdaten!K:K,11,Rohdaten!G:G,"<3") -> 0 | L5: =IF(C5=0,"-",COUNTIFS(Rohdaten!J:J,"2025",Rohdaten!K:K,11,Rohdaten!#REF!,"Ja")/C5) -> #REF!
A6: 12/2025 | B6: =COUNTIFS(Rohdaten!J:J,"2025",Rohdaten!K:K,12) -> 3 | C6: =COUNTIFS(Rohdaten!J:J,"2025",Rohdaten!K:K,12,Rohdaten!F:F,"Ja") -> 3 | D6: =IF(B6=0,"-",C6/B6) -> 1 | E6: =COUNTIFS(Rohdaten!J:J,"2025",Rohdaten!K:K,12,Rohdaten!H:H,"Ja") -> 1 | F6: =IF(B6=0,"-",E6/B6) -> 0.33333333 | G6: =IFERROR(AVERAGEIFS(Rohdaten!G:G,Rohdaten!J:J,"2025",Rohdaten!K:K,12,Rohdaten!F:F,"Ja"),"-") -> 4.6666667 | H6: =COUNTIFS(Rohdaten!J:J,"2025",Rohdaten!K:K,12,Rohdaten!G:G,5) -> 2 | I6: =COUNTIFS(Rohdaten!J:J,"2025",Rohdaten!K:K,12,Rohdaten!G:G,4) -> 1 | J6: =COUNTIFS(Rohdaten!J:J,"2025",Rohdaten!K:K,12,Rohdaten!G:G,3) -> 0 | K6: =COUNTIFS(Rohdaten!J:J,"2025",Rohdaten!K:K,12,Rohdaten!G:G,"<3") -> 0 | L6: =IF(C6=0,"-",COUNTIFS(Rohdaten!J:J,"2025",Rohdaten!K:K,12,Rohdaten!#REF!,"Ja")/C6) -> #REF!
A7: 01/2026 | B7: =COUNTIFS(Rohdaten!J:J,"2026",Rohdaten!K:K,1) -> 3 | C7: =COUNTIFS(Rohdaten!J:J,"2026",Rohdaten!K:K,1,Rohdaten!F:F,"Ja") -> 1 | D7: =IF(B7=0,"-",C7/B7) -> 0.33333333 | E7: =COUNTIFS(Rohdaten!J:J,"2026",Rohdaten!K:K,1,Rohdaten!H:H,"Ja") -> 1 | F7: =IF(B7=0,"-",E7/B7) -> 0.33333333 | G7: =IFERROR(AVERAGEIFS(Rohdaten!G:G,Rohdaten!J:J,"2026",Rohdaten!K:K,1,Rohdaten!F:F,"Ja"),"-") -> 5 | H7: =COUNTIFS(Rohdaten!J:J,"2026",Rohdaten!K:K,1,Rohdaten!G:G,5) -> 3 | I7: =COUNTIFS(Rohdaten!J:J,"2026",Rohdaten!K:K,1,Rohdaten!G:G,4) -> 0 | J7: =COUNTIFS(Rohdaten!J:J,"2026",Rohdaten!K:K,1,Rohdaten!G:G,3) -> 0 | K7: =COUNTIFS(Rohdaten!J:J,"2026",Rohdaten!K:K,1,Rohdaten!G:G,"<3") -> 0 | L7: =IF(C7=0,"-",COUNTIFS(Rohdaten!J:J,"2026",Rohdaten!K:K,1,Rohdaten!#REF!,"Ja")/C7) -> #REF!
A8: 02/2026 | B8: =COUNTIFS(Rohdaten!J:J,"2026",Rohdaten!K:K,2) -> 14 | C8: =COUNTIFS(Rohdaten!J:J,"2026",Rohdaten!K:K,2,Rohdaten!F:F,"Ja") -> 11 | D8: =IF(B8=0,"-",C8/B8) -> 0.78571429 | E8: =COUNTIFS(Rohdaten!J:J,"2026",Rohdaten!K:K,2,Rohdaten!H:H,"Ja") -> 13 | F8: =IF(B8=0,"-",E8/B8) -> 0.92857143 | G8: =IFERROR(AVERAGEIFS(Rohdaten!G:G,Rohdaten!J:J,"2026",Rohdaten!K:K,2,Rohdaten!F:F,"Ja"),"-") -> 5 | H8: =COUNTIFS(Rohdaten!J:J,"2026",Rohdaten!K:K,2,Rohdaten!G:G,5) -> 11 | I8: =COUNTIFS(Rohdaten!J:J,"2026",Rohdaten!K:K,2,Rohdaten!G:G,4) -> 0 | J8: =COUNTIFS(Rohdaten!J:J,"2026",Rohdaten!K:K,2,Rohdaten!G:G,3) -> 0 | K8: =COUNTIFS(Rohdaten!J:J,"2026",Rohdaten!K:K,2,Rohdaten!G:G,"<3") -> 0 | L8: =IF(C8=0,"-",COUNTIFS(Rohdaten!J:J,"2026",Rohdaten!K:K,2,Rohdaten!#REF!,"Ja")/C8) -> #REF!
A9: 03/2026 | B9: =COUNTIFS(Rohdaten!J:J,"2026",Rohdaten!K:K,3) -> 21 | C9: =COUNTIFS(Rohdaten!J:J,"2026",Rohdaten!K:K,3,Rohdaten!F:F,"Ja") -> 15 | D9: =IF(B9=0,"-",C9/B9) -> 0.71428571 | E9: =COUNTIFS(Rohdaten!J:J,"2026",Rohdaten!K:K,3,Rohdaten!H:H,"Ja") -> 17 | F9: =IF(B9=0,"-",E9/B9) -> 0.80952381 | G9: =IFERROR(AVERAGEIFS(Rohdaten!G:G,Rohdaten!J:J,"2026",Rohdaten!K:K,3,Rohdaten!F:F,"Ja"),"-") -> 5 | H9: =COUNTIFS(Rohdaten!J:J,"2026",Rohdaten!K:K,3,Rohdaten!G:G,5) -> 15 | I9: =COUNTIFS(Rohdaten!J:J,"2026",Rohdaten!K:K,3,Rohdaten!G:G,4) -> 0 | J9: =COUNTIFS(Rohdaten!J:J,"2026",Rohdaten!K:K,3,Rohdaten!G:G,3) -> 0 | K9: =COUNTIFS(Rohdaten!J:J,"2026",Rohdaten!K:K,3,Rohdaten!G:G,"<3") -> 0 | L9: =IF(C9=0,"-",COUNTIFS(Rohdaten!J:J,"2026",Rohdaten!K:K,3,Rohdaten!#REF!,"Ja")/C9) -> #REF!
A10: 04/2026 | B10: =COUNTIFS(Rohdaten!J:J,"2026",Rohdaten!K:K,4) -> 17 | C10: =COUNTIFS(Rohdaten!J:J,"2026",Rohdaten!K:K,4,Rohdaten!F:F,"Ja") -> 8 | D10: =IF(B10=0,"-",C10/B10) -> 0.47058824 | E10: =COUNTIFS(Rohdaten!J:J,"2026",Rohdaten!K:K,4,Rohdaten!H:H,"Ja") -> 16 | F10: =IF(B10=0,"-",E10/B10) -> 0.94117647 | G10: =IFERROR(AVERAGEIFS(Rohdaten!G:G,Rohdaten!J:J,"2026",Rohdaten!K:K,4,Rohdaten!F:F,"Ja"),"-") -> 5 | H10: =COUNTIFS(Rohdaten!J:J,"2026",Rohdaten!K:K,4,Rohdaten!G:G,5) -> 8 | I10: =COUNTIFS(Rohdaten!J:J,"2026",Rohdaten!K:K,4,Rohdaten!G:G,4) -> 0 | J10: =COUNTIFS(Rohdaten!J:J,"2026",Rohdaten!K:K,4,Rohdaten!G:G,3) -> 0 | K10: =COUNTIFS(Rohdaten!J:J,"2026",Rohdaten!K:K,4,Rohdaten!G:G,"<3") -> 0 | L10: =IF(C10=0,"-",COUNTIFS(Rohdaten!J:J,"2026",Rohdaten!K:K,4,Rohdaten!#REF!,"Ja")/C10) -> #REF!
A11: 05/2026 | B11: =COUNTIFS(Rohdaten!J:J,"2026",Rohdaten!K:K,5) -> 7 | C11: =COUNTIFS(Rohdaten!J:J,"2026",Rohdaten!K:K,5,Rohdaten!F:F,"Ja") -> 3 | D11: =IF(B11=0,"-",C11/B11) -> 0.42857143 | E11: =COUNTIFS(Rohdaten!J:J,"2026",Rohdaten!K:K,5,Rohdaten!H:H,"Ja") -> 7 | F11: =IF(B11=0,"-",E11/B11) -> 1 | G11: =IFERROR(AVERAGEIFS(Rohdaten!G:G,Rohdaten!J:J,"2026",Rohdaten!K:K,5,Rohdaten!F:F,"Ja"),"-") -> 5 | H11: =COUNTIFS(Rohdaten!J:J,"2026",Rohdaten!K:K,5,Rohdaten!G:G,5) -> 3 | I11: =COUNTIFS(Rohdaten!J:J,"2026",Rohdaten!K:K,5,Rohdaten!G:G,4) -> 0 | J11: =COUNTIFS(Rohdaten!J:J,"2026",Rohdaten!K:K,5,Rohdaten!G:G,3) -> 0 | K11: =COUNTIFS(Rohdaten!J:J,"2026",Rohdaten!K:K,5,Rohdaten!G:G,"<3") -> 0 | L11: =IF(C11=0,"-",COUNTIFS(Rohdaten!J:J,"2026",Rohdaten!K:K,5,Rohdaten!#REF!,"Ja")/C11) -> #REF!
A12: 06/2026 | B12: =COUNTIFS(Rohdaten!J:J,"2026",Rohdaten!K:K,6) -> 13 | C12: =COUNTIFS(Rohdaten!J:J,"2026",Rohdaten!K:K,6,Rohdaten!F:F,"Ja") -> 4 | D12: =IF(B12=0,"-",C12/B12) -> 0.30769231 | E12: =COUNTIFS(Rohdaten!J:J,"2026",Rohdaten!K:K,6,Rohdaten!H:H,"Ja") -> 11 | F12: =IF(B12=0,"-",E12/B12) -> 0.84615385 | G12: =IFERROR(AVERAGEIFS(Rohdaten!G:G,Rohdaten!J:J,"2026",Rohdaten!K:K,6,Rohdaten!F:F,"Ja"),"-") -> 4.75 | H12: =COUNTIFS(Rohdaten!J:J,"2026",Rohdaten!K:K,6,Rohdaten!G:G,5) -> 3 | I12: =COUNTIFS(Rohdaten!J:J,"2026",Rohdaten!K:K,6,Rohdaten!G:G,4) -> 1 | J12: =COUNTIFS(Rohdaten!J:J,"2026",Rohdaten!K:K,6,Rohdaten!G:G,3) -> 0 | K12: =COUNTIFS(Rohdaten!J:J,"2026",Rohdaten!K:K,6,Rohdaten!G:G,"<3") -> 0 | L12: =IF(C12=0,"-",COUNTIFS(Rohdaten!J:J,"2026",Rohdaten!K:K,6,Rohdaten!#REF!,"Ja")/C12) -> #REF!
A13: 07/2026 | B13: =COUNTIFS(Rohdaten!J:J,"2026",Rohdaten!K:K,7) -> 3 | C13: =COUNTIFS(Rohdaten!J:J,"2026",Rohdaten!K:K,7,Rohdaten!F:F,"Ja") -> 1 | D13: =IF(B13=0,"-",C13/B13) -> 0.33333333 | E13: =COUNTIFS(Rohdaten!J:J,"2026",Rohdaten!K:K,7,Rohdaten!H:H,"Ja") -> 2 | F13: =IF(B13=0,"-",E13/B13) -> 0.66666667 | G13: =IFERROR(AVERAGEIFS(Rohdaten!G:G,Rohdaten!J:J,"2026",Rohdaten!K:K,7,Rohdaten!F:F,"Ja"),"-") -> 5 | H13: =COUNTIFS(Rohdaten!J:J,"2026",Rohdaten!K:K,7,Rohdaten!G:G,5) -> 1 | I13: =COUNTIFS(Rohdaten!J:J,"2026",Rohdaten!K:K,7,Rohdaten!G:G,4) -> 0 | J13: =COUNTIFS(Rohdaten!J:J,"2026",Rohdaten!K:K,7,Rohdaten!G:G,3) -> 0 | K13: =COUNTIFS(Rohdaten!J:J,"2026",Rohdaten!K:K,7,Rohdaten!G:G,"<3") -> 0 | L13: =IF(C13=0,"-",COUNTIFS(Rohdaten!J:J,"2026",Rohdaten!K:K,7,Rohdaten!#REF!,"Ja")/C13) -> #REF!
A14: 08/2026 | B14: =COUNTIFS(Rohdaten!J:J,"2026",Rohdaten!K:K,8) -> 0 | C14: =COUNTIFS(Rohdaten!J:J,"2026",Rohdaten!K:K,8,Rohdaten!F:F,"Ja") -> 0 | D14: =IF(B14=0,"-",C14/B14) -> - | E14: =COUNTIFS(Rohdaten!J:J,"2026",Rohdaten!K:K,8,Rohdaten!H:H,"Ja") -> 0 | F14: =IF(B14=0,"-",E14/B14) -> - | G14: =IFERROR(AVERAGEIFS(Rohdaten!G:G,Rohdaten!J:J,"2026",Rohdaten!K:K,8,Rohdaten!F:F,"Ja"),"-") -> - | H14: =COUNTIFS(Rohdaten!J:J,"2026",Rohdaten!K:K,8,Rohdaten!G:G,5) -> 0 | I14: =COUNTIFS(Rohdaten!J:J,"2026",Rohdaten!K:K,8,Rohdaten!G:G,4) -> 0 | J14: =COUNTIFS(Rohdaten!J:J,"2026",Rohdaten!K:K,8,Rohdaten!G:G,3) -> 0 | K14: =COUNTIFS(Rohdaten!J:J,"2026",Rohdaten!K:K,8,Rohdaten!G:G,"<3") -> 0 | L14: =IF(C14=0,"-",COUNTIFS(Rohdaten!J:J,"2026",Rohdaten!K:K,8,Rohdaten!#REF!,"Ja")/C14) -> -
A15: 09/2026 | B15: =COUNTIFS(Rohdaten!J:J,"2026",Rohdaten!K:K,9) -> 0 | C15: =COUNTIFS(Rohdaten!J:J,"2026",Rohdaten!K:K,9,Rohdaten!F:F,"Ja") -> 0 | D15: =IF(B15=0,"-",C15/B15) -> - | E15: =COUNTIFS(Rohdaten!J:J,"2026",Rohdaten!K:K,9,Rohdaten!H:H,"Ja") -> 0 | F15: =IF(B15=0,"-",E15/B15) -> - | G15: =IFERROR(AVERAGEIFS(Rohdaten!G:G,Rohdaten!J:J,"2026",Rohdaten!K:K,9,Rohdaten!F:F,"Ja"),"-") -> - | H15: =COUNTIFS(Rohdaten!J:J,"2026",Rohdaten!K:K,9,Rohdaten!G:G,5) -> 0 | I15: =COUNTIFS(Rohdaten!J:J,"2026",Rohdaten!K:K,9,Rohdaten!G:G,4) -> 0 | J15: =COUNTIFS(Rohdaten!J:J,"2026",Rohdaten!K:K,9,Rohdaten!G:G,3) -> 0 | K15: =COUNTIFS(Rohdaten!J:J,"2026",Rohdaten!K:K,9,Rohdaten!G:G,"<3") -> 0 | L15: =IF(C15=0,"-",COUNTIFS(Rohdaten!J:J,"2026",Rohdaten!K:K,9,Rohdaten!#REF!,"Ja")/C15) -> -
A16: 10/2026 | B16: =COUNTIFS(Rohdaten!J:J,"2026",Rohdaten!K:K,10) -> 0 | C16: =COUNTIFS(Rohdaten!J:J,"2026",Rohdaten!K:K,10,Rohdaten!F:F,"Ja") -> 0 | D16: =IF(B16=0,"-",C16/B16) -> - | E16: =COUNTIFS(Rohdaten!J:J,"2026",Rohdaten!K:K,10,Rohdaten!H:H,"Ja") -> 0 | F16: =IF(B16=0,"-",E16/B16) -> - | G16: =IFERROR(AVERAGEIFS(Rohdaten!G:G,Rohdaten!J:J,"2026",Rohdaten!K:K,10,Rohdaten!F:F,"Ja"),"-") -> - | H16: =COUNTIFS(Rohdaten!J:J,"2026",Rohdaten!K:K,10,Rohdaten!G:G,5) -> 0 | I16: =COUNTIFS(Rohdaten!J:J,"2026",Rohdaten!K:K,10,Rohdaten!G:G,4) -> 0 | J16: =COUNTIFS(Rohdaten!J:J,"2026",Rohdaten!K:K,10,Rohdaten!G:G,3) -> 0 | K16: =COUNTIFS(Rohdaten!J:J,"2026",Rohdaten!K:K,10,Rohdaten!G:G,"<3") -> 0 | L16: =IF(C16=0,"-",COUNTIFS(Rohdaten!J:J,"2026",Rohdaten!K:K,10,Rohdaten!#REF!,"Ja")/C16) -> -
A17: 11/2026 | B17: =COUNTIFS(Rohdaten!J:J,"2026",Rohdaten!K:K,11) -> 0 | C17: =COUNTIFS(Rohdaten!J:J,"2026",Rohdaten!K:K,11,Rohdaten!F:F,"Ja") -> 0 | D17: =IF(B17=0,"-",C17/B17) -> - | E17: =COUNTIFS(Rohdaten!J:J,"2026",Rohdaten!K:K,11,Rohdaten!H:H,"Ja") -> 0 | F17: =IF(B17=0,"-",E17/B17) -> - | G17: =IFERROR(AVERAGEIFS(Rohdaten!G:G,Rohdaten!J:J,"2026",Rohdaten!K:K,11,Rohdaten!F:F,"Ja"),"-") -> - | H17: =COUNTIFS(Rohdaten!J:J,"2026",Rohdaten!K:K,11,Rohdaten!G:G,5) -> 0 | I17: =COUNTIFS(Rohdaten!J:J,"2026",Rohdaten!K:K,11,Rohdaten!G:G,4) -> 0 | J17: =COUNTIFS(Rohdaten!J:J,"2026",Rohdaten!K:K,11,Rohdaten!G:G,3) -> 0 | K17: =COUNTIFS(Rohdaten!J:J,"2026",Rohdaten!K:K,11,Rohdaten!G:G,"<3") -> 0 | L17: =IF(C17=0,"-",COUNTIFS(Rohdaten!J:J,"2026",Rohdaten!K:K,11,Rohdaten!#REF!,"Ja")/C17) -> -
A18: 12/2026 | B18: =COUNTIFS(Rohdaten!J:J,"2026",Rohdaten!K:K,12) -> 0 | C18: =COUNTIFS(Rohdaten!J:J,"2026",Rohdaten!K:K,12,Rohdaten!F:F,"Ja") -> 0 | D18: =IF(B18=0,"-",C18/B18) -> - | E18: =COUNTIFS(Rohdaten!J:J,"2026",Rohdaten!K:K,12,Rohdaten!H:H,"Ja") -> 0 | F18: =IF(B18=0,"-",E18/B18) -> - | G18: =IFERROR(AVERAGEIFS(Rohdaten!G:G,Rohdaten!J:J,"2026",Rohdaten!K:K,12,Rohdaten!F:F,"Ja"),"-") -> - | H18: =COUNTIFS(Rohdaten!J:J,"2026",Rohdaten!K:K,12,Rohdaten!G:G,5) -> 0 | I18: =COUNTIFS(Rohdaten!J:J,"2026",Rohdaten!K:K,12,Rohdaten!G:G,4) -> 0 | J18: =COUNTIFS(Rohdaten!J:J,"2026",Rohdaten!K:K,12,Rohdaten!G:G,3) -> 0 | K18: =COUNTIFS(Rohdaten!J:J,"2026",Rohdaten!K:K,12,Rohdaten!G:G,"<3") -> 0 | L18: =IF(C18=0,"-",COUNTIFS(Rohdaten!J:J,"2026",Rohdaten!K:K,12,Rohdaten!#REF!,"Ja")/C18) -> -
A19: 01/2027 | B19: =COUNTIFS(Rohdaten!J:J,"2027",Rohdaten!K:K,1) -> 0 | C19: =COUNTIFS(Rohdaten!J:J,"2027",Rohdaten!K:K,1,Rohdaten!F:F,"Ja") -> 0 | D19: =IF(B19=0,"-",C19/B19) -> - | E19: =COUNTIFS(Rohdaten!J:J,"2027",Rohdaten!K:K,1,Rohdaten!H:H,"Ja") -> 0 | F19: =IF(B19=0,"-",E19/B19) -> - | G19: =IFERROR(AVERAGEIFS(Rohdaten!G:G,Rohdaten!J:J,"2027",Rohdaten!K:K,1,Rohdaten!F:F,"Ja"),"-") -> - | H19: =COUNTIFS(Rohdaten!J:J,"2027",Rohdaten!K:K,1,Rohdaten!G:G,5) -> 0 | I19: =COUNTIFS(Rohdaten!J:J,"2027",Rohdaten!K:K,1,Rohdaten!G:G,4) -> 0 | J19: =COUNTIFS(Rohdaten!J:J,"2027",Rohdaten!K:K,1,Rohdaten!G:G,3) -> 0 | K19: =COUNTIFS(Rohdaten!J:J,"2027",Rohdaten!K:K,1,Rohdaten!G:G,"<3") -> 0 | L19: =IF(C19=0,"-",COUNTIFS(Rohdaten!J:J,"2027",Rohdaten!K:K,1,Rohdaten!#REF!,"Ja")/C19) -> -
A20: 02/2027 | B20: =COUNTIFS(Rohdaten!J:J,"2027",Rohdaten!K:K,2) -> 0 | C20: =COUNTIFS(Rohdaten!J:J,"2027",Rohdaten!K:K,2,Rohdaten!F:F,"Ja") -> 0 | D20: =IF(B20=0,"-",C20/B20) -> - | E20: =COUNTIFS(Rohdaten!J:J,"2027",Rohdaten!K:K,2,Rohdaten!H:H,"Ja") -> 0 | F20: =IF(B20=0,"-",E20/B20) -> - | G20: =IFERROR(AVERAGEIFS(Rohdaten!G:G,Rohdaten!J:J,"2027",Rohdaten!K:K,2,Rohdaten!F:F,"Ja"),"-") -> - | H20: =COUNTIFS(Rohdaten!J:J,"2027",Rohdaten!K:K,2,Rohdaten!G:G,5) -> 0 | I20: =COUNTIFS(Rohdaten!J:J,"2027",Rohdaten!K:K,2,Rohdaten!G:G,4) -> 0 | J20: =COUNTIFS(Rohdaten!J:J,"2027",Rohdaten!K:K,2,Rohdaten!G:G,3) -> 0 | K20: =COUNTIFS(Rohdaten!J:J,"2027",Rohdaten!K:K,2,Rohdaten!G:G,"<3") -> 0 | L20: =IF(C20=0,"-",COUNTIFS(Rohdaten!J:J,"2027",Rohdaten!K:K,2,Rohdaten!#REF!,"Ja")/C20) -> -
A21: 03/2027 | B21: =COUNTIFS(Rohdaten!J:J,"2027",Rohdaten!K:K,3) -> 0 | C21: =COUNTIFS(Rohdaten!J:J,"2027",Rohdaten!K:K,3,Rohdaten!F:F,"Ja") -> 0 | D21: =IF(B21=0,"-",C21/B21) -> - | E21: =COUNTIFS(Rohdaten!J:J,"2027",Rohdaten!K:K,3,Rohdaten!H:H,"Ja") -> 0 | F21: =IF(B21=0,"-",E21/B21) -> - | G21: =IFERROR(AVERAGEIFS(Rohdaten!G:G,Rohdaten!J:J,"2027",Rohdaten!K:K,3,Rohdaten!F:F,"Ja"),"-") -> - | H21: =COUNTIFS(Rohdaten!J:J,"2027",Rohdaten!K:K,3,Rohdaten!G:G,5) -> 0 | I21: =COUNTIFS(Rohdaten!J:J,"2027",Rohdaten!K:K,3,Rohdaten!G:G,4) -> 0 | J21: =COUNTIFS(Rohdaten!J:J,"2027",Rohdaten!K:K,3,Rohdaten!G:G,3) -> 0 | K21: =COUNTIFS(Rohdaten!J:J,"2027",Rohdaten!K:K,3,Rohdaten!G:G,"<3") -> 0 | L21: =IF(C21=0,"-",COUNTIFS(Rohdaten!J:J,"2027",Rohdaten!K:K,3,Rohdaten!#REF!,"Ja")/C21) -> -
A22: 04/2027 | B22: =COUNTIFS(Rohdaten!J:J,"2027",Rohdaten!K:K,4) -> 0 | C22: =COUNTIFS(Rohdaten!J:J,"2027",Rohdaten!K:K,4,Rohdaten!F:F,"Ja") -> 0 | D22: =IF(B22=0,"-",C22/B22) -> - | E22: =COUNTIFS(Rohdaten!J:J,"2027",Rohdaten!K:K,4,Rohdaten!H:H,"Ja") -> 0 | F22: =IF(B22=0,"-",E22/B22) -> - | G22: =IFERROR(AVERAGEIFS(Rohdaten!G:G,Rohdaten!J:J,"2027",Rohdaten!K:K,4,Rohdaten!F:F,"Ja"),"-") -> - | H22: =COUNTIFS(Rohdaten!J:J,"2027",Rohdaten!K:K,4,Rohdaten!G:G,5) -> 0 | I22: =COUNTIFS(Rohdaten!J:J,"2027",Rohdaten!K:K,4,Rohdaten!G:G,4) -> 0 | J22: =COUNTIFS(Rohdaten!J:J,"2027",Rohdaten!K:K,4,Rohdaten!G:G,3) -> 0 | K22: =COUNTIFS(Rohdaten!J:J,"2027",Rohdaten!K:K,4,Rohdaten!G:G,"<3") -> 0 | L22: =IF(C22=0,"-",COUNTIFS(Rohdaten!J:J,"2027",Rohdaten!K:K,4,Rohdaten!#REF!,"Ja")/C22) -> -
A23: 05/2027 | B23: =COUNTIFS(Rohdaten!J:J,"2027",Rohdaten!K:K,5) -> 0 | C23: =COUNTIFS(Rohdaten!J:J,"2027",Rohdaten!K:K,5,Rohdaten!F:F,"Ja") -> 0 | D23: =IF(B23=0,"-",C23/B23) -> - | E23: =COUNTIFS(Rohdaten!J:J,"2027",Rohdaten!K:K,5,Rohdaten!H:H,"Ja") -> 0 | F23: =IF(B23=0,"-",E23/B23) -> - | G23: =IFERROR(AVERAGEIFS(Rohdaten!G:G,Rohdaten!J:J,"2027",Rohdaten!K:K,5,Rohdaten!F:F,"Ja"),"-") -> - | H23: =COUNTIFS(Rohdaten!J:J,"2027",Rohdaten!K:K,5,Rohdaten!G:G,5) -> 0 | I23: =COUNTIFS(Rohdaten!J:J,"2027",Rohdaten!K:K,5,Rohdaten!G:G,4) -> 0 | J23: =COUNTIFS(Rohdaten!J:J,"2027",Rohdaten!K:K,5,Rohdaten!G:G,3) -> 0 | K23: =COUNTIFS(Rohdaten!J:J,"2027",Rohdaten!K:K,5,Rohdaten!G:G,"<3") -> 0 | L23: =IF(C23=0,"-",COUNTIFS(Rohdaten!J:J,"2027",Rohdaten!K:K,5,Rohdaten!#REF!,"Ja")/C23) -> -
A24: 06/2027 | B24: =COUNTIFS(Rohdaten!J:J,"2027",Rohdaten!K:K,6) -> 0 | C24: =COUNTIFS(Rohdaten!J:J,"2027",Rohdaten!K:K,6,Rohdaten!F:F,"Ja") -> 0 | D24: =IF(B24=0,"-",C24/B24) -> - | E24: =COUNTIFS(Rohdaten!J:J,"2027",Rohdaten!K:K,6,Rohdaten!H:H,"Ja") -> 0 | F24: =IF(B24=0,"-",E24/B24) -> - | G24: =IFERROR(AVERAGEIFS(Rohdaten!G:G,Rohdaten!J:J,"2027",Rohdaten!K:K,6,Rohdaten!F:F,"Ja"),"-") -> - | H24: =COUNTIFS(Rohdaten!J:J,"2027",Rohdaten!K:K,6,Rohdaten!G:G,5) -> 0 | I24: =COUNTIFS(Rohdaten!J:J,"2027",Rohdaten!K:K,6,Rohdaten!G:G,4) -> 0 | J24: =COUNTIFS(Rohdaten!J:J,"2027",Rohdaten!K:K,6,Rohdaten!G:G,3) -> 0 | K24: =COUNTIFS(Rohdaten!J:J,"2027",Rohdaten!K:K,6,Rohdaten!G:G,"<3") -> 0 | L24: =IF(C24=0,"-",COUNTIFS(Rohdaten!J:J,"2027",Rohdaten!K:K,6,Rohdaten!#REF!,"Ja")/C24) -> -
A25: 07/2027 | B25: =COUNTIFS(Rohdaten!J:J,"2027",Rohdaten!K:K,7) -> 0 | C25: =COUNTIFS(Rohdaten!J:J,"2027",Rohdaten!K:K,7,Rohdaten!F:F,"Ja") -> 0 | D25: =IF(B25=0,"-",C25/B25) -> - | E25: =COUNTIFS(Rohdaten!J:J,"2027",Rohdaten!K:K,7,Rohdaten!H:H,"Ja") -> 0 | F25: =IF(B25=0,"-",E25/B25) -> - | G25: =IFERROR(AVERAGEIFS(Rohdaten!G:G,Rohdaten!J:J,"2027",Rohdaten!K:K,7,Rohdaten!F:F,"Ja"),"-") -> - | H25: =COUNTIFS(Rohdaten!J:J,"2027",Rohdaten!K:K,7,Rohdaten!G:G,5) -> 0 | I25: =COUNTIFS(Rohdaten!J:J,"2027",Rohdaten!K:K,7,Rohdaten!G:G,4) -> 0 | J25: =COUNTIFS(Rohdaten!J:J,"2027",Rohdaten!K:K,7,Rohdaten!G:G,3) -> 0 | K25: =COUNTIFS(Rohdaten!J:J,"2027",Rohdaten!K:K,7,Rohdaten!G:G,"<3") -> 0 | L25: =IF(C25=0,"-",COUNTIFS(Rohdaten!J:J,"2027",Rohdaten!K:K,7,Rohdaten!#REF!,"Ja")/C25) -> -
A26: 08/2027 | B26: =COUNTIFS(Rohdaten!J:J,"2027",Rohdaten!K:K,8) -> 0 | C26: =COUNTIFS(Rohdaten!J:J,"2027",Rohdaten!K:K,8,Rohdaten!F:F,"Ja") -> 0 | D26: =IF(B26=0,"-",C26/B26) -> - | E26: =COUNTIFS(Rohdaten!J:J,"2027",Rohdaten!K:K,8,Rohdaten!H:H,"Ja") -> 0 | F26: =IF(B26=0,"-",E26/B26) -> - | G26: =IFERROR(AVERAGEIFS(Rohdaten!G:G,Rohdaten!J:J,"2027",Rohdaten!K:K,8,Rohdaten!F:F,"Ja"),"-") -> - | H26: =COUNTIFS(Rohdaten!J:J,"2027",Rohdaten!K:K,8,Rohdaten!G:G,5) -> 0 | I26: =COUNTIFS(Rohdaten!J:J,"2027",Rohdaten!K:K,8,Rohdaten!G:G,4) -> 0 | J26: =COUNTIFS(Rohdaten!J:J,"2027",Rohdaten!K:K,8,Rohdaten!G:G,3) -> 0 | K26: =COUNTIFS(Rohdaten!J:J,"2027",Rohdaten!K:K,8,Rohdaten!G:G,"<3") -> 0 | L26: =IF(C26=0,"-",COUNTIFS(Rohdaten!J:J,"2027",Rohdaten!K:K,8,Rohdaten!#REF!,"Ja")/C26) -> -
A27: 09/2027 | B27: =COUNTIFS(Rohdaten!J:J,"2027",Rohdaten!K:K,9) -> 0 | C27: =COUNTIFS(Rohdaten!J:J,"2027",Rohdaten!K:K,9,Rohdaten!F:F,"Ja") -> 0 | D27: =IF(B27=0,"-",C27/B27) -> - | E27: =COUNTIFS(Rohdaten!J:J,"2027",Rohdaten!K:K,9,Rohdaten!H:H,"Ja") -> 0 | F27: =IF(B27=0,"-",E27/B27) -> - | G27: =IFERROR(AVERAGEIFS(Rohdaten!G:G,Rohdaten!J:J,"2027",Rohdaten!K:K,9,Rohdaten!F:F,"Ja"),"-") -> - | H27: =COUNTIFS(Rohdaten!J:J,"2027",Rohdaten!K:K,9,Rohdaten!G:G,5) -> 0 | I27: =COUNTIFS(Rohdaten!J:J,"2027",Rohdaten!K:K,9,Rohdaten!G:G,4) -> 0 | J27: =COUNTIFS(Rohdaten!J:J,"2027",Rohdaten!K:K,9,Rohdaten!G:G,3) -> 0 | K27: =COUNTIFS(Rohdaten!J:J,"2027",Rohdaten!K:K,9,Rohdaten!G:G,"<3") -> 0 | L27: =IF(C27=0,"-",COUNTIFS(Rohdaten!J:J,"2027",Rohdaten!K:K,9,Rohdaten!#REF!,"Ja")/C27) -> -
A28: 10/2027 | B28: =COUNTIFS(Rohdaten!J:J,"2027",Rohdaten!K:K,10) -> 0 | C28: =COUNTIFS(Rohdaten!J:J,"2027",Rohdaten!K:K,10,Rohdaten!F:F,"Ja") -> 0 | D28: =IF(B28=0,"-",C28/B28) -> - | E28: =COUNTIFS(Rohdaten!J:J,"2027",Rohdaten!K:K,10,Rohdaten!H:H,"Ja") -> 0 | F28: =IF(B28=0,"-",E28/B28) -> - | G28: =IFERROR(AVERAGEIFS(Rohdaten!G:G,Rohdaten!J:J,"2027",Rohdaten!K:K,10,Rohdaten!F:F,"Ja"),"-") -> - | H28: =COUNTIFS(Rohdaten!J:J,"2027",Rohdaten!K:K,10,Rohdaten!G:G,5) -> 0 | I28: =COUNTIFS(Rohdaten!J:J,"2027",Rohdaten!K:K,10,Rohdaten!G:G,4) -> 0 | J28: =COUNTIFS(Rohdaten!J:J,"2027",Rohdaten!K:K,10,Rohdaten!G:G,3) -> 0 | K28: =COUNTIFS(Rohdaten!J:J,"2027",Rohdaten!K:K,10,Rohdaten!G:G,"<3") -> 0 | L28: =IF(C28=0,"-",COUNTIFS(Rohdaten!J:J,"2027",Rohdaten!K:K,10,Rohdaten!#REF!,"Ja")/C28) -> -
A29: 11/2027 | B29: =COUNTIFS(Rohdaten!J:J,"2027",Rohdaten!K:K,11) -> 0 | C29: =COUNTIFS(Rohdaten!J:J,"2027",Rohdaten!K:K,11,Rohdaten!F:F,"Ja") -> 0 | D29: =IF(B29=0,"-",C29/B29) -> - | E29: =COUNTIFS(Rohdaten!J:J,"2027",Rohdaten!K:K,11,Rohdaten!H:H,"Ja") -> 0 | F29: =IF(B29=0,"-",E29/B29) -> - | G29: =IFERROR(AVERAGEIFS(Rohdaten!G:G,Rohdaten!J:J,"2027",Rohdaten!K:K,11,Rohdaten!F:F,"Ja"),"-") -> - | H29: =COUNTIFS(Rohdaten!J:J,"2027",Rohdaten!K:K,11,Rohdaten!G:G,5) -> 0 | I29: =COUNTIFS(Rohdaten!J:J,"2027",Rohdaten!K:K,11,Rohdaten!G:G,4) -> 0 | J29: =COUNTIFS(Rohdaten!J:J,"2027",Rohdaten!K:K,11,Rohdaten!G:G,3) -> 0 | K29: =COUNTIFS(Rohdaten!J:J,"2027",Rohdaten!K:K,11,Rohdaten!G:G,"<3") -> 0 | L29: =IF(C29=0,"-",COUNTIFS(Rohdaten!J:J,"2027",Rohdaten!K:K,11,Rohdaten!#REF!,"Ja")/C29) -> -
A30: 12/2027 | B30: =COUNTIFS(Rohdaten!J:J,"2027",Rohdaten!K:K,12) -> 0 | C30: =COUNTIFS(Rohdaten!J:J,"2027",Rohdaten!K:K,12,Rohdaten!F:F,"Ja") -> 0 | D30: =IF(B30=0,"-",C30/B30) -> - | E30: =COUNTIFS(Rohdaten!J:J,"2027",Rohdaten!K:K,12,Rohdaten!H:H,"Ja") -> 0 | F30: =IF(B30=0,"-",E30/B30) -> - | G30: =IFERROR(AVERAGEIFS(Rohdaten!G:G,Rohdaten!J:J,"2027",Rohdaten!K:K,12,Rohdaten!F:F,"Ja"),"-") -> - | H30: =COUNTIFS(Rohdaten!J:J,"2027",Rohdaten!K:K,12,Rohdaten!G:G,5) -> 0 | I30: =COUNTIFS(Rohdaten!J:J,"2027",Rohdaten!K:K,12,Rohdaten!G:G,4) -> 0 | J30: =COUNTIFS(Rohdaten!J:J,"2027",Rohdaten!K:K,12,Rohdaten!G:G,3) -> 0 | K30: =COUNTIFS(Rohdaten!J:J,"2027",Rohdaten!K:K,12,Rohdaten!G:G,"<3") -> 0 | L30: =IF(C30=0,"-",COUNTIFS(Rohdaten!J:J,"2027",Rohdaten!K:K,12,Rohdaten!#REF!,"Ja")/C30) -> -
A31: GESAMT | B31: =SUM(B4:B30) -> 87 | C31: =SUM(C4:C30) -> 52 | D31: =IF(B31=0,"-",C31/B31) -> 0.59770115 | E31: =SUM(E4:E30) -> 73 | F31: =IF(B31=0,"-",E31/B31) -> 0.83908046 | G31: =IFERROR(AVERAGEIF(Rohdaten!F:F,"Ja",Rohdaten!G:G),"-") -> 4.9622642 | H31: =SUM(H4:H30) -> 52 | I31: =SUM(I4:I30) -> 2 | J31: =SUM(J4:J30) -> 0 | K31: =SUM(K4:K30) -> 0 | L31: =IF(C31=0,"-",COUNTIF(Rohdaten!#REF!,"Ja")/C31) -> #REF!

Sheet Segmentanalyse
A1: SEGMENTANALYSE – automatisch nach Institutionstyp
A3: Institutionstyp | B3: Anzahl Auslieferungen | C3: Google-Bew. erhalten | D3: Google- Quote | E3: Referenzen erhalten | F3: Referenz- Quote | G3: Ø Sterne
A4: Feuerwehr (FFW) | B4: =COUNTIF(Rohdaten!E:E,A4) -> 28 | C4: =COUNTIFS(Rohdaten!E:E,A4,Rohdaten!F:F,"Ja") -> 18 | D4: =IF(B4=0,"-",C4/B4) -> 0.64285714 | E4: =COUNTIFS(Rohdaten!E:E,A4,Rohdaten!H:H,"Ja") -> 22 | F4: =IF(B4=0,"-",E4/B4) -> 0.78571429 | G4: =IFERROR(AVERAGEIFS(Rohdaten!G:G,Rohdaten!E:E,A4,Rohdaten!F:F,"Ja"),"-") -> 4.8888889
A5: Sportverein | B5: =COUNTIF(Rohdaten!E:E,A5) -> 21 | C5: =COUNTIFS(Rohdaten!E:E,A5,Rohdaten!F:F,"Ja") -> 7 | D5: =IF(B5=0,"-",C5/B5) -> 0.33333333 | E5: =COUNTIFS(Rohdaten!E:E,A5,Rohdaten!H:H,"Ja") -> 14 | F5: =IF(B5=0,"-",E5/B5) -> 0.66666667 | G5: =IFERROR(AVERAGEIFS(Rohdaten!G:G,Rohdaten!E:E,A5,Rohdaten!F:F,"Ja"),"-") -> 5
A6: Kulturverein / Theater | B6: =COUNTIF(Rohdaten!E:E,A6) -> 13 | C6: =COUNTIFS(Rohdaten!E:E,A6,Rohdaten!F:F,"Ja") -> 8 | D6: =IF(B6=0,"-",C6/B6) -> 0.61538462 | E6: =COUNTIFS(Rohdaten!E:E,A6,Rohdaten!H:H,"Ja") -> 12 | F6: =IF(B6=0,"-",E6/B6) -> 0.92307692 | G6: =IFERROR(AVERAGEIFS(Rohdaten!G:G,Rohdaten!E:E,A6,Rohdaten!F:F,"Ja"),"-") -> 5
A7: Musikverein | B7: =COUNTIF(Rohdaten!E:E,A7) -> 3 | C7: =COUNTIFS(Rohdaten!E:E,A7,Rohdaten!F:F,"Ja") -> 3 | D7: =IF(B7=0,"-",C7/B7) -> 1 | E7: =COUNTIFS(Rohdaten!E:E,A7,Rohdaten!H:H,"Ja") -> 3 | F7: =IF(B7=0,"-",E7/B7) -> 1 | G7: =IFERROR(AVERAGEIFS(Rohdaten!G:G,Rohdaten!E:E,A7,Rohdaten!F:F,"Ja"),"-") -> 5
A8: Soziale Einrichtung | B8: =COUNTIF(Rohdaten!E:E,A8) -> 9 | C8: =COUNTIFS(Rohdaten!E:E,A8,Rohdaten!F:F,"Ja") -> 6 | D8: =IF(B8=0,"-",C8/B8) -> 0.66666667 | E8: =COUNTIFS(Rohdaten!E:E,A8,Rohdaten!H:H,"Ja") -> 8 | F8: =IF(B8=0,"-",E8/B8) -> 0.88888889 | G8: =IFERROR(AVERAGEIFS(Rohdaten!G:G,Rohdaten!E:E,A8,Rohdaten!F:F,"Ja"),"-") -> 5
A9: THW / Hilfsorganisation | B9: =COUNTIF(Rohdaten!E:E,A9) -> 4 | C9: =COUNTIFS(Rohdaten!E:E,A9,Rohdaten!F:F,"Ja") -> 4 | D9: =IF(B9=0,"-",C9/B9) -> 1 | E9: =COUNTIFS(Rohdaten!E:E,A9,Rohdaten!H:H,"Ja") -> 4 | F9: =IF(B9=0,"-",E9/B9) -> 1 | G9: =IFERROR(AVERAGEIFS(Rohdaten!G:G,Rohdaten!E:E,A9,Rohdaten!F:F,"Ja"),"-") -> 5
A10: Gemeinde / Kommune | B10: =COUNTIF(Rohdaten!E:E,A10) -> 1 | C10: =COUNTIFS(Rohdaten!E:E,A10,Rohdaten!F:F,"Ja") -> 0 | D10: =IF(B10=0,"-",C10/B10) -> 0 | E10: =COUNTIFS(Rohdaten!E:E,A10,Rohdaten!H:H,"Ja") -> 1 | F10: =IF(B10=0,"-",E10/B10) -> 1 | G10: =IFERROR(AVERAGEIFS(Rohdaten!G:G,Rohdaten!E:E,A10,Rohdaten!F:F,"Ja"),"-") -> -
A11: Schule / Kita | B11: =COUNTIF(Rohdaten!E:E,A11) -> 3 | C11: =COUNTIFS(Rohdaten!E:E,A11,Rohdaten!F:F,"Ja") -> 3 | D11: =IF(B11=0,"-",C11/B11) -> 1 | E11: =COUNTIFS(Rohdaten!E:E,A11,Rohdaten!H:H,"Ja") -> 3 | F11: =IF(B11=0,"-",E11/B11) -> 1 | G11: =IFERROR(AVERAGEIFS(Rohdaten!G:G,Rohdaten!E:E,A11,Rohdaten!F:F,"Ja"),"-") -> 5
A12: Sonstige | B12: =COUNTIF(Rohdaten!E:E,A12) -> 6 | C12: =COUNTIFS(Rohdaten!E:E,A12,Rohdaten!F:F,"Ja") -> 4 | D12: =IF(B12=0,"-",C12/B12) -> 0.66666667 | E12: =COUNTIFS(Rohdaten!E:E,A12,Rohdaten!H:H,"Ja") -> 6 | F12: =IF(B12=0,"-",E12/B12) -> 1 | G12: =IFERROR(AVERAGEIFS(Rohdaten!G:G,Rohdaten!E:E,A12,Rohdaten!F:F,"Ja"),"-") -> 5
