Workbook

Sheet Dashboard
B2: Grafikabschluss bis Auslieferung
B4: Jahr: | C4: 2026
B6: Ø Produktionsdauer | C6: Anzahl Projekte | D6: Schnellstes | E6: Längstes
B7: =AVERAGEIFS(Rohdaten!F:F,Rohdaten!G:G,$C$4,Rohdaten!F:F,">0",Rohdaten!F:F,"<=150") -> 70.2 | C7: =COUNTIFS(Rohdaten!G:G,$C$4,Rohdaten!F:F,">0",Rohdaten!F:F,"<=150") -> 55 | D7: =_xlfn.MINIFS(Rohdaten!F:F,Rohdaten!G:G,$C$4,Rohdaten!F:F,">0",Rohdaten!F:F,"<=150") -> 14 | E7: =_xlfn.MAXIFS(Rohdaten!F:F,Rohdaten!G:G,$C$4,Rohdaten!F:F,">0",Rohdaten!F:F,"<=150") -> 142
B8: Tage | C8: Projekte | D8: Tage | E8: Tage
B10: Ø Dauer nach Produkttyp
B11: Produkt | C11: Anzahl | D11: Ø Tage | E11: Min | F11: Max
B12: Torzähler "Plus" 5 Jahre | C12: =COUNTIFS(Rohdaten!G:G,$C$4,Rohdaten!C:C,"Torzähler ""Plus"" 5 Jahre",Rohdaten!F:F,">0",Rohdaten!F:F,"<=150") -> 8 | D12: =IF(COUNTIFS(Rohdaten!G:G,$C$4,Rohdaten!C:C,"Torzähler ""Plus"" 5 Jahre",Rohdaten!F:F,">0",Rohdaten!F:F,"<=150")>0,AVERAGEIFS(Rohdaten!F:F,Rohdaten!G:G,$C$4,Rohdaten!C:C,"Torzähler ""Plus"" 5 Jahre",Rohdaten!F:F,">0",Rohdaten!F:F,"<=150"),"-") -> 79.75 | E12: =IF(COUNTIFS(Rohdaten!G:G,$C$4,Rohdaten!C:C,"Torzähler ""Plus"" 5 Jahre",Rohdaten!F:F,">0",Rohdaten!F:F,"<=150")>0,_xlfn.MINIFS(Rohdaten!F:F,Rohdaten!G:G,$C$4,Rohdaten!C:C,"Torzähler ""Plus"" 5 Jahre",Rohdaten!F:F,">0",Rohdaten!F:F,"<=150"),"-") -> 25 | F12: =IF(COUNTIFS(Rohdaten!G:G,$C$4,Rohdaten!C:C,"Torzähler ""Plus"" 5 Jahre",Rohdaten!F:F,">0",Rohdaten!F:F,"<=150")>0,_xlfn.MAXIFS(Rohdaten!F:F,Rohdaten!G:G,$C$4,Rohdaten!C:C,"Torzähler ""Plus"" 5 Jahre",Rohdaten!F:F,">0",Rohdaten!F:F,"<=150"),"-") -> 126
B13: Fahrzeug | C13: =COUNTIFS(Rohdaten!G:G,$C$4,Rohdaten!C:C,"Fahrzeug",Rohdaten!F:F,">0",Rohdaten!F:F,"<=150") -> 18 | D13: =IF(COUNTIFS(Rohdaten!G:G,$C$4,Rohdaten!C:C,"Fahrzeug",Rohdaten!F:F,">0",Rohdaten!F:F,"<=150")>0,AVERAGEIFS(Rohdaten!F:F,Rohdaten!G:G,$C$4,Rohdaten!C:C,"Fahrzeug",Rohdaten!F:F,">0",Rohdaten!F:F,"<=150"),"-") -> 66.833333 | E13: =IF(COUNTIFS(Rohdaten!G:G,$C$4,Rohdaten!C:C,"Fahrzeug",Rohdaten!F:F,">0",Rohdaten!F:F,"<=150")>0,_xlfn.MINIFS(Rohdaten!F:F,Rohdaten!G:G,$C$4,Rohdaten!C:C,"Fahrzeug",Rohdaten!F:F,">0",Rohdaten!F:F,"<=150"),"-") -> 16 | F13: =IF(COUNTIFS(Rohdaten!G:G,$C$4,Rohdaten!C:C,"Fahrzeug",Rohdaten!F:F,">0",Rohdaten!F:F,"<=150")>0,_xlfn.MAXIFS(Rohdaten!F:F,Rohdaten!G:G,$C$4,Rohdaten!C:C,"Fahrzeug",Rohdaten!F:F,">0",Rohdaten!F:F,"<=150"),"-") -> 142
B14: Kühlanhänger | C14: =COUNTIFS(Rohdaten!G:G,$C$4,Rohdaten!C:C,"Kühlanhänger",Rohdaten!F:F,">0",Rohdaten!F:F,"<=150") -> 14 | D14: =IF(COUNTIFS(Rohdaten!G:G,$C$4,Rohdaten!C:C,"Kühlanhänger",Rohdaten!F:F,">0",Rohdaten!F:F,"<=150")>0,AVERAGEIFS(Rohdaten!F:F,Rohdaten!G:G,$C$4,Rohdaten!C:C,"Kühlanhänger",Rohdaten!F:F,">0",Rohdaten!F:F,"<=150"),"-") -> 77 | E14: =IF(COUNTIFS(Rohdaten!G:G,$C$4,Rohdaten!C:C,"Kühlanhänger",Rohdaten!F:F,">0",Rohdaten!F:F,"<=150")>0,_xlfn.MINIFS(Rohdaten!F:F,Rohdaten!G:G,$C$4,Rohdaten!C:C,"Kühlanhänger",Rohdaten!F:F,">0",Rohdaten!F:F,"<=150"),"-") -> 14 | F14: =IF(COUNTIFS(Rohdaten!G:G,$C$4,Rohdaten!C:C,"Kühlanhänger",Rohdaten!F:F,">0",Rohdaten!F:F,"<=150")>0,_xlfn.MAXIFS(Rohdaten!F:F,Rohdaten!G:G,$C$4,Rohdaten!C:C,"Kühlanhänger",Rohdaten!F:F,">0",Rohdaten!F:F,"<=150"),"-") -> 141
B15: Torzähler Mobil | C15: =COUNTIFS(Rohdaten!G:G,$C$4,Rohdaten!C:C,"Torzähler Mobil",Rohdaten!F:F,">0",Rohdaten!F:F,"<=150") -> 4 | D15: =IF(COUNTIFS(Rohdaten!G:G,$C$4,Rohdaten!C:C,"Torzähler Mobil",Rohdaten!F:F,">0",Rohdaten!F:F,"<=150")>0,AVERAGEIFS(Rohdaten!F:F,Rohdaten!G:G,$C$4,Rohdaten!C:C,"Torzähler Mobil",Rohdaten!F:F,">0",Rohdaten!F:F,"<=150"),"-") -> 40.75 | E15: =IF(COUNTIFS(Rohdaten!G:G,$C$4,Rohdaten!C:C,"Torzähler Mobil",Rohdaten!F:F,">0",Rohdaten!F:F,"<=150")>0,_xlfn.MINIFS(Rohdaten!F:F,Rohdaten!G:G,$C$4,Rohdaten!C:C,"Torzähler Mobil",Rohdaten!F:F,">0",Rohdaten!F:F,"<=150"),"-") -> 16 | F15: =IF(COUNTIFS(Rohdaten!G:G,$C$4,Rohdaten!C:C,"Torzähler Mobil",Rohdaten!F:F,">0",Rohdaten!F:F,"<=150")>0,_xlfn.MAXIFS(Rohdaten!F:F,Rohdaten!G:G,$C$4,Rohdaten!C:C,"Torzähler Mobil",Rohdaten!F:F,">0",Rohdaten!F:F,"<=150"),"-") -> 87
B16: Eventanhänger | C16: =COUNTIFS(Rohdaten!G:G,$C$4,Rohdaten!C:C,"Eventanhänger",Rohdaten!F:F,">0",Rohdaten!F:F,"<=150") -> 6 | D16: =IF(COUNTIFS(Rohdaten!G:G,$C$4,Rohdaten!C:C,"Eventanhänger",Rohdaten!F:F,">0",Rohdaten!F:F,"<=150")>0,AVERAGEIFS(Rohdaten!F:F,Rohdaten!G:G,$C$4,Rohdaten!C:C,"Eventanhänger",Rohdaten!F:F,">0",Rohdaten!F:F,"<=150"),"-") -> 82.333333 | E16: =IF(COUNTIFS(Rohdaten!G:G,$C$4,Rohdaten!C:C,"Eventanhänger",Rohdaten!F:F,">0",Rohdaten!F:F,"<=150")>0,_xlfn.MINIFS(Rohdaten!F:F,Rohdaten!G:G,$C$4,Rohdaten!C:C,"Eventanhänger",Rohdaten!F:F,">0",Rohdaten!F:F,"<=150"),"-") -> 34 | F16: =IF(COUNTIFS(Rohdaten!G:G,$C$4,Rohdaten!C:C,"Eventanhänger",Rohdaten!F:F,">0",Rohdaten!F:F,"<=150")>0,_xlfn.MAXIFS(Rohdaten!F:F,Rohdaten!G:G,$C$4,Rohdaten!C:C,"Eventanhänger",Rohdaten!F:F,">0",Rohdaten!F:F,"<=150"),"-") -> 108
B17: Altfahrzeug Neu Beworben | C17: =COUNTIFS(Rohdaten!G:G,$C$4,Rohdaten!C:C,"Altfahrzeug Neu Beworben",Rohdaten!F:F,">0",Rohdaten!F:F,"<=150") -> 3 | D17: =IF(COUNTIFS(Rohdaten!G:G,$C$4,Rohdaten!C:C,"Altfahrzeug Neu Beworben",Rohdaten!F:F,">0",Rohdaten!F:F,"<=150")>0,AVERAGEIFS(Rohdaten!F:F,Rohdaten!G:G,$C$4,Rohdaten!C:C,"Altfahrzeug Neu Beworben",Rohdaten!F:F,">0",Rohdaten!F:F,"<=150"),"-") -> 30.666667 | E17: =IF(COUNTIFS(Rohdaten!G:G,$C$4,Rohdaten!C:C,"Altfahrzeug Neu Beworben",Rohdaten!F:F,">0",Rohdaten!F:F,"<=150")>0,_xlfn.MINIFS(Rohdaten!F:F,Rohdaten!G:G,$C$4,Rohdaten!C:C,"Altfahrzeug Neu Beworben",Rohdaten!F:F,">0",Rohdaten!F:F,"<=150"),"-") -> 21 | F17: =IF(COUNTIFS(Rohdaten!G:G,$C$4,Rohdaten!C:C,"Altfahrzeug Neu Beworben",Rohdaten!F:F,">0",Rohdaten!F:F,"<=150")>0,_xlfn.MAXIFS(Rohdaten!F:F,Rohdaten!G:G,$C$4,Rohdaten!C:C,"Altfahrzeug Neu Beworben",Rohdaten!F:F,">0",Rohdaten!F:F,"<=150"),"-") -> 47
B20: Monatlicher Trend
B21: Monat | C21: Anzahl | D21: Ø Tage
B22: Januar | C22: =COUNTIFS(Rohdaten!G:G,$C$4,Rohdaten!I:I,1,Rohdaten!F:F,">0",Rohdaten!F:F,"<=150") -> 1 | D22: =IFERROR(AVERAGEIFS(Rohdaten!F:F,Rohdaten!G:G,$C$4,Rohdaten!I:I,1,Rohdaten!F:F,">0",Rohdaten!F:F,"<=150"),"-") -> 97
B23: Februar | C23: =COUNTIFS(Rohdaten!G:G,$C$4,Rohdaten!I:I,2,Rohdaten!F:F,">0",Rohdaten!F:F,"<=150") -> 16 | D23: =IFERROR(AVERAGEIFS(Rohdaten!F:F,Rohdaten!G:G,$C$4,Rohdaten!I:I,2,Rohdaten!F:F,">0",Rohdaten!F:F,"<=150"),"-") -> 84
B24: März | C24: =COUNTIFS(Rohdaten!G:G,$C$4,Rohdaten!I:I,3,Rohdaten!F:F,">0",Rohdaten!F:F,"<=150") -> 22 | D24: =IFERROR(AVERAGEIFS(Rohdaten!F:F,Rohdaten!G:G,$C$4,Rohdaten!I:I,3,Rohdaten!F:F,">0",Rohdaten!F:F,"<=150"),"-") -> 71.136364
B25: April | C25: =COUNTIFS(Rohdaten!G:G,$C$4,Rohdaten!I:I,4,Rohdaten!F:F,">0",Rohdaten!F:F,"<=150") -> 16 | D25: =IFERROR(AVERAGEIFS(Rohdaten!F:F,Rohdaten!G:G,$C$4,Rohdaten!I:I,4,Rohdaten!F:F,">0",Rohdaten!F:F,"<=150"),"-") -> 53.4375
B26: Mai | C26: =COUNTIFS(Rohdaten!G:G,$C$4,Rohdaten!I:I,5,Rohdaten!F:F,">0",Rohdaten!F:F,"<=150") -> 0 | D26: =IFERROR(AVERAGEIFS(Rohdaten!F:F,Rohdaten!G:G,$C$4,Rohdaten!I:I,5,Rohdaten!F:F,">0",Rohdaten!F:F,"<=150"),"-") -> -
B27: Juni | C27: =COUNTIFS(Rohdaten!G:G,$C$4,Rohdaten!I:I,6,Rohdaten!F:F,">0",Rohdaten!F:F,"<=150") -> 0 | D27: =IFERROR(AVERAGEIFS(Rohdaten!F:F,Rohdaten!G:G,$C$4,Rohdaten!I:I,6,Rohdaten!F:F,">0",Rohdaten!F:F,"<=150"),"-") -> -
B28: Juli | C28: =COUNTIFS(Rohdaten!G:G,$C$4,Rohdaten!I:I,7,Rohdaten!F:F,">0",Rohdaten!F:F,"<=150") -> 0 | D28: =IFERROR(AVERAGEIFS(Rohdaten!F:F,Rohdaten!G:G,$C$4,Rohdaten!I:I,7,Rohdaten!F:F,">0",Rohdaten!F:F,"<=150"),"-") -> -
B29: August | C29: =COUNTIFS(Rohdaten!G:G,$C$4,Rohdaten!I:I,8,Rohdaten!F:F,">0",Rohdaten!F:F,"<=150") -> 0 | D29: =IFERROR(AVERAGEIFS(Rohdaten!F:F,Rohdaten!G:G,$C$4,Rohdaten!I:I,8,Rohdaten!F:F,">0",Rohdaten!F:F,"<=150"),"-") -> -
B30: September | C30: =COUNTIFS(Rohdaten!G:G,$C$4,Rohdaten!I:I,9,Rohdaten!F:F,">0",Rohdaten!F:F,"<=150") -> 0 | D30: =IFERROR(AVERAGEIFS(Rohdaten!F:F,Rohdaten!G:G,$C$4,Rohdaten!I:I,9,Rohdaten!F:F,">0",Rohdaten!F:F,"<=150"),"-") -> -
B31: Oktober | C31: =COUNTIFS(Rohdaten!G:G,$C$4,Rohdaten!I:I,10,Rohdaten!F:F,">0",Rohdaten!F:F,"<=150") -> 0 | D31: =IFERROR(AVERAGEIFS(Rohdaten!F:F,Rohdaten!G:G,$C$4,Rohdaten!I:I,10,Rohdaten!F:F,">0",Rohdaten!F:F,"<=150"),"-") -> -
B32: November | C32: =COUNTIFS(Rohdaten!G:G,$C$4,Rohdaten!I:I,11,Rohdaten!F:F,">0",Rohdaten!F:F,"<=150") -> 0 | D32: =IFERROR(AVERAGEIFS(Rohdaten!F:F,Rohdaten!G:G,$C$4,Rohdaten!I:I,11,Rohdaten!F:F,">0",Rohdaten!F:F,"<=150"),"-") -> -
B33: Dezember | C33: =COUNTIFS(Rohdaten!G:G,$C$4,Rohdaten!I:I,12,Rohdaten!F:F,">0",Rohdaten!F:F,"<=150") -> 0 | D33: =IFERROR(AVERAGEIFS(Rohdaten!F:F,Rohdaten!G:G,$C$4,Rohdaten!I:I,12,Rohdaten!F:F,">0",Rohdaten!F:F,"<=150"),"-") -> -

Sheet Rohdaten
A1: Projektnummer | B1: Projektname | C1: Produkt | D1: Grafikabschluss | E1: Auslieferungsdatum | F1: Produktionsdauer (Tage) | G1: Auslieferungsjahr | H1: Quartal | I1: Monat (Nr.)
A2: 2402052510 | B2: akademie für darstellende kunst | C2: Fahrzeug | D2: 46057 | E2: 46084 | F2: =E2-D2 -> 27 | G2: 2026 | H2: Q1 2026 | I2: 3
A3: 2402052504 | B3: Graf von Galen Schule - Heidelberg | C3: Fahrzeug | D3: 45985 | E3: 46085 | F3: =E3-D3 -> 100 | G3: 2026 | H3: Q1 2026 | I3: 3
A4: 2407052686 | B4: Theater Gruene Sosse | C4: Fahrzeug | D4: 46013 | E4: 46086 | F4: =E4-D4 -> 73 | G4: 2026 | H4: Q1 2026 | I4: 3
A5: 2202051897 | B5: Freie Waldorfschule Vordertaunus e. V. | C5: Eventanhänger | D5: 46042 | E5: 46087 | F5: =E5-D5 -> 45 | G5: 2026 | H5: Q1 2026 | I5: 3
A6: 2502052818 | B6: Schützenverein Owingen 1921 e.V. | C6: Eventanhänger | D6: 46057 | E6: 46091 | F6: =E6-D6 -> 34 | G6: 2026 | H6: Q1 2026 | I6: 3
A7: 2502052815 | B7: Anderssein e.V. | C7: Fahrzeug | D7: 46065 | E7: 46092 | F7: =E7-D7 -> 27 | G7: 2026 | H7: Q1 2026 | I7: 3
A8: 2407052675 | B8: Oppumer Verein für notleidende Pferde | C8: Fahrzeug | D8: 45950 | E8: 46092 | F8: =E8-D8 -> 142 | G8: 2026 | H8: Q1 2026 | I8: 3
A9: 2407052688 | B9: Mainzer Kinder- und Jugendtheater e.V. | C9: Fahrzeug | D9: 46048 | E9: 46098 | F9: =E9-D9 -> 50 | G9: 2026 | H9: Q1 2026 | I9: 3
A10: 2507052961 | B10: Freiwillige Feuerwehr Ottmaring e.V | C10: Hochwasseranhänger | D10: 45966 | E10: 46100 | F10: =E10-D10 -> 134 | G10: 2026 | H10: Q1 2026 | I10: 3
A11: 2507052954 | B11: AWO Betreuungsverein Altenkirchen e.V. | C11: Fahrzeug | D11: 46070 | E11: 46100 | F11: =E11-D11 -> 30 | G11: 2026 | H11: Q1 2026 | I11: 3
A12: 2504052871 | B12: Freiwillige Feuerwehr Waldorfhäslach | C12: Kühlanhänger | D12: 46000 | E12: 46100 | F12: =E12-D12 -> 100 | G12: 2026 | H12: Q1 2026 | I12: 3
A13: 2301052183 | B13: StadtTheater Bruneck | C13: Altfahrzeug Neu Beworben | D13: 46053 | E13: 46100 | F13: =E13-D13 -> 47 | G13: 2026 | H13: Q1 2026 | I13: 3
... A23: 2505052915 | B23: Stadtjugendfeuerwehr Hessisch Oldendorf | C23: Kühlanhänger | D23: 46072 | E23: 46122 | F23: =E23-D23 -> 50 | G23: 2026 | H23: Q2 2026 | I23: 4
A24: 2503052855 | B24: Kleines Theater Bad Godesberg e.V. | C24: Fahrzeug | D24: 45972 | E24: 46070 | F24: =E24-D24 -> 98 | G24: 2026 | H24: ="Q"&INT((MONTH(E2)-1)/3)+1&" "&YEAR(E2) -> Q1 2026 | I24: 2
A25: 2406052661 | B25: WSV Unterammergau 1924 | C25: Torzähler "Plus" 5 Jahre | D25: 45875 | E25: 46066 | F25: =E25-D25 -> 191 | G25: 2026 | H25: ="Q"&INT((MONTH(E3)-1)/3)+1&" "&YEAR(E3) -> Q1 2026 | I25: 2
A26: 2409052706 | B26: Florianskameradschaft Sauggart e.V. | C26: Eventanhänger | D26: 45961 | E26: 46066 | F26: =E26-D26 -> 105 | G26: 2026 | H26: ="Q"&INT((MONTH(E4)-1)/3)+1&" "&YEAR(E4) -> Q1 2026 | I26: 2
A27: 2502052826 | B27: THW Helfervereinigung Lüneburg e.V. | C27: Fahrzeug | D27: 45992 | E27: 46064 | F27: =E27-D27 -> 72 | G27: 2026 | H27: ="Q"&INT((MONTH(E5)-1)/3)+1&" "&YEAR(E5) -> Q1 2026 | I27: 2
A28: 2501052799 | B28: TSG Stadtbergen 1892 | C28: Torzähler "Plus" 5 Jahre | D28: 45905 | E28: 46064 | F28: =E28-D28 -> 159 | G28: 2026 | H28: ="Q"&INT((MONTH(E6)-1)/3)+1&" "&YEAR(E6) -> Q1 2026 | I28: 2
A29: 2405052628 | B29: SSV Neumünster-Unterschöneberg e.V. | C29: Torzähler "Plus" 5 Jahre | D29: 46008 | E29: 46064 | F29: =E29-D29 -> 56 | G29: 2026 | H29: ="Q"&INT((MONTH(E7)-1)/3)+1&" "&YEAR(E7) -> Q1 2026 | I29: 2
A30: 2503052854 | B30: Stadtkapelle/Spielmannszug Pfaffenhofen | C30: Kühlanhänger | D30: 45985 | E30: 46062 | F30: =E30-D30 -> 77 | G30: 2026 | H30: ="Q"&INT((MONTH(E8)-1)/3)+1&" "&YEAR(E8) -> Q1 2026 | I30: 2
A31: 2311052463 | B31: Theater im Palais -Erfurt | C31: Fahrzeug | D31: 45987 | E31: 46058 | F31: =E31-D31 -> 71 | G31: 2026 | H31: ="Q"&INT((MONTH(E9)-1)/3)+1&" "&YEAR(E9) -> Q1 2026 | I31: 2
A32: 2311052463 | B32: Theater im Palais e. V. | C32: Fahrzeug | D32: 45987 | E32: 46058 | F32: =E32-D32 -> 71 | G32: 2026 | H32: ="Q"&INT((MONTH(E10)-1)/3)+1&" "&YEAR(E10) -> Q1 2026 | I32: 2
A33: 2402052527 | B33: Haus Aichele -Beuren | C33: Fahrzeug | D33: 45981 | E33: 46057 | F33: =E33-D33 -> 76 | G33: 2026 | H33: ="Q"&INT((MONTH(E11)-1)/3)+1&" "&YEAR(E11) -> Q1 2026 | I33: 2
A34: 2402052527 | B34: Haus Aichele | C34: Fahrzeug | D34: 45981 | E34: 46057 | F34: =E34-D34 -> 76 | G34: 2026 | H34: ="Q"&INT((MONTH(E12)-1)/3)+1&" "&YEAR(E12) -> Q1 2026 | I34: 2
A35: 2407052681 | B35: Musikverein Bad Cannstatt e.V. - Stuttgart | C35: Eventanhänger | D35: 45954 | E35: 46055 | F35: =E35-D35 -> 101 | G35: 2026 | H35: ="Q"&INT((MONTH(E13)-1)/3)+1&" "&YEAR(E13) -> Q1 2026 | I35: 2
... A86: 2402052503 | B86: Freiwillige Feuerwehr Schneeberg | C86: Kühlanhänger | D86: 45818 | E86: 45940 | F86: =E86-D86 -> 122 | G86: 2025 | H86: ="Q"&INT((MONTH(E64)-1)/3)+1&" "&YEAR(E64) -> Q4 2025 | I86: 10
A87: 2404052592 | B87: SV Hörmannsdorf e.V. | C87: Torzähler "Plus" 5 Jahre | D87: 45940 | E87: 46092 | F87: =E87-D87 -> 152 | G87: 2026 | H87: Q1 2026 | I87: 3
A88: 2502052827 | B88: TSV 1905 Biberach e. V. | C88: Torzähler Mobil | D88: 45797 | E88: 45940 | F88: =E88-D88 -> 143 | G88: 2025 | H88: ="Q"&INT((MONTH(E66)-1)/3)+1&" "&YEAR(E66) -> Q4 2025 | I88: 10
A89: 2309052386 | B89: FC Herdecke-Ende e.V. | C89: Torzähler "Plus" 5 Jahre | D89: 45924 | E89: 45939 | F89: =E89-D89 -> 15 | G89: 2025 | H89: ="Q"&INT((MONTH(E67)-1)/3)+1&" "&YEAR(E67) -> Q4 2025 | I89: 10
A90: 2402052538 | B90: TuS Heven 09 | C90: Torzähler "Plus" 5 Jahre | D90: 45883 | E90: 45939 | F90: =E90-D90 -> 56 | G90: 2025 | H90: ="Q"&INT((MONTH(E68)-1)/3)+1&" "&YEAR(E68) -> Q4 2025 | I90: 10
A91: 2211052114 | B91: PIT, Freudenstadt | C91: Fahrzeug | D91: 45910 | E91: 45932 | F91: =E91-D91 -> 22 | G91: 2025 | H91: ="Q"&INT((MONTH(E69)-1)/3)+1&" "&YEAR(E69) -> Q4 2025 | I91: 10
A92: 2502052809 | B92: SV Lichtenau Weilheim e.V. | C92: Torzähler "Plus" 5 Jahre | D92: 45891 | E92: 45931 | F92: =E92-D92 -> 40 | G92: 2025 | H92: ="Q"&INT((MONTH(E70)-1)/3)+1&" "&YEAR(E70) -> Q4 2025 | I92: 10
A93: 2405052638 | B93: 1. FC Stern Mögglingen | C93: Torzähler "Plus" 5 Jahre | D93: 45873 | E93: 45931 | F93: =E93-D93 -> 58 | G93: 2025 | H93: ="Q"&INT((MONTH(E71)-1)/3)+1&" "&YEAR(E71) -> Q4 2025 | I93: 10
A94: 2404052621 | B94: Förderverein des TH, Neu-Ulm | C94: Kühlanhänger | D94: 45888 | E94: 45930 | F94: =E94-D94 -> 42 | G94: 2025 | H94: ="Q"&INT((MONTH(E72)-1)/3)+1&" "&YEAR(E72) -> Q4 2025 | I94: 9
A95: 2502052832 | B95: FV Rammersweier | C95: Torzähler "Plus" 5 Jahre | D95: 45888 | E95: 45929 | F95: =E95-D95 -> 41 | G95: 2025 | H95: ="Q"&INT((MONTH(E73)-1)/3)+1&" "&YEAR(E73) -> Q4 2025 | I95: 9
A96: 2408052695 | B96: Feuerwehrverein Oßweil e.V | C96: Kühlanhänger | D96: 45813 | E96: 45924 | F96: =E96-D96 -> 111 | G96: 2025 | H96: ="Q"&INT((MONTH(E74)-1)/3)+1&" "&YEAR(E74) -> Q4 2025 | I96: 9
A97: 1912051517 | B97: Stadt Overath | C97: Fahrzeug | D97: 45742 | E97: 45923 | F97: =E97-D97 -> 181 | G97: 2025 | H97: ="Q"&INT((MONTH(E75)-1)/3)+1&" "&YEAR(E75) -> Q4 2025 | I97: 9
A98: 2501052801 | B98: SV Friedrichsort von 1890 e.V. | C98: Torzähler "Plus" 5 Jahre | D98: 45790 | E98: 45921 | F98: =E98-D98 -> 131 | G98: 2025 | H98: ="Q"&INT((MONTH(E76)-1)/3)+1&" "&YEAR(E76) -> Q4 2025 | I98: 9
A99: 2403052567 | B99: DLRG Ortsgruppe Aalen | C99: Kühlanhänger | D99: 45842 | E99: 45919 | F99: =E99-D99 -> 77 | G99: 2025 | H99: ="Q"&INT((MONTH(E77)-1)/3)+1&" "&YEAR(E77) -> Q4 2025 | I99: 9
...

Sheet Auswertung
A1: Produktliste | B1: Anzahl Projekte | C1: Ø Dauer (Tage) | D1: Min (Tage) | E1: Max (Tage)
A2: Altfahrzeug Neu Beworben | B2: =COUNTIF(Rohdaten!C2:C500,A2) -> 7 | C2: =IFERROR(AVERAGEIF(Rohdaten!C2:C500,A2,Rohdaten!F2:F500),"-") -> 41 | D2: =IFERROR(_xlfn.MINIFS(Rohdaten!F2:F500,Rohdaten!C2:C500,A2),"-") -> 21 | E2: =IFERROR(_xlfn.MAXIFS(Rohdaten!F2:F500,Rohdaten!C2:C500,A2),"-") -> 56
A3: Eventanhänger | B3: =COUNTIF(Rohdaten!C2:C500,A3) -> 10 | C3: =IFERROR(AVERAGEIF(Rohdaten!C2:C500,A3,Rohdaten!F2:F500),"-") -> 73 | D3: =IFERROR(_xlfn.MINIFS(Rohdaten!F2:F500,Rohdaten!C2:C500,A3),"-") -> 15 | E3: =IFERROR(_xlfn.MAXIFS(Rohdaten!F2:F500,Rohdaten!C2:C500,A3),"-") -> 111
A4: Fahrzeug | B4: =COUNTIF(Rohdaten!C2:C500,A4) -> 63 | C4: =IFERROR(AVERAGEIF(Rohdaten!C2:C500,A4,Rohdaten!F2:F500),"-") -> 90.142857 | D4: =IFERROR(_xlfn.MINIFS(Rohdaten!F2:F500,Rohdaten!C2:C500,A4),"-") -> 16 | E4: =IFERROR(_xlfn.MAXIFS(Rohdaten!F2:F500,Rohdaten!C2:C500,A4),"-") -> 266
A5: Hyundai i10 | B5: =COUNTIF(Rohdaten!C2:C500,A5) -> 0 | C5: =IFERROR(AVERAGEIF(Rohdaten!C2:C500,A5,Rohdaten!F2:F500),"-") -> - | D5: =IFERROR(_xlfn.MINIFS(Rohdaten!F2:F500,Rohdaten!C2:C500,A5),"-") -> 0 | E5: =IFERROR(_xlfn.MAXIFS(Rohdaten!F2:F500,Rohdaten!C2:C500,A5),"-") -> 0
A6: Kühlanhänger | B6: =COUNTIF(Rohdaten!C2:C500,A6) -> 51 | C6: =IFERROR(AVERAGEIF(Rohdaten!C2:C500,A6,Rohdaten!F2:F500),"-") -> 79.784314 | D6: =IFERROR(_xlfn.MINIFS(Rohdaten!F2:F500,Rohdaten!C2:C500,A6),"-") -> 14 | E6: =IFERROR(_xlfn.MAXIFS(Rohdaten!F2:F500,Rohdaten!C2:C500,A6),"-") -> 181
A7: Spielanhänger | B7: =COUNTIF(Rohdaten!C2:C500,A7) -> 2 | C7: =IFERROR(AVERAGEIF(Rohdaten!C2:C500,A7,Rohdaten!F2:F500),"-") -> 99 | D7: =IFERROR(_xlfn.MINIFS(Rohdaten!F2:F500,Rohdaten!C2:C500,A7),"-") -> 59 | E7: =IFERROR(_xlfn.MAXIFS(Rohdaten!F2:F500,Rohdaten!C2:C500,A7),"-") -> 139
A8: Torzähler "Plus" 5 Jahre | B8: =COUNTIF(Rohdaten!C2:C500,A8) -> 65 | C8: =IFERROR(AVERAGEIF(Rohdaten!C2:C500,A8,Rohdaten!F2:F500),"-") -> 82.646154 | D8: =IFERROR(_xlfn.MINIFS(Rohdaten!F2:F500,Rohdaten!C2:C500,A8),"-") -> 14 | E8: =IFERROR(_xlfn.MAXIFS(Rohdaten!F2:F500,Rohdaten!C2:C500,A8),"-") -> 334
A9: Torzähler Mobil 10 Flächen | B9: =COUNTIF(Rohdaten!C2:C500,A9) -> 0 | C9: =IFERROR(AVERAGEIF(Rohdaten!C2:C500,A9,Rohdaten!F2:F500),"-") -> - | D9: =IFERROR(_xlfn.MINIFS(Rohdaten!F2:F500,Rohdaten!C2:C500,A9),"-") -> 0 | E9: =IFERROR(_xlfn.MAXIFS(Rohdaten!F2:F500,Rohdaten!C2:C500,A9),"-") -> 0
A10: Torzähler Mobil 8 Flächen | B10: =COUNTIF(Rohdaten!C2:C500,A10) -> 0 | C10: =IFERROR(AVERAGEIF(Rohdaten!C2:C500,A10,Rohdaten!F2:F500),"-") -> - | D10: =IFERROR(_xlfn.MINIFS(Rohdaten!F2:F500,Rohdaten!C2:C500,A10),"-") -> 0 | E10: =IFERROR(_xlfn.MAXIFS(Rohdaten!F2:F500,Rohdaten!C2:C500,A10),"-") -> 0
A11: Torzähler Premium | B11: =COUNTIF(Rohdaten!C2:C500,A11) -> 1 | C11: =IFERROR(AVERAGEIF(Rohdaten!C2:C500,A11,Rohdaten!F2:F500),"-") -> 338 | D11: =IFERROR(_xlfn.MINIFS(Rohdaten!F2:F500,Rohdaten!C2:C500,A11),"-") -> 338 | E11: =IFERROR(_xlfn.MAXIFS(Rohdaten!F2:F500,Rohdaten!C2:C500,A11),"-") -> 338
A14: Jahresliste
A15: 2025
A16: 2026
A19: Ø Dauer nach Produkt und Jahr | B19: 2025 Ø Tage | C19: 2025 Anzahl | D19: 2026 Ø Tage | E19: 2026 Anzahl
A20: Altfahrzeug Neu Beworben | B20: =IFERROR(AVERAGEIFS(Rohdaten!F2:F500,Rohdaten!C2:C500,A20,Rohdaten!G2:G500,2025),"-") -> 53.333333 | C20: =COUNTIFS(Rohdaten!C2:C500,A20,Rohdaten!G2:G500,2025) -> 3 | D20: =IFERROR(AVERAGEIFS(Rohdaten!F2:F500,Rohdaten!C2:C500,A20,Rohdaten!G2:G500,2026),"-") -> 30.666667 | E20: =COUNTIFS(Rohdaten!C2:C500,A20,Rohdaten!G2:G500,2026) -> 3
A21: Eventanhänger | B21: =IFERROR(AVERAGEIFS(Rohdaten!F2:F500,Rohdaten!C2:C500,A21,Rohdaten!G2:G500,2025),"-") -> 91.5 | C21: =COUNTIFS(Rohdaten!C2:C500,A21,Rohdaten!G2:G500,2025) -> 2 | D21: =IFERROR(AVERAGEIFS(Rohdaten!F2:F500,Rohdaten!C2:C500,A21,Rohdaten!G2:G500,2026),"-") -> 82.333333 | E21: =COUNTIFS(Rohdaten!C2:C500,A21,Rohdaten!G2:G500,2026) -> 6
A22: Fahrzeug | B22: =IFERROR(AVERAGEIFS(Rohdaten!F2:F500,Rohdaten!C2:C500,A22,Rohdaten!G2:G500,2025),"-") -> 102.95122 | C22: =COUNTIFS(Rohdaten!C2:C500,A22,Rohdaten!G2:G500,2025) -> 41 | D22: =IFERROR(AVERAGEIFS(Rohdaten!F2:F500,Rohdaten!C2:C500,A22,Rohdaten!G2:G500,2026),"-") -> 66.833333 | E22: =COUNTIFS(Rohdaten!C2:C500,A22,Rohdaten!G2:G500,2026) -> 18
A23: Hyundai i10 | B23: =IFERROR(AVERAGEIFS(Rohdaten!F2:F500,Rohdaten!C2:C500,A23,Rohdaten!G2:G500,2025),"-") -> - | C23: =COUNTIFS(Rohdaten!C2:C500,A23,Rohdaten!G2:G500,2025) -> 0 | D23: =IFERROR(AVERAGEIFS(Rohdaten!F2:F500,Rohdaten!C2:C500,A23,Rohdaten!G2:G500,2026),"-") -> - | E23: =COUNTIFS(Rohdaten!C2:C500,A23,Rohdaten!G2:G500,2026) -> 0
A24: Kühlanhänger | B24: =IFERROR(AVERAGEIFS(Rohdaten!F2:F500,Rohdaten!C2:C500,A24,Rohdaten!G2:G500,2025),"-") -> 84.24 | C24: =COUNTIFS(Rohdaten!C2:C500,A24,Rohdaten!G2:G500,2025) -> 25 | D24: =IFERROR(AVERAGEIFS(Rohdaten!F2:F500,Rohdaten!C2:C500,A24,Rohdaten!G2:G500,2026),"-") -> 77 | E24: =COUNTIFS(Rohdaten!C2:C500,A24,Rohdaten!G2:G500,2026) -> 14
A25: Spielanhänger | B25: =IFERROR(AVERAGEIFS(Rohdaten!F2:F500,Rohdaten!C2:C500,A25,Rohdaten!G2:G500,2025),"-") -> 139 | C25: =COUNTIFS(Rohdaten!C2:C500,A25,Rohdaten!G2:G500,2025) -> 1 | D25: =IFERROR(AVERAGEIFS(Rohdaten!F2:F500,Rohdaten!C2:C500,A25,Rohdaten!G2:G500,2026),"-") -> 59 | E25: =COUNTIFS(Rohdaten!C2:C500,A25,Rohdaten!G2:G500,2026) -> 1
A26: Torzähler "Plus" 5 Jahre | B26: =IFERROR(AVERAGEIFS(Rohdaten!F2:F500,Rohdaten!C2:C500,A26,Rohdaten!G2:G500,2025),"-") -> 69.470588 | C26: =COUNTIFS(Rohdaten!C2:C500,A26,Rohdaten!G2:G500,2025) -> 51 | D26: =IFERROR(AVERAGEIFS(Rohdaten!F2:F500,Rohdaten!C2:C500,A26,Rohdaten!G2:G500,2026),"-") -> 130.64286 | E26: =COUNTIFS(Rohdaten!C2:C500,A26,Rohdaten!G2:G500,2026) -> 14
A27: Torzähler Mobil 10 Flächen | B27: =IFERROR(AVERAGEIFS(Rohdaten!F2:F500,Rohdaten!C2:C500,A27,Rohdaten!G2:G500,2025),"-") -> - | C27: =COUNTIFS(Rohdaten!C2:C500,A27,Rohdaten!G2:G500,2025) -> 0 | D27: =IFERROR(AVERAGEIFS(Rohdaten!F2:F500,Rohdaten!C2:C500,A27,Rohdaten!G2:G500,2026),"-") -> - | E27: =COUNTIFS(Rohdaten!C2:C500,A27,Rohdaten!G2:G500,2026) -> 0
A28: Torzähler Mobil 8 Flächen | B28: =IFERROR(AVERAGEIFS(Rohdaten!F2:F500,Rohdaten!C2:C500,A28,Rohdaten!G2:G500,2025),"-") -> - | C28: =COUNTIFS(Rohdaten!C2:C500,A28,Rohdaten!G2:G500,2025) -> 0 | D28: =IFERROR(AVERAGEIFS(Rohdaten!F2:F500,Rohdaten!C2:C500,A28,Rohdaten!G2:G500,2026),"-") -> - | E28: =COUNTIFS(Rohdaten!C2:C500,A28,Rohdaten!G2:G500,2026) -> 0
A29: Torzähler Premium | B29: =IFERROR(AVERAGEIFS(Rohdaten!F2:F500,Rohdaten!C2:C500,A29,Rohdaten!G2:G500,2025),"-") -> 338 | C29: =COUNTIFS(Rohdaten!C2:C500,A29,Rohdaten!G2:G500,2025) -> 1 | D29: =IFERROR(AVERAGEIFS(Rohdaten!F2:F500,Rohdaten!C2:C500,A29,Rohdaten!G2:G500,2026),"-") -> - | E29: =COUNTIFS(Rohdaten!C2:C500,A29,Rohdaten!G2:G500,2026) -> 0
A30: GESAMT | B30: =IFERROR(AVERAGEIF(Rohdaten!G2:G500,2025,Rohdaten!F2:F500),"-") -> 87.404255 | C30: =COUNTIF(Rohdaten!G2:G500,2025) -> 141 | D30: =IFERROR(AVERAGEIF(Rohdaten!G2:G500,2026,Rohdaten!F2:F500),"-") -> 82.819672 | E30: =COUNTIF(Rohdaten!G2:G500,2026) -> 61
A33: Monatliche Trendanalyse | B33: Ø Tage | C33: Anzahl Projekte
A34: 45658 | B34: =IFERROR(AVERAGEIFS(Rohdaten!F2:F500,Rohdaten!E2:E500,">="&A34,Rohdaten!E2:E500,"<"&DATE(YEAR(A34),MONTH(A34)+1,1)),"-") -> 85.25 | C34: =COUNTIFS(Rohdaten!E2:E500,">="&A34,Rohdaten!E2:E500,"<"&DATE(YEAR(A34),MONTH(A34)+1,1)) -> 4
A35: 45689 | B35: =IFERROR(AVERAGEIFS(Rohdaten!F2:F500,Rohdaten!E2:E500,">="&A35,Rohdaten!E2:E500,"<"&DATE(YEAR(A35),MONTH(A35)+1,1)),"-") -> 67.461538 | C35: =COUNTIFS(Rohdaten!E2:E500,">="&A35,Rohdaten!E2:E500,"<"&DATE(YEAR(A35),MONTH(A35)+1,1)) -> 13
A36: 45717 | B36: =IFERROR(AVERAGEIFS(Rohdaten!F2:F500,Rohdaten!E2:E500,">="&A36,Rohdaten!E2:E500,"<"&DATE(YEAR(A36),MONTH(A36)+1,1)),"-") -> 78.75 | C36: =COUNTIFS(Rohdaten!E2:E500,">="&A36,Rohdaten!E2:E500,"<"&DATE(YEAR(A36),MONTH(A36)+1,1)) -> 8
A37: 45748 | B37: =IFERROR(AVERAGEIFS(Rohdaten!F2:F500,Rohdaten!E2:E500,">="&A37,Rohdaten!E2:E500,"<"&DATE(YEAR(A37),MONTH(A37)+1,1)),"-") -> 63.454545 | C37: =COUNTIFS(Rohdaten!E2:E500,">="&A37,Rohdaten!E2:E500,"<"&DATE(YEAR(A37),MONTH(A37)+1,1)) -> 11
A38: 45778 | B38: =IFERROR(AVERAGEIFS(Rohdaten!F2:F500,Rohdaten!E2:E500,">="&A38,Rohdaten!E2:E500,"<"&DATE(YEAR(A38),MONTH(A38)+1,1)),"-") -> 91.818182 | C38: =COUNTIFS(Rohdaten!E2:E500,">="&A38,Rohdaten!E2:E500,"<"&DATE(YEAR(A38),MONTH(A38)+1,1)) -> 11
A39: 45809 | B39: =IFERROR(AVERAGEIFS(Rohdaten!F2:F500,Rohdaten!E2:E500,">="&A39,Rohdaten!E2:E500,"<"&DATE(YEAR(A39),MONTH(A39)+1,1)),"-") -> 135 | C39: =COUNTIFS(Rohdaten!E2:E500,">="&A39,Rohdaten!E2:E500,"<"&DATE(YEAR(A39),MONTH(A39)+1,1)) -> 6
A40: 45839 | B40: =IFERROR(AVERAGEIFS(Rohdaten!F2:F500,Rohdaten!E2:E500,">="&A40,Rohdaten!E2:E500,"<"&DATE(YEAR(A40),MONTH(A40)+1,1)),"-") -> 70.555556 | C40: =COUNTIFS(Rohdaten!E2:E500,">="&A40,Rohdaten!E2:E500,"<"&DATE(YEAR(A40),MONTH(A40)+1,1)) -> 9
A41: 45870 | B41: =IFERROR(AVERAGEIFS(Rohdaten!F2:F500,Rohdaten!E2:E500,">="&A41,Rohdaten!E2:E500,"<"&DATE(YEAR(A41),MONTH(A41)+1,1)),"-") -> 78 | C41: =COUNTIFS(Rohdaten!E2:E500,">="&A41,Rohdaten!E2:E500,"<"&DATE(YEAR(A41),MONTH(A41)+1,1)) -> 6
A42: 45901 | B42: =IFERROR(AVERAGEIFS(Rohdaten!F2:F500,Rohdaten!E2:E500,">="&A42,Rohdaten!E2:E500,"<"&DATE(YEAR(A42),MONTH(A42)+1,1)),"-") -> 108.27778 | C42: =COUNTIFS(Rohdaten!E2:E500,">="&A42,Rohdaten!E2:E500,"<"&DATE(YEAR(A42),MONTH(A42)+1,1)) -> 18
A43: 45931 | B43: =IFERROR(AVERAGEIFS(Rohdaten!F2:F500,Rohdaten!E2:E500,">="&A43,Rohdaten!E2:E500,"<"&DATE(YEAR(A43),MONTH(A43)+1,1)),"-") -> 87.086957 | C43: =COUNTIFS(Rohdaten!E2:E500,">="&A43,Rohdaten!E2:E500,"<"&DATE(YEAR(A43),MONTH(A43)+1,1)) -> 23
A44: 45962 | B44: =IFERROR(AVERAGEIFS(Rohdaten!F2:F500,Rohdaten!E2:E500,">="&A44,Rohdaten!E2:E500,"<"&DATE(YEAR(A44),MONTH(A44)+1,1)),"-") -> 102.22727 | C44: =COUNTIFS(Rohdaten!E2:E500,">="&A44,Rohdaten!E2:E500,"<"&DATE(YEAR(A44),MONTH(A44)+1,1)) -> 22
A45: 45992 | B45: =IFERROR(AVERAGEIFS(Rohdaten!F2:F500,Rohdaten!E2:E500,">="&A45,Rohdaten!E2:E500,"<"&DATE(YEAR(A45),MONTH(A45)+1,1)),"-") -> 65.4 | C45: =COUNTIFS(Rohdaten!E2:E500,">="&A45,Rohdaten!E2:E500,"<"&DATE(YEAR(A45),MONTH(A45)+1,1)) -> 10
A46: 46023 | B46: =IFERROR(AVERAGEIFS(Rohdaten!F2:F500,Rohdaten!E2:E500,">="&A46,Rohdaten!E2:E500,"<"&DATE(YEAR(A46),MONTH(A46)+1,1)),"-") -> 215.5 | C46: =COUNTIFS(Rohdaten!E2:E500,">="&A46,Rohdaten!E2:E500,"<"&DATE(YEAR(A46),MONTH(A46)+1,1)) -> 2
...

Sheet Anleitung
B2: 📖 Anleitung zur Nutzung
B4: 1. Daten erweitern
B5: Neue Projekte einfach unten an die Tabelle im Sheet 'Rohdaten' anfügen.
B6: Die Formeln im Dashboard und in der Auswertung passen sich automatisch an,
B7: SOFERN der Rohdaten-Bereich in den Formeln ausreichend groß ist.
B8: Tipp: Wenn viele neue Zeilen hinzukommen, die Formelbereiche in Auswertung & Dashboard anpassen (z.B. F2:F500 statt F2:F157).
B10: 2. Neue Produkttypen
B11: Werden automatisch erkannt, wenn sie in der Spalte 'Produkt' eingetragen sind.
B12: Für das Dashboard: Neue Zeile in der Produkttabelle einfügen und Formeln nach unten kopieren.
B14: 3. Nach Jahren filtern
B15: Option A: Im Sheet 'Rohdaten' den Autofilter in Spalte G (Auslieferungsjahr) nutzen.
B16: Option B: Die Jahresvergleichstabelle im Dashboard zeigt die Daten nach Jahren aufgeschlüsselt.
... B25: → Im Dashboard und Auswertung eine neue Jahres-Spalte ergänzen und Formeln anpassen.
